Workbook

Sheet Commulative
A1: Department of Agriculture
A2: REGIONAL FIELD OFFICE MIMAROPA
A3: Rice Program
A5: DRY SEASON 2026 Harvesting Report
A7: MUNICIPALITY / BARANGAY | B7: NO. OF FARMER HARVESTED | C7: IRRIGATED | U7: RAINFED | AV7: =A5 -> DRY SEASON 2026 Harvesting Report | BN7: REMARKS
C9: HYBRID SEEDS | F9: REGISTERED SEEDS | I9: CERTIFIED SEEDS | L9: GOOD QUALITY SEEDS | O9: FARMERS HOME SAVED SEEDS / GS | R9: TOTAL | U9: LOWLAND | AJ9: UPLAND | AS9: TOTAL | AV9: HYBRID SEEDS | AY9: REGISTERED SEEDS | BB9: CERTIFIED SEEDS | BE9: GOOD QUALITY SEEDS | BH9: FARMERS HOME SAVED SEEDS / GS | BK9: TOTAL
U10: HYBRID SEEDS | X10: REGISTERED SEEDS | AA10: CERTIFIED SEEDS | AD10: GOOD QUALITY SEEDS | AG10: FARMERS HOME SAVED SEEDS | AJ10: CERTIFIED SEEDS | AM10: GOOD QUALITY SEEDS | AP10: FARMERS HOME SAVED SEEDS / GS
C11: Area Harvested (ha) | D11: Ave. Yield (mt/ha) | E11: Production (mt) | F11: Area Harvested (ha) | G11: Ave. Yield (mt/ha) | H11: Production (mt) | I11: Area Harvested (ha) | J11: Ave. Yield (mt/ha) | K11: Production (mt) | L11: Area Harvested (ha) | M11: Ave. Yield (mt/ha) | N11: Production (mt) | O11: Area Harvested (ha) | P11: Ave. Yield (mt/ha) | Q11: Production (mt) | R11: Area Harvested (ha) | S11: Ave. Yield (mt/ha) | T11: Production (mt) | U11: Area Harvested (ha) | V11: Ave. Yield (mt/ha) | W11: Production (mt) | X11: Area Harvested (ha) | Y11: Ave. Yield (mt/ha) | Z11: Production (mt) | AA11: Area Harvested (ha) | AB11: Ave. Yield (mt/ha) | AC11: Production (mt) | AD11: Area Harvested (ha) | AE11: Ave. Yield (mt/ha) | AF11: Production (mt) | AG11: Area Harvested (ha) | AH11: Ave. Yield (mt/ha) | AI11: Production (mt) | AJ11: Area Harvested (ha) | AK11: Ave. Yield (mt/ha) | AL11: Production (mt) | AM11: Area Harvested (ha) | AN11: Ave. Yield (mt/ha) | AO11: Production (mt) | AP11: Area Harvested (ha) | AQ11: Ave. Yield (mt/ha) | AR11: Production (mt) | AS11: Area Harvested (ha) | AT11: Ave. Yield (mt/ha) | AU11: Production (mt) | AV11: Area Harvested (ha) | AW11: Ave. Yield (mt/ha) | AX11: Production (mt) | AY11: Area Harvested (ha) | AZ11: Ave. Yield (mt/ha) | BA11: Production (mt) | BB11: Area Harvested (ha) | BC11: Ave. Yield (mt/ha) | BD11: Production (mt) | BE11: Area Harvested (ha) | BF11: Ave. Yield (mt/ha) | BG11: Production (mt) | BH11: Area Harvested (ha) | BI11: Ave. Yield (mt/ha) | BJ11: Production (mt) | BK11: Area Harvested (ha) | BL11: Ave. Yield (mt/ha) | BM11: Production (mt)
A12: Rizal | B12: =SUM(B13:B24) -> 1219 | C12: =SUM(C13:C24) -> 669.8 | D12: =E12/C12 -> 5.3011048 | E12: =SUM(E13:E24) -> 3550.68 | F12: =SUM(F13:F24) -> 0 | G12: =H12/F12 -> #DIV/0! | H12: =SUM(H13:H24) -> 0 | I12: =SUM(I13:I24) -> 658.5 | J12: =K12/I12 -> 3.9415945 | K12: =SUM(K13:K24) -> 2595.54 | L12: =SUM(L13:L24) -> 0 | M12: =N12/L12 -> #DIV/0! | N12: =SUM(N13:N24) -> 0 | O12: =SUM(O13:O24) -> 116.5 | P12: =Q12/O12 -> 3.1237768 | Q12: =SUM(Q13:Q24) -> 363.92 | R12: =SUM(R13:R24) -> 234.1 | S12: =T12/R12 -> 3.9885092 | T12: =SUM(T13:T24) -> 933.71 | U12: =SUM(U13:U24) -> 277 | V12: =W12/U12 -> 4.8083393 | W12: =SUM(W13:W24) -> 1331.91 | X12: =SUM(X13:X24) -> 0 | Y12: =Z12/X12 -> #DIV/0! | Z12: =SUM(Z13:Z24) -> 0 | AA12: =SUM(AA13:AA24) -> 471.5 | AB12: =AC12/AA12 -> 3.8280382 | AC12: =SUM(AC13:AC24) -> 1804.92 | AD12: =SUM(AD13:AD24) -> 0 | AE12: =AF12/AD12 -> #DIV/0! | AF12: =SUM(AF13:AF24) -> 0 | AG12: =SUM(AG13:AG24) -> 117.8 | AH12: =AI12/AG12 -> 3.0916808 | AI12: =SUM(AI13:AI24) -> 364.2 | AJ12: =SUM(AJ13:AJ24) -> 0 | AK12: =AL12/AJ12 -> #DIV/0! | AL12: =SUM(AL13:AL24) -> 0 | AM12: =SUM(AM13:AM24) -> 0 | AN12: =AO12/AM12 -> #DIV/0! | AO12: =SUM(AO13:AO24) -> 0 | AP12: =SUM(AP13:AP24) -> 0 | AQ12: =AR12/AP12 -> #DIV/0! | AR12: =SUM(AR13:AR24) -> 0 | AS12: =SUM(AS13:AS24) -> 866.3 | AT12: =AU12/AS12 -> 4.0413598 | AU12: =SUM(AU13:AU24) -> 3501.03 | AV12: =SUM(AV13:AV24) -> 946.8 | AW12: =AX12/AV12 -> 5.1569392 | AX12: =SUM(AX13:AX24) -> 4882.59 | AY12: =SUM(AY13:AY24) -> 0 | AZ12: =BA12/AY12 -> #DIV/0! | BA12: =SUM(BA13:BA24) -> 0 | BB12: =SUM(BB13:BB24) -> 1130 | BC12: =BD12/BB12 -> 3.8942124 | BD12: =SUM(BD13:BD24) -> 4400.46 | BE12: =SUM(BE13:BE24) -> 0 | BF12: =BG12/BE12 -> #DIV/0! | BG12: =SUM(BG13:BG24) -> 0 | BH12: =SUM(BH13:BH24) -> 234.3 | BI12: =BJ12/BH12 -> 3.1076398 | BJ12: =SUM(BJ13:BJ24) -> 728.12 | BK12: =SUM(BK13:BK24) -> 2311.1 | BL12: =BM12/BK12 -> 4.3317771 | BM12: =SUM(BM13:BM24) -> 10011.17
A13: Bunog | B13: =SUM('Jan 1-15'!B13,'Jan 16-31'!B13,'Feb 1-15'!B13,'Feb 16-29'!B13,'Mar 1-15'!B13,'Mar 16-31'!B13,'Apr 1-15'!B13,'Apr 16-30'!B13,'May 1-15'!B13,'May 16-31'!B13,'Jun 1-15'!B13,'Jun 16-30'!B13) -> 116 | C13: =SUM('Jan 1-15'!C13,'Jan 16-31'!C13,'Feb 1-15'!C13,'Feb 16-29'!C13,'Mar 1-15'!C13,'Mar 16-31'!C13,'Apr 1-15'!C13,'Apr 16-30'!C13,'May 1-15'!C13,'May 16-31'!C13,'Jun 1-15'!C13,'Jun 16-30'!C13) -> 6.9 | D13: =E13/C13 -> 5 | E13: =SUM('Jan 1-15'!E13,'Jan 16-31'!E13,'Feb 1-15'!E13,'Feb 16-29'!E13,'Mar 1-15'!E13,'Mar 16-31'!E13,'Apr 1-15'!E13,'Apr 16-30'!E13,'May 1-15'!E13,'May 16-31'!E13,'Jun 1-15'!E13,'Jun 16-30'!E13) -> 34.5 | F13: =SUM('Jan 1-15'!F13,'Jan 16-31'!F13,'Feb 1-15'!F13,'Feb 16-29'!F13,'Mar 1-15'!F13,'Mar 16-31'!F13,'Apr 1-15'!F13,'Apr 16-30'!F13,'May 1-15'!F13,'May 16-31'!F13,'Jun 1-15'!F13,'Jun 16-30'!F13) -> 0 | G13: =H13/F13 -> #DIV/0! | H13: =SUM('Jan 1-15'!H13,'Jan 16-31'!H13,'Feb 1-15'!H13,'Feb 16-29'!H13,'Mar 1-15'!H13,'Mar 16-31'!H13,'Apr 1-15'!H13,'Apr 16-30'!H13,'May 1-15'!H13,'May 16-31'!H13,'Jun 1-15'!H13,'Jun 16-30'!H13) -> 0 | I13: =SUM('Jan 1-15'!I13,'Jan 16-31'!I13,'Feb 1-15'!I13,'Feb 16-29'!I13,'Mar 1-15'!I13,'Mar 16-31'!I13,'Apr 1-15'!I13,'Apr 16-30'!I13,'May 1-15'!I13,'May 16-31'!I13,'Jun 1-15'!I13,'Jun 16-30'!I13) -> 11.5 | J13: =K13/I13 -> 3.9 | K13: =SUM('Jan 1-15'!K13,'Jan 16-31'!K13,'Feb 1-15'!K13,'Feb 16-29'!K13,'Mar 1-15'!K13,'Mar 16-31'!K13,'Apr 1-15'!K13,'Apr 16-30'!K13,'May 1-15'!K13,'May 16-31'!K13,'Jun 1-15'!K13,'Jun 16-30'!K13) -> 44.85 | L13: =SUM('Jan 1-15'!L13,'Jan 16-31'!L13,'Feb 1-15'!L13,'Feb 16-29'!L13,'Mar 1-15'!L13,'Mar 16-31'!L13,'Apr 1-15'!L13,'Apr 16-30'!L13,'May 1-15'!L13,'May 16-31'!L13,'Jun 1-15'!L13,'Jun 16-30'!L13) -> 0 | M13: =N13/L13 -> #DIV/0! | N13: =SUM('Jan 1-15'!N13,'Jan 16-31'!N13,'Feb 1-15'!N13,'Feb 16-29'!N13,'Mar 1-15'!N13,'Mar 16-31'!N13,'Apr 1-15'!N13,'Apr 16-30'!N13,'May 1-15'!N13,'May 16-31'!N13,'Jun 1-15'!N13,'Jun 16-30'!N13) -> 0 | O13: =SUM('Jan 1-15'!O13,'Jan 16-31'!O13,'Feb 1-15'!O13,'Feb 16-29'!O13,'Mar 1-15'!O13,'Mar 16-31'!O13,'Apr 1-15'!O13,'Apr 16-30'!O13,'May 1-15'!O13,'May 16-31'!O13,'Jun 1-15'!O13,'Jun 16-30'!O13) -> 15.1 | P13: =Q13/O13 -> 3.2 | Q13: =SUM('Jan 1-15'!Q13,'Jan 16-31'!Q13,'Feb 1-15'!Q13,'Feb 16-29'!Q13,'Mar 1-15'!Q13,'Mar 16-31'!Q13,'Apr 1-15'!Q13,'Apr 16-30'!Q13,'May 1-15'!Q13,'May 16-31'!Q13,'Jun 1-15'!Q13,'Jun 16-30'!Q13) -> 48.32 | R13: =SUM('Jan 1-15'!R13,'Jan 16-31'!R13,'Feb 1-15'!R13,'Feb 16-29'!R13,'Mar 1-15'!R13,'Mar 16-31'!R13,'Apr 1-15'!R13,'Apr 16-30'!R13,'May 1-15'!R13,'May 16-31'!R13,'Jun 1-15'!R13,'Jun 16-30'!R13) -> 1.8 | S13: =T13/R13 -> 4.4 | T13: =SUM('Jan 1-15'!T13,'Jan 16-31'!T13,'Feb 1-15'!T13,'Feb 16-29'!T13,'Mar 1-15'!T13,'Mar 16-31'!T13,'Apr 1-15'!T13,'Apr 16-30'!T13,'May 1-15'!T13,'May 16-31'!T13,'Jun 1-15'!T13,'Jun 16-30'!T13) -> 7.92 | U13: =SUM('Jan 1-15'!U13,'Jan 16-31'!U13,'Feb 1-15'!U13,'Feb 16-29'!U13,'Mar 1-15'!U13,'Mar 16-31'!U13,'Apr 1-15'!U13,'Apr 16-30'!U13,'May 1-15'!U13,'May 16-31'!U13,'Jun 1-15'!U13,'Jun 16-30'!U13) -> 18.4 | V13: =W13/U13 -> 5.023913 | W13: =SUM('Jan 1-15'!W13,'Jan 16-31'!W13,'Feb 1-15'!W13,'Feb 16-29'!W13,'Mar 1-15'!W13,'Mar 16-31'!W13,'Apr 1-15'!W13,'Apr 16-30'!W13,'May 1-15'!W13,'May 16-31'!W13,'Jun 1-15'!W13,'Jun 16-30'!W13) -> 92.44 | X13: =SUM('Jan 1-15'!X13,'Jan 16-31'!X13,'Feb 1-15'!X13,'Feb 16-29'!X13,'Mar 1-15'!X13,'Mar 16-31'!X13,'Apr 1-15'!X13,'Apr 16-30'!X13,'May 1-15'!X13,'May 16-31'!X13,'Jun 1-15'!X13,'Jun 16-30'!X13) -> 0 | Y13: =Z13/X13 -> #DIV/0! | Z13: =SUM('Jan 1-15'!Z13,'Jan 16-31'!Z13,'Feb 1-15'!Z13,'Feb 16-29'!Z13,'Mar 1-15'!Z13,'Mar 16-31'!Z13,'Apr 1-15'!Z13,'Apr 16-30'!Z13,'May 1-15'!Z13,'May 16-31'!Z13,'Jun 1-15'!Z13,'Jun 16-30'!Z13) -> 0 | AA13: =SUM('Jan 1-15'!AA13,'Jan 16-31'!AA13,'Feb 1-15'!AA13,'Feb 16-29'!AA13,'Mar 1-15'!AA13,'Mar 16-31'!AA13,'Apr 1-15'!AA13,'Apr 16-30'!AA13,'May 1-15'!AA13,'May 16-31'!AA13,'Jun 1-15'!AA13,'Jun 16-30'!AA13) -> 41.9 | AB13: =AC13/AA13 -> 3.6565632 | AC13: =SUM('Jan 1-15'!AC13,'Jan 16-31'!AC13,'Feb 1-15'!AC13,'Feb 16-29'!AC13,'Mar 1-15'!AC13,'Mar 16-31'!AC13,'Apr 1-15'!AC13,'Apr 16-30'!AC13,'May 1-15'!AC13,'May 16-31'!AC13,'Jun 1-15'!AC13,'Jun 16-30'!AC13) -> 153.21 | AD13: =SUM('Jan 1-15'!AD13,'Jan 16-31'!AD13,'Feb 1-15'!AD13,'Feb 16-29'!AD13,'Mar 1-15'!AD13,'Mar 16-31'!AD13,'Apr 1-15'!AD13,'Apr 16-30'!AD13,'May 1-15'!AD13,'May 16-31'!AD13,'Jun 1-15'!AD13,'Jun 16-30'!AD13) -> 0 | AE13: =AF13/AD13 -> #DIV/0! | AF13: =SUM('Jan 1-15'!AF13,'Jan 16-31'!AF13,'Feb 1-15'!AF13,'Feb 16-29'!AF13,'Mar 1-15'!AF13,'Mar 16-31'!AF13,'Apr 1-15'!AF13,'Apr 16-30'!AF13,'May 1-15'!AF13,'May 16-31'!AF13,'Jun 1-15'!AF13,'Jun 16-30'!AF13) -> 0 | AG13: =SUM('Jan 1-15'!AG13,'Jan 16-31'!AG13,'Feb 1-15'!AG13,'Feb 16-29'!AG13,'Mar 1-15'!AG13,'Mar 16-31'!AG13,'Apr 1-15'!AG13,'Apr 16-30'!AG13,'May 1-15'!AG13,'May 16-31'!AG13,'Jun 1-15'!AG13,'Jun 16-30'!AG13) -> 47.4 | AH13: =AI13/AG13 -> 3 | AI13: =SUM('Jan 1-15'!AI13,'Jan 16-31'!AI13,'Feb 1-15'!AI13,'Feb 16-29'!AI13,'Mar 1-15'!AI13,'Mar 16-31'!AI13,'Apr 1-15'!AI13,'Apr 16-30'!AI13,'May 1-15'!AI13,'May 16-31'!AI13,'Jun 1-15'!AI13,'Jun 16-30'!AI13) -> 142.2 | AJ13: =SUM('Jan 1-15'!AJ13,'Jan 16-31'!AJ13,'Feb 1-15'!AJ13,'Feb 16-29'!AJ13,'Mar 1-15'!AJ13,'Mar 16-31'!AJ13,'Apr 1-15'!AJ13,'Apr 16-30'!AJ13,'May 1-15'!AJ13,'May 16-31'!AJ13,'Jun 1-15'!AJ13,'Jun 16-30'!AJ13) -> 0 | AK13: =AL13/AJ13 -> #DIV/0! | AL13: =SUM('Jan 1-15'!AL13,'Jan 16-31'!AL13,'Feb 1-15'!AL13,'Feb 16-29'!AL13,'Mar 1-15'!AL13,'Mar 16-31'!AL13,'Apr 1-15'!AL13,'Apr 16-30'!AL13,'May 1-15'!AL13,'May 16-31'!AL13,'Jun 1-15'!AL13,'Jun 16-30'!AL13) -> 0 | AM13: =SUM('Jan 1-15'!AM13,'Jan 16-31'!AM13,'Feb 1-15'!AM13,'Feb 16-29'!AM13,'Mar 1-15'!AM13,'Mar 16-31'!AM13,'Apr 1-15'!AM13,'Apr 16-30'!AM13,'May 1-15'!AM13,'May 16-31'!AM13,'Jun 1-15'!AM13,'Jun 16-30'!AM13) -> 0 | AN13: =AO13/AM13 -> #DIV/0! | AO13: =SUM('Jan 1-15'!AO13,'Jan 16-31'!AO13,'Feb 1-15'!AO13,'Feb 16-29'!AO13,'Mar 1-15'!AO13,'Mar 16-31'!AO13,'Apr 1-15'!AO13,'Apr 16-30'!AO13,'May 1-15'!AO13,'May 16-31'!AO13,'Jun 1-15'!AO13,'Jun 16-30'!AO13) -> 0 | AP13: =SUM('Jan 1-15'!AP13,'Jan 16-31'!AP13,'Feb 1-15'!AP13,'Feb 16-29'!AP13,'Mar 1-15'!AP13,'Mar 16-31'!AP13,'Apr 1-15'!AP13,'Apr 16-30'!AP13,'May 1-15'!AP13,'May 16-31'!AP13,'Jun 1-15'!AP13,'Jun 16-30'!AP13) -> 0 | AQ13: =AR13/AP13 -> #DIV/0! | AR13: =SUM('Jan 1-15'!AR13,'Jan 16-31'!AR13,'Feb 1-15'!AR13,'Feb 16-29'!AR13,'Mar 1-15'!AR13,'Mar 16-31'!AR13,'Apr 1-15'!AR13,'Apr 16-30'!AR13,'May 1-15'!AR13,'May 16-31'!AR13,'Jun 1-15'!AR13,'Jun 16-30'!AR13) -> 0 | AS13: =U13+X13+AA13+AD13+AG13+AJ13+AM13+AP13 -> 107.7 | AT13: =AU13/AS13 -> 3.6012071 | AU13: =W13+Z13+AC13+AF13+AI13+AL13+AO13+AR13 -> 387.85 | AV13: =C13+U13 -> 25.3 | AW13: =AX13/AV13 -> 5.0173913 | AX13: =E13+W13 -> 126.94 | AY13: =F13+X13 -> 0 | AZ13: =BA13/AY13 -> #DIV/0! | BA13: =H13+Z13 -> 0 | BB13: =AJ13+AA13+I13 -> 53.4 | BC13: =BD13/BB13 -> 3.7089888 | BD13: =AL13+AC13+K13 -> 198.06 | BE13: =AM13+AD13+L13 -> 0 | BF13: =BG13/BE13 -> #DIV/0! | BG13: =AO13+AF13+N13 -> 0 | BH13: =AP13+AG13+O13 -> 62.5 | BI13: =BJ13/BH13 -> 3.04832 | BJ13: =AR13+AI13+Q13 -> 190.52 | BK13: =AV13+AY13+BB13+BE13+BH13 -> 141.2 | BL13: =BM13/BK13 -> 3.6509915 | BM13: =AX13+BA13+BD13+BG13+BJ13 -> 515.52
A14: Campong Ulay | B14: =SUM('Jan 1-15'!B14,'Jan 16-31'!B14,'Feb 1-15'!B14,'Feb 16-29'!B14,'Mar 1-15'!B14,'Mar 16-31'!B14,'Apr 1-15'!B14,'Apr 16-30'!B14,'May 1-15'!B14,'May 16-31'!B14,'Jun 1-15'!B14,'Jun 16-30'!B14) -> 88 | C14: =SUM('Jan 1-15'!C14,'Jan 16-31'!C14,'Feb 1-15'!C14,'Feb 16-29'!C14,'Mar 1-15'!C14,'Mar 16-31'!C14,'Apr 1-15'!C14,'Apr 16-30'!C14,'May 1-15'!C14,'May 16-31'!C14,'Jun 1-15'!C14,'Jun 16-30'!C14) -> 37.3 | D14: =E14/C14 -> 4.919571 | E14: =SUM('Jan 1-15'!E14,'Jan 16-31'!E14,'Feb 1-15'!E14,'Feb 16-29'!E14,'Mar 1-15'!E14,'Mar 16-31'!E14,'Apr 1-15'!E14,'Apr 16-30'!E14,'May 1-15'!E14,'May 16-31'!E14,'Jun 1-15'!E14,'Jun 16-30'!E14) -> 183.5 | F14: =SUM('Jan 1-15'!F14,'Jan 16-31'!F14,'Feb 1-15'!F14,'Feb 16-29'!F14,'Mar 1-15'!F14,'Mar 16-31'!F14,'Apr 1-15'!F14,'Apr 16-30'!F14,'May 1-15'!F14,'May 16-31'!F14,'Jun 1-15'!F14,'Jun 16-30'!F14) -> 0 | G14: =H14/F14 -> #DIV/0! | H14: =SUM('Jan 1-15'!H14,'Jan 16-31'!H14,'Feb 1-15'!H14,'Feb 16-29'!H14,'Mar 1-15'!H14,'Mar 16-31'!H14,'Apr 1-15'!H14,'Apr 16-30'!H14,'May 1-15'!H14,'May 16-31'!H14,'Jun 1-15'!H14,'Jun 16-30'!H14) -> 0 | I14: =SUM('Jan 1-15'!I14,'Jan 16-31'!I14,'Feb 1-15'!I14,'Feb 16-29'!I14,'Mar 1-15'!I14,'Mar 16-31'!I14,'Apr 1-15'!I14,'Apr 16-30'!I14,'May 1-15'!I14,'May 16-31'!I14,'Jun 1-15'!I14,'Jun 16-30'!I14) -> 66.2 | J14: =K14/I14 -> 3.9803625 | K14: =SUM('Jan 1-15'!K14,'Jan 16-31'!K14,'Feb 1-15'!K14,'Feb 16-29'!K14,'Mar 1-15'!K14,'Mar 16-31'!K14,'Apr 1-15'!K14,'Apr 16-30'!K14,'May 1-15'!K14,'May 16-31'!K14,'Jun 1-15'!K14,'Jun 16-30'!K14) -> 263.5 | L14: =SUM('Jan 1-15'!L14,'Jan 16-31'!L14,'Feb 1-15'!L14,'Feb 16-29'!L14,'Mar 1-15'!L14,'Mar 16-31'!L14,'Apr 1-15'!L14,'Apr 16-30'!L14,'May 1-15'!L14,'May 16-31'!L14,'Jun 1-15'!L14,'Jun 16-30'!L14) -> 0 | M14: =N14/L14 -> #DIV/0! | N14: =SUM('Jan 1-15'!N14,'Jan 16-31'!N14,'Feb 1-15'!N14,'Feb 16-29'!N14,'Mar 1-15'!N14,'Mar 16-31'!N14,'Apr 1-15'!N14,'Apr 16-30'!N14,'May 1-15'!N14,'May 16-31'!N14,'Jun 1-15'!N14,'Jun 16-30'!N14) -> 0 | O14: =SUM('Jan 1-15'!O14,'Jan 16-31'!O14,'Feb 1-15'!O14,'Feb 16-29'!O14,'Mar 1-15'!O14,'Mar 16-31'!O14,'Apr 1-15'!O14,'Apr 16-30'!O14,'May 1-15'!O14,'May 16-31'!O14,'Jun 1-15'!O14,'Jun 16-30'!O14) -> 25.5 | P14: =Q14/O14 -> 3.1607843 | Q14: =SUM('Jan 1-15'!Q14,'Jan 16-31'!Q14,'Feb 1-15'!Q14,'Feb 16-29'!Q14,'Mar 1-15'!Q14,'Mar 16-31'!Q14,'Apr 1-15'!Q14,'Apr 16-30'!Q14,'May 1-15'!Q14,'May 16-31'!Q14,'Jun 1-15'!Q14,'Jun 16-30'!Q14) -> 80.6 | R14: =SUM('Jan 1-15'!R14,'Jan 16-31'!R14,'Feb 1-15'!R14,'Feb 16-29'!R14,'Mar 1-15'!R14,'Mar 16-31'!R14,'Apr 1-15'!R14,'Apr 16-30'!R14,'May 1-15'!R14,'May 16-31'!R14,'Jun 1-15'!R14,'Jun 16-30'!R14) -> 29.5 | S14: =T14/R14 -> 4.1322034 | T14: =SUM('Jan 1-15'!T14,'Jan 16-31'!T14,'Feb 1-15'!T14,'Feb 16-29'!T14,'Mar 1-15'!T14,'Mar 16-31'!T14,'Apr 1-15'!T14,'Apr 16-30'!T14,'May 1-15'!T14,'May 16-31'!T14,'Jun 1-15'!T14,'Jun 16-30'!T14) -> 121.9 | U14: =SUM('Jan 1-15'!U14,'Jan 16-31'!U14,'Feb 1-15'!U14,'Feb 16-29'!U14,'Mar 1-15'!U14,'Mar 16-31'!U14,'Apr 1-15'!U14,'Apr 16-30'!U14,'May 1-15'!U14,'May 16-31'!U14,'Jun 1-15'!U14,'Jun 16-30'!U14) -> 0 | V14: =W14/U14 -> #DIV/0! | W14: =SUM('Jan 1-15'!W14,'Jan 16-31'!W14,'Feb 1-15'!W14,'Feb 16-29'!W14,'Mar 1-15'!W14,'Mar 16-31'!W14,'Apr 1-15'!W14,'Apr 16-30'!W14,'May 1-15'!W14,'May 16-31'!W14,'Jun 1-15'!W14,'Jun 16-30'!W14) -> 0 | X14: =SUM('Jan 1-15'!X14,'Jan 16-31'!X14,'Feb 1-15'!X14,'Feb 16-29'!X14,'Mar 1-15'!X14,'Mar 16-31'!X14,'Apr 1-15'!X14,'Apr 16-30'!X14,'May 1-15'!X14,'May 16-31'!X14,'Jun 1-15'!X14,'Jun 16-30'!X14) -> 0 | Y14: =Z14/X14 -> #DIV/0! | Z14: =SUM('Jan 1-15'!Z14,'Jan 16-31'!Z14,'Feb 1-15'!Z14,'Feb 16-29'!Z14,'Mar 1-15'!Z14,'Mar 16-31'!Z14,'Apr 1-15'!Z14,'Apr 16-30'!Z14,'May 1-15'!Z14,'May 16-31'!Z14,'Jun 1-15'!Z14,'Jun 16-30'!Z14) -> 0 | AA14: =SUM('Jan 1-15'!AA14,'Jan 16-31'!AA14,'Feb 1-15'!AA14,'Feb 16-29'!AA14,'Mar 1-15'!AA14,'Mar 16-31'!AA14,'Apr 1-15'!AA14,'Apr 16-30'!AA14,'May 1-15'!AA14,'May 16-31'!AA14,'Jun 1-15'!AA14,'Jun 16-30'!AA14) -> 8 | AB14: =AC14/AA14 -> 3.98125 | AC14: =SUM('Jan 1-15'!AC14,'Jan 16-31'!AC14,'Feb 1-15'!AC14,'Feb 16-29'!AC14,'Mar 1-15'!AC14,'Mar 16-31'!AC14,'Apr 1-15'!AC14,'Apr 16-30'!AC14,'May 1-15'!AC14,'May 16-31'!AC14,'Jun 1-15'!AC14,'Jun 16-30'!AC14) -> 31.85 | AD14: =SUM('Jan 1-15'!AD14,'Jan 16-31'!AD14,'Feb 1-15'!AD14,'Feb 16-29'!AD14,'Mar 1-15'!AD14,'Mar 16-31'!AD14,'Apr 1-15'!AD14,'Apr 16-30'!AD14,'May 1-15'!AD14,'May 16-31'!AD14,'Jun 1-15'!AD14,'Jun 16-30'!AD14) -> 0 | AE14: =AF14/AD14 -> #DIV/0! | AF14: =SUM('Jan 1-15'!AF14,'Jan 16-31'!AF14,'Feb 1-15'!AF14,'Feb 16-29'!AF14,'Mar 1-15'!AF14,'Mar 16-31'!AF14,'Apr 1-15'!AF14,'Apr 16-30'!AF14,'May 1-15'!AF14,'May 16-31'!AF14,'Jun 1-15'!AF14,'Jun 16-30'!AF14) -> 0 | AG14: =SUM('Jan 1-15'!AG14,'Jan 16-31'!AG14,'Feb 1-15'!AG14,'Feb 16-29'!AG14,'Mar 1-15'!AG14,'Mar 16-31'!AG14,'Apr 1-15'!AG14,'Apr 16-30'!AG14,'May 1-15'!AG14,'May 16-31'!AG14,'Jun 1-15'!AG14,'Jun 16-30'!AG14) -> 0 | AH14: =AI14/AG14 -> #DIV/0! | AI14: =SUM('Jan 1-15'!AI14,'Jan 16-31'!AI14,'Feb 1-15'!AI14,'Feb 16-29'!AI14,'Mar 1-15'!AI14,'Mar 16-31'!AI14,'Apr 1-15'!AI14,'Apr 16-30'!AI14,'May 1-15'!AI14,'May 16-31'!AI14,'Jun 1-15'!AI14,'Jun 16-30'!AI14) -> 0 | AJ14: =SUM('Jan 1-15'!AJ14,'Jan 16-31'!AJ14,'Feb 1-15'!AJ14,'Feb 16-29'!AJ14,'Mar 1-15'!AJ14,'Mar 16-31'!AJ14,'Apr 1-15'!AJ14,'Apr 16-30'!AJ14,'May 1-15'!AJ14,'May 16-31'!AJ14,'Jun 1-15'!AJ14,'Jun 16-30'!AJ14) -> 0 | AK14: =AL14/AJ14 -> #DIV/0! | AL14: =SUM('Jan 1-15'!AL14,'Jan 16-31'!AL14,'Feb 1-15'!AL14,'Feb 16-29'!AL14,'Mar 1-15'!AL14,'Mar 16-31'!AL14,'Apr 1-15'!AL14,'Apr 16-30'!AL14,'May 1-15'!AL14,'May 16-31'!AL14,'Jun 1-15'!AL14,'Jun 16-30'!AL14) -> 0 | AM14: =SUM('Jan 1-15'!AM14,'Jan 16-31'!AM14,'Feb 1-15'!AM14,'Feb 16-29'!AM14,'Mar 1-15'!AM14,'Mar 16-31'!AM14,'Apr 1-15'!AM14,'Apr 16-30'!AM14,'May 1-15'!AM14,'May 16-31'!AM14,'Jun 1-15'!AM14,'Jun 16-30'!AM14) -> 0 | AN14: =AO14/AM14 -> #DIV/0! | AO14: =SUM('Jan 1-15'!AO14,'Jan 16-31'!AO14,'Feb 1-15'!AO14,'Feb 16-29'!AO14,'Mar 1-15'!AO14,'Mar 16-31'!AO14,'Apr 1-15'!AO14,'Apr 16-30'!AO14,'May 1-15'!AO14,'May 16-31'!AO14,'Jun 1-15'!AO14,'Jun 16-30'!AO14) -> 0 | AP14: =SUM('Jan 1-15'!AP14,'Jan 16-31'!AP14,'Feb 1-15'!AP14,'Feb 16-29'!AP14,'Mar 1-15'!AP14,'Mar 16-31'!AP14,'Apr 1-15'!AP14,'Apr 16-30'!AP14,'May 1-15'!AP14,'May 16-31'!AP14,'Jun 1-15'!AP14,'Jun 16-30'!AP14) -> 0 | AQ14: =AR14/AP14 -> #DIV/0! | AR14: =SUM('Jan 1-15'!AR14,'Jan 16-31'!AR14,'Feb 1-15'!AR14,'Feb 16-29'!AR14,'Mar 1-15'!AR14,'Mar 16-31'!AR14,'Apr 1-15'!AR14,'Apr 16-30'!AR14,'May 1-15'!AR14,'May 16-31'!AR14,'Jun 1-15'!AR14,'Jun 16-30'!AR14) -> 0 | AS14: =U14+X14+AA14+AD14+AG14+AJ14+AM14+AP14 -> 8 | AT14: =AU14/AS14 -> 3.98125 | AU14: =W14+Z14+AC14+AF14+AI14+AL14+AO14+AR14 -> 31.85 | AV14: =C14+U14 -> 37.3 | AW14: =AX14/AV14 -> 4.919571 | AX14: =E14+W14 -> 183.5 | AY14: =F14+X14 -> 0 | AZ14: =BA14/AY14 -> #DIV/0! | BA14: =H14+Z14 -> 0 | BB14: =AJ14+AA14+I14 -> 74.2 | BC14: =BD14/BB14 -> 3.9804582 | BD14: =AL14+AC14+K14 -> 295.35 | BE14: =AM14+AD14+L14 -> 0 | BF14: =BG14/BE14 -> #DIV/0! | BG14: =AO14+AF14+N14 -> 0 | BH14: =AP14+AG14+O14 -> 25.5 | BI14: =BJ14/BH14 -> 3.1607843 | BJ14: =AR14+AI14+Q14 -> 80.6 | BK14: =AV14+AY14+BB14+BE14+BH14 -> 137 | BL14: =BM14/BK14 -> 4.0835766 | BM14: =AX14+BA14+BD14+BG14+BJ14 -> 559.45
A15: Candawaga | B15: =SUM('Jan 1-15'!B15,'Jan 16-31'!B15,'Feb 1-15'!B15,'Feb 16-29'!B15,'Mar 1-15'!B15,'Mar 16-31'!B15,'Apr 1-15'!B15,'Apr 16-30'!B15,'May 1-15'!B15,'May 16-31'!B15,'Jun 1-15'!B15,'Jun 16-30'!B15) -> 198 | C15: =SUM('Jan 1-15'!C15,'Jan 16-31'!C15,'Feb 1-15'!C15,'Feb 16-29'!C15,'Mar 1-15'!C15,'Mar 16-31'!C15,'Apr 1-15'!C15,'Apr 16-30'!C15,'May 1-15'!C15,'May 16-31'!C15,'Jun 1-15'!C15,'Jun 16-30'!C15) -> 322.3 | D15: =E15/C15 -> 5.2808253 | E15: =SUM('Jan 1-15'!E15,'Jan 16-31'!E15,'Feb 1-15'!E15,'Feb 16-29'!E15,'Mar 1-15'!E15,'Mar 16-31'!E15,'Apr 1-15'!E15,'Apr 16-30'!E15,'May 1-15'!E15,'May 16-31'!E15,'Jun 1-15'!E15,'Jun 16-30'!E15) -> 1702.01 | F15: =SUM('Jan 1-15'!F15,'Jan 16-31'!F15,'Feb 1-15'!F15,'Feb 16-29'!F15,'Mar 1-15'!F15,'Mar 16-31'!F15,'Apr 1-15'!F15,'Apr 16-30'!F15,'May 1-15'!F15,'May 16-31'!F15,'Jun 1-15'!F15,'Jun 16-30'!F15) -> 0 | G15: =H15/F15 -> #DIV/0! | H15: =SUM('Jan 1-15'!H15,'Jan 16-31'!H15,'Feb 1-15'!H15,'Feb 16-29'!H15,'Mar 1-15'!H15,'Mar 16-31'!H15,'Apr 1-15'!H15,'Apr 16-30'!H15,'May 1-15'!H15,'May 16-31'!H15,'Jun 1-15'!H15,'Jun 16-30'!H15) -> 0 | I15: =SUM('Jan 1-15'!I15,'Jan 16-31'!I15,'Feb 1-15'!I15,'Feb 16-29'!I15,'Mar 1-15'!I15,'Mar 16-31'!I15,'Apr 1-15'!I15,'Apr 16-30'!I15,'May 1-15'!I15,'May 16-31'!I15,'Jun 1-15'!I15,'Jun 16-30'!I15) -> 78.4 | J15: =K15/I15 -> 4.2 | K15: =SUM('Jan 1-15'!K15,'Jan 16-31'!K15,'Feb 1-15'!K15,'Feb 16-29'!K15,'Mar 1-15'!K15,'Mar 16-31'!K15,'Apr 1-15'!K15,'Apr 16-30'!K15,'May 1-15'!K15,'May 16-31'!K15,'Jun 1-15'!K15,'Jun 16-30'!K15) -> 329.28 | L15: =SUM('Jan 1-15'!L15,'Jan 16-31'!L15,'Feb 1-15'!L15,'Feb 16-29'!L15,'Mar 1-15'!L15,'Mar 16-31'!L15,'Apr 1-15'!L15,'Apr 16-30'!L15,'May 1-15'!L15,'May 16-31'!L15,'Jun 1-15'!L15,'Jun 16-30'!L15) -> 0 | M15: =N15/L15 -> #DIV/0! | N15: =SUM('Jan 1-15'!N15,'Jan 16-31'!N15,'Feb 1-15'!N15,'Feb 16-29'!N15,'Mar 1-15'!N15,'Mar 16-31'!N15,'Apr 1-15'!N15,'Apr 16-30'!N15,'May 1-15'!N15,'May 16-31'!N15,'Jun 1-15'!N15,'Jun 16-30'!N15) -> 0 | O15: =SUM('Jan 1-15'!O15,'Jan 16-31'!O15,'Feb 1-15'!O15,'Feb 16-29'!O15,'Mar 1-15'!O15,'Mar 16-31'!O15,'Apr 1-15'!O15,'Apr 16-30'!O15,'May 1-15'!O15,'May 16-31'!O15,'Jun 1-15'!O15,'Jun 16-30'!O15) -> 0 | P15: =Q15/O15 -> #DIV/0! | Q15: =SUM('Jan 1-15'!Q15,'Jan 16-31'!Q15,'Feb 1-15'!Q15,'Feb 16-29'!Q15,'Mar 1-15'!Q15,'Mar 16-31'!Q15,'Apr 1-15'!Q15,'Apr 16-30'!Q15,'May 1-15'!Q15,'May 16-31'!Q15,'Jun 1-15'!Q15,'Jun 16-30'!Q15) -> 0 | R15: =SUM('Jan 1-15'!R15,'Jan 16-31'!R15,'Feb 1-15'!R15,'Feb 16-29'!R15,'Mar 1-15'!R15,'Mar 16-31'!R15,'Apr 1-15'!R15,'Apr 16-30'!R15,'May 1-15'!R15,'May 16-31'!R15,'Jun 1-15'!R15,'Jun 16-30'!R15) -> 31.6 | S15: =T15/R15 -> 4.721519 | T15: =SUM('Jan 1-15'!T15,'Jan 16-31'!T15,'Feb 1-15'!T15,'Feb 16-29'!T15,'Mar 1-15'!T15,'Mar 16-31'!T15,'Apr 1-15'!T15,'Apr 16-30'!T15,'May 1-15'!T15,'May 16-31'!T15,'Jun 1-15'!T15,'Jun 16-30'!T15) -> 149.2 | U15: =SUM('Jan 1-15'!U15,'Jan 16-31'!U15,'Feb 1-15'!U15,'Feb 16-29'!U15,'Mar 1-15'!U15,'Mar 16-31'!U15,'Apr 1-15'!U15,'Apr 16-30'!U15,'May 1-15'!U15,'May 16-31'!U15,'Jun 1-15'!U15,'Jun 16-30'!U15) -> 29.3 | V15: =W15/U15 -> 5.2 | W15: =SUM('Jan 1-15'!W15,'Jan 16-31'!W15,'Feb 1-15'!W15,'Feb 16-29'!W15,'Mar 1-15'!W15,'Mar 16-31'!W15,'Apr 1-15'!W15,'Apr 16-30'!W15,'May 1-15'!W15,'May 16-31'!W15,'Jun 1-15'!W15,'Jun 16-30'!W15) -> 152.36 | X15: =SUM('Jan 1-15'!X15,'Jan 16-31'!X15,'Feb 1-15'!X15,'Feb 16-29'!X15,'Mar 1-15'!X15,'Mar 16-31'!X15,'Apr 1-15'!X15,'Apr 16-30'!X15,'May 1-15'!X15,'May 16-31'!X15,'Jun 1-15'!X15,'Jun 16-30'!X15) -> 0 | Y15: =Z15/X15 -> #DIV/0! | Z15: =SUM('Jan 1-15'!Z15,'Jan 16-31'!Z15,'Feb 1-15'!Z15,'Feb 16-29'!Z15,'Mar 1-15'!Z15,'Mar 16-31'!Z15,'Apr 1-15'!Z15,'Apr 16-30'!Z15,'May 1-15'!Z15,'May 16-31'!Z15,'Jun 1-15'!Z15,'Jun 16-30'!Z15) -> 0 | AA15: =SUM('Jan 1-15'!AA15,'Jan 16-31'!AA15,'Feb 1-15'!AA15,'Feb 16-29'!AA15,'Mar 1-15'!AA15,'Mar 16-31'!AA15,'Apr 1-15'!AA15,'Apr 16-30'!AA15,'May 1-15'!AA15,'May 16-31'!AA15,'Jun 1-15'!AA15,'Jun 16-30'!AA15) -> 26.9 | AB15: =AC15/AA15 -> 4 | AC15: =SUM('Jan 1-15'!AC15,'Jan 16-31'!AC15,'Feb 1-15'!AC15,'Feb 16-29'!AC15,'Mar 1-15'!AC15,'Mar 16-31'!AC15,'Apr 1-15'!AC15,'Apr 16-30'!AC15,'May 1-15'!AC15,'May 16-31'!AC15,'Jun 1-15'!AC15,'Jun 16-30'!AC15) -> 107.6 | AD15: =SUM('Jan 1-15'!AD15,'Jan 16-31'!AD15,'Feb 1-15'!AD15,'Feb 16-29'!AD15,'Mar 1-15'!AD15,'Mar 16-31'!AD15,'Apr 1-15'!AD15,'Apr 16-30'!AD15,'May 1-15'!AD15,'May 16-31'!AD15,'Jun 1-15'!AD15,'Jun 16-30'!AD15) -> 0 | AE15: =AF15/AD15 -> #DIV/0! | AF15: =SUM('Jan 1-15'!AF15,'Jan 16-31'!AF15,'Feb 1-15'!AF15,'Feb 16-29'!AF15,'Mar 1-15'!AF15,'Mar 16-31'!AF15,'Apr 1-15'!AF15,'Apr 16-30'!AF15,'May 1-15'!AF15,'May 16-31'!AF15,'Jun 1-15'!AF15,'Jun 16-30'!AF15) -> 0 | AG15: =SUM('Jan 1-15'!AG15,'Jan 16-31'!AG15,'Feb 1-15'!AG15,'Feb 16-29'!AG15,'Mar 1-15'!AG15,'Mar 16-31'!AG15,'Apr 1-15'!AG15,'Apr 16-30'!AG15,'May 1-15'!AG15,'May 16-31'!AG15,'Jun 1-15'!AG15,'Jun 16-30'!AG15) -> 3 | AH15: =AI15/AG15 -> 3.2 | AI15: =SUM('Jan 1-15'!AI15,'Jan 16-31'!AI15,'Feb 1-15'!AI15,'Feb 16-29'!AI15,'Mar 1-15'!AI15,'Mar 16-31'!AI15,'Apr 1-15'!AI15,'Apr 16-30'!AI15,'May 1-15'!AI15,'May 16-31'!AI15,'Jun 1-15'!AI15,'Jun 16-30'!AI15) -> 9.6 | AJ15: =SUM('Jan 1-15'!AJ15,'Jan 16-31'!AJ15,'Feb 1-15'!AJ15,'Feb 16-29'!AJ15,'Mar 1-15'!AJ15,'Mar 16-31'!AJ15,'Apr 1-15'!AJ15,'Apr 16-30'!AJ15,'May 1-15'!AJ15,'May 16-31'!AJ15,'Jun 1-15'!AJ15,'Jun 16-30'!AJ15) -> 0 | AK15: =AL15/AJ15 -> #DIV/0! | AL15: =SUM('Jan 1-15'!AL15,'Jan 16-31'!AL15,'Feb 1-15'!AL15,'Feb 16-29'!AL15,'Mar 1-15'!AL15,'Mar 16-31'!AL15,'Apr 1-15'!AL15,'Apr 16-30'!AL15,'May 1-15'!AL15,'May 16-31'!AL15,'Jun 1-15'!AL15,'Jun 16-30'!AL15) -> 0 | AM15: =SUM('Jan 1-15'!AM15,'Jan 16-31'!AM15,'Feb 1-15'!AM15,'Feb 16-29'!AM15,'Mar 1-15'!AM15,'Mar 16-31'!AM15,'Apr 1-15'!AM15,'Apr 16-30'!AM15,'May 1-15'!AM15,'May 16-31'!AM15,'Jun 1-15'!AM15,'Jun 16-30'!AM15) -> 0 | AN15: =AO15/AM15 -> #DIV/0! | AO15: =SUM('Jan 1-15'!AO15,'Jan 16-31'!AO15,'Feb 1-15'!AO15,'Feb 16-29'!AO15,'Mar 1-15'!AO15,'Mar 16-31'!AO15,'Apr 1-15'!AO15,'Apr 16-30'!AO15,'May 1-15'!AO15,'May 16-31'!AO15,'Jun 1-15'!AO15,'Jun 16-30'!AO15) -> 0 | AP15: =SUM('Jan 1-15'!AP15,'Jan 16-31'!AP15,'Feb 1-15'!AP15,'Feb 16-29'!AP15,'Mar 1-15'!AP15,'Mar 16-31'!AP15,'Apr 1-15'!AP15,'Apr 16-30'!AP15,'May 1-15'!AP15,'May 16-31'!AP15,'Jun 1-15'!AP15,'Jun 16-30'!AP15) -> 0 | AQ15: =AR15/AP15 -> #DIV/0! | AR15: =SUM('Jan 1-15'!AR15,'Jan 16-31'!AR15,'Feb 1-15'!AR15,'Feb 16-29'!AR15,'Mar 1-15'!AR15,'Mar 16-31'!AR15,'Apr 1-15'!AR15,'Apr 16-30'!AR15,'May 1-15'!AR15,'May 16-31'!AR15,'Jun 1-15'!AR15,'Jun 16-30'!AR15) -> 0 | AS15: =U15+X15+AA15+AD15+AG15+AJ15+AM15+AP15 -> 59.2 | AT15: =AU15/AS15 -> 4.5533784 | AU15: =W15+Z15+AC15+AF15+AI15+AL15+AO15+AR15 -> 269.56 | AV15: =C15+U15 -> 351.6 | AW15: =AX15/AV15 -> 5.2740899 | AX15: =E15+W15 -> 1854.37 | AY15: =F15+X15 -> 0 | AZ15: =BA15/AY15 -> #DIV/0! | BA15: =H15+Z15 -> 0 | BB15: =AJ15+AA15+I15 -> 105.3 | BC15: =BD15/BB15 -> 4.1489079 | BD15: =AL15+AC15+K15 -> 436.88 | BE15: =AM15+AD15+L15 -> 0 | BF15: =BG15/BE15 -> #DIV/0! | BG15: =AO15+AF15+N15 -> 0 | BH15: =AP15+AG15+O15 -> 3 | BI15: =BJ15/BH15 -> 3.2 | BJ15: =AR15+AI15+Q15 -> 9.6 | BK15: =AV15+AY15+BB15+BE15+BH15 -> 459.9 | BL15: =BM15/BK15 -> 5.0029354 | BM15: =AX15+BA15+BD15+BG15+BJ15 -> 2300.85
A16: Canipaan | B16: =SUM('Jan 1-15'!B16,'Jan 16-31'!B16,'Feb 1-15'!B16,'Feb 16-29'!B16,'Mar 1-15'!B16,'Mar 16-31'!B16,'Apr 1-15'!B16,'Apr 16-30'!B16,'May 1-15'!B16,'May 16-31'!B16,'Jun 1-15'!B16,'Jun 16-30'!B16) -> 99 | C16: =SUM('Jan 1-15'!C16,'Jan 16-31'!C16,'Feb 1-15'!C16,'Feb 16-29'!C16,'Mar 1-15'!C16,'Mar 16-31'!C16,'Apr 1-15'!C16,'Apr 16-30'!C16,'May 1-15'!C16,'May 16-31'!C16,'Jun 1-15'!C16,'Jun 16-30'!C16) -> 5.8 | D16: =E16/C16 -> 5 | E16: =SUM('Jan 1-15'!E16,'Jan 16-31'!E16,'Feb 1-15'!E16,'Feb 16-29'!E16,'Mar 1-15'!E16,'Mar 16-31'!E16,'Apr 1-15'!E16,'Apr 16-30'!E16,'May 1-15'!E16,'May 16-31'!E16,'Jun 1-15'!E16,'Jun 16-30'!E16) -> 29 | F16: =SUM('Jan 1-15'!F16,'Jan 16-31'!F16,'Feb 1-15'!F16,'Feb 16-29'!F16,'Mar 1-15'!F16,'Mar 16-31'!F16,'Apr 1-15'!F16,'Apr 16-30'!F16,'May 1-15'!F16,'May 16-31'!F16,'Jun 1-15'!F16,'Jun 16-30'!F16) -> 0 | G16: =H16/F16 -> #DIV/0! | H16: =SUM('Jan 1-15'!H16,'Jan 16-31'!H16,'Feb 1-15'!H16,'Feb 16-29'!H16,'Mar 1-15'!H16,'Mar 16-31'!H16,'Apr 1-15'!H16,'Apr 16-30'!H16,'May 1-15'!H16,'May 16-31'!H16,'Jun 1-15'!H16,'Jun 16-30'!H16) -> 0 | I16: =SUM('Jan 1-15'!I16,'Jan 16-31'!I16,'Feb 1-15'!I16,'Feb 16-29'!I16,'Mar 1-15'!I16,'Mar 16-31'!I16,'Apr 1-15'!I16,'Apr 16-30'!I16,'May 1-15'!I16,'May 16-31'!I16,'Jun 1-15'!I16,'Jun 16-30'!I16) -> 33 | J16: =K16/I16 -> 3.9 | K16: =SUM('Jan 1-15'!K16,'Jan 16-31'!K16,'Feb 1-15'!K16,'Feb 16-29'!K16,'Mar 1-15'!K16,'Mar 16-31'!K16,'Apr 1-15'!K16,'Apr 16-30'!K16,'May 1-15'!K16,'May 16-31'!K16,'Jun 1-15'!K16,'Jun 16-30'!K16) -> 128.7 | L16: =SUM('Jan 1-15'!L16,'Jan 16-31'!L16,'Feb 1-15'!L16,'Feb 16-29'!L16,'Mar 1-15'!L16,'Mar 16-31'!L16,'Apr 1-15'!L16,'Apr 16-30'!L16,'May 1-15'!L16,'May 16-31'!L16,'Jun 1-15'!L16,'Jun 16-30'!L16) -> 0 | M16: =N16/L16 -> #DIV/0! | N16: =SUM('Jan 1-15'!N16,'Jan 16-31'!N16,'Feb 1-15'!N16,'Feb 16-29'!N16,'Mar 1-15'!N16,'Mar 16-31'!N16,'Apr 1-15'!N16,'Apr 16-30'!N16,'May 1-15'!N16,'May 16-31'!N16,'Jun 1-15'!N16,'Jun 16-30'!N16) -> 0 | O16: =SUM('Jan 1-15'!O16,'Jan 16-31'!O16,'Feb 1-15'!O16,'Feb 16-29'!O16,'Mar 1-15'!O16,'Mar 16-31'!O16,'Apr 1-15'!O16,'Apr 16-30'!O16,'May 1-15'!O16,'May 16-31'!O16,'Jun 1-15'!O16,'Jun 16-30'!O16) -> 2.8 | P16: =Q16/O16 -> 3.2 | Q16: =SUM('Jan 1-15'!Q16,'Jan 16-31'!Q16,'Feb 1-15'!Q16,'Feb 16-29'!Q16,'Mar 1-15'!Q16,'Mar 16-31'!Q16,'Apr 1-15'!Q16,'Apr 16-30'!Q16,'May 1-15'!Q16,'May 16-31'!Q16,'Jun 1-15'!Q16,'Jun 16-30'!Q16) -> 8.96 | R16: =SUM('Jan 1-15'!R16,'Jan 16-31'!R16,'Feb 1-15'!R16,'Feb 16-29'!R16,'Mar 1-15'!R16,'Mar 16-31'!R16,'Apr 1-15'!R16,'Apr 16-30'!R16,'May 1-15'!R16,'May 16-31'!R16,'Jun 1-15'!R16,'Jun 16-30'!R16) -> 11.3 | S16: =T16/R16 -> 4.1725664 | T16: =SUM('Jan 1-15'!T16,'Jan 16-31'!T16,'Feb 1-15'!T16,'Feb 16-29'!T16,'Mar 1-15'!T16,'Mar 16-31'!T16,'Apr 1-15'!T16,'Apr 16-30'!T16,'May 1-15'!T16,'May 16-31'!T16,'Jun 1-15'!T16,'Jun 16-30'!T16) -> 47.15 | U16: =SUM('Jan 1-15'!U16,'Jan 16-31'!U16,'Feb 1-15'!U16,'Feb 16-29'!U16,'Mar 1-15'!U16,'Mar 16-31'!U16,'Apr 1-15'!U16,'Apr 16-30'!U16,'May 1-15'!U16,'May 16-31'!U16,'Jun 1-15'!U16,'Jun 16-30'!U16) -> 24 | V16: =W16/U16 -> 4.84 | W16: =SUM('Jan 1-15'!W16,'Jan 16-31'!W16,'Feb 1-15'!W16,'Feb 16-29'!W16,'Mar 1-15'!W16,'Mar 16-31'!W16,'Apr 1-15'!W16,'Apr 16-30'!W16,'May 1-15'!W16,'May 16-31'!W16,'Jun 1-15'!W16,'Jun 16-30'!W16) -> 116.16 | X16: =SUM('Jan 1-15'!X16,'Jan 16-31'!X16,'Feb 1-15'!X16,'Feb 16-29'!X16,'Mar 1-15'!X16,'Mar 16-31'!X16,'Apr 1-15'!X16,'Apr 16-30'!X16,'May 1-15'!X16,'May 16-31'!X16,'Jun 1-15'!X16,'Jun 16-30'!X16) -> 0 | Y16: =Z16/X16 -> #DIV/0! | Z16: =SUM('Jan 1-15'!Z16,'Jan 16-31'!Z16,'Feb 1-15'!Z16,'Feb 16-29'!Z16,'Mar 1-15'!Z16,'Mar 16-31'!Z16,'Apr 1-15'!Z16,'Apr 16-30'!Z16,'May 1-15'!Z16,'May 16-31'!Z16,'Jun 1-15'!Z16,'Jun 16-30'!Z16) -> 0 | AA16: =SUM('Jan 1-15'!AA16,'Jan 16-31'!AA16,'Feb 1-15'!AA16,'Feb 16-29'!AA16,'Mar 1-15'!AA16,'Mar 16-31'!AA16,'Apr 1-15'!AA16,'Apr 16-30'!AA16,'May 1-15'!AA16,'May 16-31'!AA16,'Jun 1-15'!AA16,'Jun 16-30'!AA16) -> 143.7 | AB16: =AC16/AA16 -> 3.7432846 | AC16: =SUM('Jan 1-15'!AC16,'Jan 16-31'!AC16,'Feb 1-15'!AC16,'Feb 16-29'!AC16,'Mar 1-15'!AC16,'Mar 16-31'!AC16,'Apr 1-15'!AC16,'Apr 16-30'!AC16,'May 1-15'!AC16,'May 16-31'!AC16,'Jun 1-15'!AC16,'Jun 16-30'!AC16) -> 537.91 | AD16: =SUM('Jan 1-15'!AD16,'Jan 16-31'!AD16,'Feb 1-15'!AD16,'Feb 16-29'!AD16,'Mar 1-15'!AD16,'Mar 16-31'!AD16,'Apr 1-15'!AD16,'Apr 16-30'!AD16,'May 1-15'!AD16,'May 16-31'!AD16,'Jun 1-15'!AD16,'Jun 16-30'!AD16) -> 0 | AE16: =AF16/AD16 -> #DIV/0! | AF16: =SUM('Jan 1-15'!AF16,'Jan 16-31'!AF16,'Feb 1-15'!AF16,'Feb 16-29'!AF16,'Mar 1-15'!AF16,'Mar 16-31'!AF16,'Apr 1-15'!AF16,'Apr 16-30'!AF16,'May 1-15'!AF16,'May 16-31'!AF16,'Jun 1-15'!AF16,'Jun 16-30'!AF16) -> 0 | AG16: =SUM('Jan 1-15'!AG16,'Jan 16-31'!AG16,'Feb 1-15'!AG16,'Feb 16-29'!AG16,'Mar 1-15'!AG16,'Mar 16-31'!AG16,'Apr 1-15'!AG16,'Apr 16-30'!AG16,'May 1-15'!AG16,'May 16-31'!AG16,'Jun 1-15'!AG16,'Jun 16-30'!AG16) -> 20.5 | AH16: =AI16/AG16 -> 3.2 | AI16: =SUM('Jan 1-15'!AI16,'Jan 16-31'!AI16,'Feb 1-15'!AI16,'Feb 16-29'!AI16,'Mar 1-15'!AI16,'Mar 16-31'!AI16,'Apr 1-15'!AI16,'Apr 16-30'!AI16,'May 1-15'!AI16,'May 16-31'!AI16,'Jun 1-15'!AI16,'Jun 16-30'!AI16) -> 65.6 | AJ16: =SUM('Jan 1-15'!AJ16,'Jan 16-31'!AJ16,'Feb 1-15'!AJ16,'Feb 16-29'!AJ16,'Mar 1-15'!AJ16,'Mar 16-31'!AJ16,'Apr 1-15'!AJ16,'Apr 16-30'!AJ16,'May 1-15'!AJ16,'May 16-31'!AJ16,'Jun 1-15'!AJ16,'Jun 16-30'!AJ16) -> 0 | AK16: =AL16/AJ16 -> #DIV/0! | AL16: =SUM('Jan 1-15'!AL16,'Jan 16-31'!AL16,'Feb 1-15'!AL16,'Feb 16-29'!AL16,'Mar 1-15'!AL16,'Mar 16-31'!AL16,'Apr 1-15'!AL16,'Apr 16-30'!AL16,'May 1-15'!AL16,'May 16-31'!AL16,'Jun 1-15'!AL16,'Jun 16-30'!AL16) -> 0 | AM16: =SUM('Jan 1-15'!AM16,'Jan 16-31'!AM16,'Feb 1-15'!AM16,'Feb 16-29'!AM16,'Mar 1-15'!AM16,'Mar 16-31'!AM16,'Apr 1-15'!AM16,'Apr 16-30'!AM16,'May 1-15'!AM16,'May 16-31'!AM16,'Jun 1-15'!AM16,'Jun 16-30'!AM16) -> 0 | AN16: =AO16/AM16 -> #DIV/0! | AO16: =SUM('Jan 1-15'!AO16,'Jan 16-31'!AO16,'Feb 1-15'!AO16,'Feb 16-29'!AO16,'Mar 1-15'!AO16,'Mar 16-31'!AO16,'Apr 1-15'!AO16,'Apr 16-30'!AO16,'May 1-15'!AO16,'May 16-31'!AO16,'Jun 1-15'!AO16,'Jun 16-30'!AO16) -> 0 | AP16: =SUM('Jan 1-15'!AP16,'Jan 16-31'!AP16,'Feb 1-15'!AP16,'Feb 16-29'!AP16,'Mar 1-15'!AP16,'Mar 16-31'!AP16,'Apr 1-15'!AP16,'Apr 16-30'!AP16,'May 1-15'!AP16,'May 16-31'!AP16,'Jun 1-15'!AP16,'Jun 16-30'!AP16) -> 0 | AQ16: =AR16/AP16 -> #DIV/0! | AR16: =SUM('Jan 1-15'!AR16,'Jan 16-31'!AR16,'Feb 1-15'!AR16,'Feb 16-29'!AR16,'Mar 1-15'!AR16,'Mar 16-31'!AR16,'Apr 1-15'!AR16,'Apr 16-30'!AR16,'May 1-15'!AR16,'May 16-31'!AR16,'Jun 1-15'!AR16,'Jun 16-30'!AR16) -> 0 | AS16: =U16+X16+AA16+AD16+AG16+AJ16+AM16+AP16 -> 188.2 | AT16: =AU16/AS16 -> 3.8239639 | AU16: =W16+Z16+AC16+AF16+AI16+AL16+AO16+AR16 -> 719.67 | AV16: =C16+U16 -> 29.8 | AW16: =AX16/AV16 -> 4.8711409 | AX16: =E16+W16 -> 145.16 | AY16: =F16+X16 -> 0 | AZ16: =BA16/AY16 -> #DIV/0! | BA16: =H16+Z16 -> 0 | BB16: =AJ16+AA16+I16 -> 176.7 | BC16: =BD16/BB16 -> 3.7725523 | BD16: =AL16+AC16+K16 -> 666.61 | BE16: =AM16+AD16+L16 -> 0 | BF16: =BG16/BE16 -> #DIV/0! | BG16: =AO16+AF16+N16 -> 0 | BH16: =AP16+AG16+O16 -> 23.3 | BI16: =BJ16/BH16 -> 3.2 | BJ16: =AR16+AI16+Q16 -> 74.56 | BK16: =AV16+AY16+BB16+BE16+BH16 -> 229.8 | BL16: =BM16/BK16 -> 3.8569626 | BM16: =AX16+BA16+BD16+BG16+BJ16 -> 886.33
A17: Culasian | B17: =SUM('Jan 1-15'!B17,'Jan 16-31'!B17,'Feb 1-15'!B17,'Feb 16-29'!B17,'Mar 1-15'!B17,'Mar 16-31'!B17,'Apr 1-15'!B17,'Apr 16-30'!B17,'May 1-15'!B17,'May 16-31'!B17,'Jun 1-15'!B17,'Jun 16-30'!B17) -> 27 | C17: =SUM('Jan 1-15'!C17,'Jan 16-31'!C17,'Feb 1-15'!C17,'Feb 16-29'!C17,'Mar 1-15'!C17,'Mar 16-31'!C17,'Apr 1-15'!C17,'Apr 16-30'!C17,'May 1-15'!C17,'May 16-31'!C17,'Jun 1-15'!C17,'Jun 16-30'!C17) -> 7 | D17: =E17/C17 -> 5 | E17: =SUM('Jan 1-15'!E17,'Jan 16-31'!E17,'Feb 1-15'!E17,'Feb 16-29'!E17,'Mar 1-15'!E17,'Mar 16-31'!E17,'Apr 1-15'!E17,'Apr 16-30'!E17,'May 1-15'!E17,'May 16-31'!E17,'Jun 1-15'!E17,'Jun 16-30'!E17) -> 35 | F17: =SUM('Jan 1-15'!F17,'Jan 16-31'!F17,'Feb 1-15'!F17,'Feb 16-29'!F17,'Mar 1-15'!F17,'Mar 16-31'!F17,'Apr 1-15'!F17,'Apr 16-30'!F17,'May 1-15'!F17,'May 16-31'!F17,'Jun 1-15'!F17,'Jun 16-30'!F17) -> 0 | G17: =H17/F17 -> #DIV/0! | H17: =SUM('Jan 1-15'!H17,'Jan 16-31'!H17,'Feb 1-15'!H17,'Feb 16-29'!H17,'Mar 1-15'!H17,'Mar 16-31'!H17,'Apr 1-15'!H17,'Apr 16-30'!H17,'May 1-15'!H17,'May 16-31'!H17,'Jun 1-15'!H17,'Jun 16-30'!H17) -> 0 | I17: =SUM('Jan 1-15'!I17,'Jan 16-31'!I17,'Feb 1-15'!I17,'Feb 16-29'!I17,'Mar 1-15'!I17,'Mar 16-31'!I17,'Apr 1-15'!I17,'Apr 16-30'!I17,'May 1-15'!I17,'May 16-31'!I17,'Jun 1-15'!I17,'Jun 16-30'!I17) -> 18.9 | J17: =K17/I17 -> 3.721164 | K17: =SUM('Jan 1-15'!K17,'Jan 16-31'!K17,'Feb 1-15'!K17,'Feb 16-29'!K17,'Mar 1-15'!K17,'Mar 16-31'!K17,'Apr 1-15'!K17,'Apr 16-30'!K17,'May 1-15'!K17,'May 16-31'!K17,'Jun 1-15'!K17,'Jun 16-30'!K17) -> 70.33 | L17: =SUM('Jan 1-15'!L17,'Jan 16-31'!L17,'Feb 1-15'!L17,'Feb 16-29'!L17,'Mar 1-15'!L17,'Mar 16-31'!L17,'Apr 1-15'!L17,'Apr 16-30'!L17,'May 1-15'!L17,'May 16-31'!L17,'Jun 1-15'!L17,'Jun 16-30'!L17) -> 0 | M17: =N17/L17 -> #DIV/0! | N17: =SUM('Jan 1-15'!N17,'Jan 16-31'!N17,'Feb 1-15'!N17,'Feb 16-29'!N17,'Mar 1-15'!N17,'Mar 16-31'!N17,'Apr 1-15'!N17,'Apr 16-30'!N17,'May 1-15'!N17,'May 16-31'!N17,'Jun 1-15'!N17,'Jun 16-30'!N17) -> 0 | O17: =SUM('Jan 1-15'!O17,'Jan 16-31'!O17,'Feb 1-15'!O17,'Feb 16-29'!O17,'Mar 1-15'!O17,'Mar 16-31'!O17,'Apr 1-15'!O17,'Apr 16-30'!O17,'May 1-15'!O17,'May 16-31'!O17,'Jun 1-15'!O17,'Jun 16-30'!O17) -> 6 | P17: =Q17/O17 -> 3.2 | Q17: =SUM('Jan 1-15'!Q17,'Jan 16-31'!Q17,'Feb 1-15'!Q17,'Feb 16-29'!Q17,'Mar 1-15'!Q17,'Mar 16-31'!Q17,'Apr 1-15'!Q17,'Apr 16-30'!Q17,'May 1-15'!Q17,'May 16-31'!Q17,'Jun 1-15'!Q17,'Jun 16-30'!Q17) -> 19.2 | R17: =SUM('Jan 1-15'!R17,'Jan 16-31'!R17,'Feb 1-15'!R17,'Feb 16-29'!R17,'Mar 1-15'!R17,'Mar 16-31'!R17,'Apr 1-15'!R17,'Apr 16-30'!R17,'May 1-15'!R17,'May 16-31'!R17,'Jun 1-15'!R17,'Jun 16-30'!R17) -> 10.4 | S17: =T17/R17 -> 3.7384615 | T17: =SUM('Jan 1-15'!T17,'Jan 16-31'!T17,'Feb 1-15'!T17,'Feb 16-29'!T17,'Mar 1-15'!T17,'Mar 16-31'!T17,'Apr 1-15'!T17,'Apr 16-30'!T17,'May 1-15'!T17,'May 16-31'!T17,'Jun 1-15'!T17,'Jun 16-30'!T17) -> 38.88 | U17: =SUM('Jan 1-15'!U17,'Jan 16-31'!U17,'Feb 1-15'!U17,'Feb 16-29'!U17,'Mar 1-15'!U17,'Mar 16-31'!U17,'Apr 1-15'!U17,'Apr 16-30'!U17,'May 1-15'!U17,'May 16-31'!U17,'Jun 1-15'!U17,'Jun 16-30'!U17) -> 0 | V17: =W17/U17 -> #DIV/0! | W17: =SUM('Jan 1-15'!W17,'Jan 16-31'!W17,'Feb 1-15'!W17,'Feb 16-29'!W17,'Mar 1-15'!W17,'Mar 16-31'!W17,'Apr 1-15'!W17,'Apr 16-30'!W17,'May 1-15'!W17,'May 16-31'!W17,'Jun 1-15'!W17,'Jun 16-30'!W17) -> 0 | X17: =SUM('Jan 1-15'!X17,'Jan 16-31'!X17,'Feb 1-15'!X17,'Feb 16-29'!X17,'Mar 1-15'!X17,'Mar 16-31'!X17,'Apr 1-15'!X17,'Apr 16-30'!X17,'May 1-15'!X17,'May 16-31'!X17,'Jun 1-15'!X17,'Jun 16-30'!X17) -> 0 | Y17: =Z17/X17 -> #DIV/0! | Z17: =SUM('Jan 1-15'!Z17,'Jan 16-31'!Z17,'Feb 1-15'!Z17,'Feb 16-29'!Z17,'Mar 1-15'!Z17,'Mar 16-31'!Z17,'Apr 1-15'!Z17,'Apr 16-30'!Z17,'May 1-15'!Z17,'May 16-31'!Z17,'Jun 1-15'!Z17,'Jun 16-30'!Z17) -> 0 | AA17: =SUM('Jan 1-15'!AA17,'Jan 16-31'!AA17,'Feb 1-15'!AA17,'Feb 16-29'!AA17,'Mar 1-15'!AA17,'Mar 16-31'!AA17,'Apr 1-15'!AA17,'Apr 16-30'!AA17,'May 1-15'!AA17,'May 16-31'!AA17,'Jun 1-15'!AA17,'Jun 16-30'!AA17) -> 22.2 | AB17: =AC17/AA17 -> 3.9 | AC17: =SUM('Jan 1-15'!AC17,'Jan 16-31'!AC17,'Feb 1-15'!AC17,'Feb 16-29'!AC17,'Mar 1-15'!AC17,'Mar 16-31'!AC17,'Apr 1-15'!AC17,'Apr 16-30'!AC17,'May 1-15'!AC17,'May 16-31'!AC17,'Jun 1-15'!AC17,'Jun 16-30'!AC17) -> 86.58 | AD17: =SUM('Jan 1-15'!AD17,'Jan 16-31'!AD17,'Feb 1-15'!AD17,'Feb 16-29'!AD17,'Mar 1-15'!AD17,'Mar 16-31'!AD17,'Apr 1-15'!AD17,'Apr 16-30'!AD17,'May 1-15'!AD17,'May 16-31'!AD17,'Jun 1-15'!AD17,'Jun 16-30'!AD17) -> 0 | AE17: =AF17/AD17 -> #DIV/0! | AF17: =SUM('Jan 1-15'!AF17,'Jan 16-31'!AF17,'Feb 1-15'!AF17,'Feb 16-29'!AF17,'Mar 1-15'!AF17,'Mar 16-31'!AF17,'Apr 1-15'!AF17,'Apr 16-30'!AF17,'May 1-15'!AF17,'May 16-31'!AF17,'Jun 1-15'!AF17,'Jun 16-30'!AF17) -> 0 | AG17: =SUM('Jan 1-15'!AG17,'Jan 16-31'!AG17,'Feb 1-15'!AG17,'Feb 16-29'!AG17,'Mar 1-15'!AG17,'Mar 16-31'!AG17,'Apr 1-15'!AG17,'Apr 16-30'!AG17,'May 1-15'!AG17,'May 16-31'!AG17,'Jun 1-15'!AG17,'Jun 16-30'!AG17) -> 2.9 | AH17: =AI17/AG17 -> 3.2 | AI17: =SUM('Jan 1-15'!AI17,'Jan 16-31'!AI17,'Feb 1-15'!AI17,'Feb 16-29'!AI17,'Mar 1-15'!AI17,'Mar 16-31'!AI17,'Apr 1-15'!AI17,'Apr 16-30'!AI17,'May 1-15'!AI17,'May 16-31'!AI17,'Jun 1-15'!AI17,'Jun 16-30'!AI17) -> 9.28 | AJ17: =SUM('Jan 1-15'!AJ17,'Jan 16-31'!AJ17,'Feb 1-15'!AJ17,'Feb 16-29'!AJ17,'Mar 1-15'!AJ17,'Mar 16-31'!AJ17,'Apr 1-15'!AJ17,'Apr 16-30'!AJ17,'May 1-15'!AJ17,'May 16-31'!AJ17,'Jun 1-15'!AJ17,'Jun 16-30'!AJ17) -> 0 | AK17: =AL17/AJ17 -> #DIV/0! | AL17: =SUM('Jan 1-15'!AL17,'Jan 16-31'!AL17,'Feb 1-15'!AL17,'Feb 16-29'!AL17,'Mar 1-15'!AL17,'Mar 16-31'!AL17,'Apr 1-15'!AL17,'Apr 16-30'!AL17,'May 1-15'!AL17,'May 16-31'!AL17,'Jun 1-15'!AL17,'Jun 16-30'!AL17) -> 0 | AM17: =SUM('Jan 1-15'!AM17,'Jan 16-31'!AM17,'Feb 1-15'!AM17,'Feb 16-29'!AM17,'Mar 1-15'!AM17,'Mar 16-31'!AM17,'Apr 1-15'!AM17,'Apr 16-30'!AM17,'May 1-15'!AM17,'May 16-31'!AM17,'Jun 1-15'!AM17,'Jun 16-30'!AM17) -> 0 | AN17: =AO17/AM17 -> #DIV/0! | AO17: =SUM('Jan 1-15'!AO17,'Jan 16-31'!AO17,'Feb 1-15'!AO17,'Feb 16-29'!AO17,'Mar 1-15'!AO17,'Mar 16-31'!AO17,'Apr 1-15'!AO17,'Apr 16-30'!AO17,'May 1-15'!AO17,'May 16-31'!AO17,'Jun 1-15'!AO17,'Jun 16-30'!AO17) -> 0 | AP17: =SUM('Jan 1-15'!AP17,'Jan 16-31'!AP17,'Feb 1-15'!AP17,'Feb 16-29'!AP17,'Mar 1-15'!AP17,'Mar 16-31'!AP17,'Apr 1-15'!AP17,'Apr 16-30'!AP17,'May 1-15'!AP17,'May 16-31'!AP17,'Jun 1-15'!AP17,'Jun 16-30'!AP17) -> 0 | AQ17: =AR17/AP17 -> #DIV/0! | AR17: =SUM('Jan 1-15'!AR17,'Jan 16-31'!AR17,'Feb 1-15'!AR17,'Feb 16-29'!AR17,'Mar 1-15'!AR17,'Mar 16-31'!AR17,'Apr 1-15'!AR17,'Apr 16-30'!AR17,'May 1-15'!AR17,'May 16-31'!AR17,'Jun 1-15'!AR17,'Jun 16-30'!AR17) -> 0 | AS17: =U17+X17+AA17+AD17+AG17+AJ17+AM17+AP17 -> 25.1 | AT17: =AU17/AS17 -> 3.8191235 | AU17: =W17+Z17+AC17+AF17+AI17+AL17+AO17+AR17 -> 95.86 | AV17: =C17+U17 -> 7 | AW17: =AX17/AV17 -> 5 | AX17: =E17+W17 -> 35 | AY17: =F17+X17 -> 0 | AZ17: =BA17/AY17 -> #DIV/0! | BA17: =H17+Z17 -> 0 | BB17: =AJ17+AA17+I17 -> 41.1 | BC17: =BD17/BB17 -> 3.8177616 | BD17: =AL17+AC17+K17 -> 156.91 | BE17: =AM17+AD17+L17 -> 0 | BF17: =BG17/BE17 -> #DIV/0! | BG17: =AO17+AF17+N17 -> 0 | BH17: =AP17+AG17+O17 -> 8.9 | BI17: =BJ17/BH17 -> 3.2 | BJ17: =AR17+AI17+Q17 -> 28.48 | BK17: =AV17+AY17+BB17+BE17+BH17 -> 57 | BL17: =BM17/BK17 -> 3.8664912 | BM17: =AX17+BA17+BD17+BG17+BJ17 -> 220.39
A18: Iraan | B18: =SUM('Jan 1-15'!B18,'Jan 16-31'!B18,'Feb 1-15'!B18,'Feb 16-29'!B18,'Mar 1-15'!B18,'Mar 16-31'!B18,'Apr 1-15'!B18,'Apr 16-30'!B18,'May 1-15'!B18,'May 16-31'!B18,'Jun 1-15'!B18,'Jun 16-30'!B18) -> 171 | C18: =SUM('Jan 1-15'!C18,'Jan 16-31'!C18,'Feb 1-15'!C18,'Feb 16-29'!C18,'Mar 1-15'!C18,'Mar 16-31'!C18,'Apr 1-15'!C18,'Apr 16-30'!C18,'May 1-15'!C18,'May 16-31'!C18,'Jun 1-15'!C18,'Jun 16-30'!C18) -> 11.3 | D18: =E18/C18 -> 4.9911504 | E18: =SUM('Jan 1-15'!E18,'Jan 16-31'!E18,'Feb 1-15'!E18,'Feb 16-29'!E18,'Mar 1-15'!E18,'Mar 16-31'!E18,'Apr 1-15'!E18,'Apr 16-30'!E18,'May 1-15'!E18,'May 16-31'!E18,'Jun 1-15'!E18,'Jun 16-30'!E18) -> 56.4 | F18: =SUM('Jan 1-15'!F18,'Jan 16-31'!F18,'Feb 1-15'!F18,'Feb 16-29'!F18,'Mar 1-15'!F18,'Mar 16-31'!F18,'Apr 1-15'!F18,'Apr 16-30'!F18,'May 1-15'!F18,'May 16-31'!F18,'Jun 1-15'!F18,'Jun 16-30'!F18) -> 0 | G18: =H18/F18 -> #DIV/0! | H18: =SUM('Jan 1-15'!H18,'Jan 16-31'!H18,'Feb 1-15'!H18,'Feb 16-29'!H18,'Mar 1-15'!H18,'Mar 16-31'!H18,'Apr 1-15'!H18,'Apr 16-30'!H18,'May 1-15'!H18,'May 16-31'!H18,'Jun 1-15'!H18,'Jun 16-30'!H18) -> 0 | I18: =SUM('Jan 1-15'!I18,'Jan 16-31'!I18,'Feb 1-15'!I18,'Feb 16-29'!I18,'Mar 1-15'!I18,'Mar 16-31'!I18,'Apr 1-15'!I18,'Apr 16-30'!I18,'May 1-15'!I18,'May 16-31'!I18,'Jun 1-15'!I18,'Jun 16-30'!I18) -> 134.2 | J18: =K18/I18 -> 3.9678838 | K18: =SUM('Jan 1-15'!K18,'Jan 16-31'!K18,'Feb 1-15'!K18,'Feb 16-29'!K18,'Mar 1-15'!K18,'Mar 16-31'!K18,'Apr 1-15'!K18,'Apr 16-30'!K18,'May 1-15'!K18,'May 16-31'!K18,'Jun 1-15'!K18,'Jun 16-30'!K18) -> 532.49 | L18: =SUM('Jan 1-15'!L18,'Jan 16-31'!L18,'Feb 1-15'!L18,'Feb 16-29'!L18,'Mar 1-15'!L18,'Mar 16-31'!L18,'Apr 1-15'!L18,'Apr 16-30'!L18,'May 1-15'!L18,'May 16-31'!L18,'Jun 1-15'!L18,'Jun 16-30'!L18) -> 0 | M18: =N18/L18 -> #DIV/0! | N18: =SUM('Jan 1-15'!N18,'Jan 16-31'!N18,'Feb 1-15'!N18,'Feb 16-29'!N18,'Mar 1-15'!N18,'Mar 16-31'!N18,'Apr 1-15'!N18,'Apr 16-30'!N18,'May 1-15'!N18,'May 16-31'!N18,'Jun 1-15'!N18,'Jun 16-30'!N18) -> 0 | O18: =SUM('Jan 1-15'!O18,'Jan 16-31'!O18,'Feb 1-15'!O18,'Feb 16-29'!O18,'Mar 1-15'!O18,'Mar 16-31'!O18,'Apr 1-15'!O18,'Apr 16-30'!O18,'May 1-15'!O18,'May 16-31'!O18,'Jun 1-15'!O18,'Jun 16-30'!O18) -> 38.5 | P18: =Q18/O18 -> 3.0711688 | Q18: =SUM('Jan 1-15'!Q18,'Jan 16-31'!Q18,'Feb 1-15'!Q18,'Feb 16-29'!Q18,'Mar 1-15'!Q18,'Mar 16-31'!Q18,'Apr 1-15'!Q18,'Apr 16-30'!Q18,'May 1-15'!Q18,'May 16-31'!Q18,'Jun 1-15'!Q18,'Jun 16-30'!Q18) -> 118.24 | R18: =SUM('Jan 1-15'!R18,'Jan 16-31'!R18,'Feb 1-15'!R18,'Feb 16-29'!R18,'Mar 1-15'!R18,'Mar 16-31'!R18,'Apr 1-15'!R18,'Apr 16-30'!R18,'May 1-15'!R18,'May 16-31'!R18,'Jun 1-15'!R18,'Jun 16-30'!R18) -> 55.1 | S18: =T18/R18 -> 3.7784029 | T18: =SUM('Jan 1-15'!T18,'Jan 16-31'!T18,'Feb 1-15'!T18,'Feb 16-29'!T18,'Mar 1-15'!T18,'Mar 16-31'!T18,'Apr 1-15'!T18,'Apr 16-30'!T18,'May 1-15'!T18,'May 16-31'!T18,'Jun 1-15'!T18,'Jun 16-30'!T18) -> 208.19 | U18: =SUM('Jan 1-15'!U18,'Jan 16-31'!U18,'Feb 1-15'!U18,'Feb 16-29'!U18,'Mar 1-15'!U18,'Mar 16-31'!U18,'Apr 1-15'!U18,'Apr 16-30'!U18,'May 1-15'!U18,'May 16-31'!U18,'Jun 1-15'!U18,'Jun 16-30'!U18) -> 15 | V18: =W18/U18 -> 4.78 | W18: =SUM('Jan 1-15'!W18,'Jan 16-31'!W18,'Feb 1-15'!W18,'Feb 16-29'!W18,'Mar 1-15'!W18,'Mar 16-31'!W18,'Apr 1-15'!W18,'Apr 16-30'!W18,'May 1-15'!W18,'May 16-31'!W18,'Jun 1-15'!W18,'Jun 16-30'!W18) -> 71.7 | X18: =SUM('Jan 1-15'!X18,'Jan 16-31'!X18,'Feb 1-15'!X18,'Feb 16-29'!X18,'Mar 1-15'!X18,'Mar 16-31'!X18,'Apr 1-15'!X18,'Apr 16-30'!X18,'May 1-15'!X18,'May 16-31'!X18,'Jun 1-15'!X18,'Jun 16-30'!X18) -> 0 | Y18: =Z18/X18 -> #DIV/0! | Z18: =SUM('Jan 1-15'!Z18,'Jan 16-31'!Z18,'Feb 1-15'!Z18,'Feb 16-29'!Z18,'Mar 1-15'!Z18,'Mar 16-31'!Z18,'Apr 1-15'!Z18,'Apr 16-30'!Z18,'May 1-15'!Z18,'May 16-31'!Z18,'Jun 1-15'!Z18,'Jun 16-30'!Z18) -> 0 | AA18: =SUM('Jan 1-15'!AA18,'Jan 16-31'!AA18,'Feb 1-15'!AA18,'Feb 16-29'!AA18,'Mar 1-15'!AA18,'Mar 16-31'!AA18,'Apr 1-15'!AA18,'Apr 16-30'!AA18,'May 1-15'!AA18,'May 16-31'!AA18,'Jun 1-15'!AA18,'Jun 16-30'!AA18) -> 47.5 | AB18: =AC18/AA18 -> 3.7745263 | AC18: =SUM('Jan 1-15'!AC18,'Jan 16-31'!AC18,'Feb 1-15'!AC18,'Feb 16-29'!AC18,'Mar 1-15'!AC18,'Mar 16-31'!AC18,'Apr 1-15'!AC18,'Apr 16-30'!AC18,'May 1-15'!AC18,'May 16-31'!AC18,'Jun 1-15'!AC18,'Jun 16-30'!AC18) -> 179.29 | AD18: =SUM('Jan 1-15'!AD18,'Jan 16-31'!AD18,'Feb 1-15'!AD18,'Feb 16-29'!AD18,'Mar 1-15'!AD18,'Mar 16-31'!AD18,'Apr 1-15'!AD18,'Apr 16-30'!AD18,'May 1-15'!AD18,'May 16-31'!AD18,'Jun 1-15'!AD18,'Jun 16-30'!AD18) -> 0 | AE18: =AF18/AD18 -> #DIV/0! | AF18: =SUM('Jan 1-15'!AF18,'Jan 16-31'!AF18,'Feb 1-15'!AF18,'Feb 16-29'!AF18,'Mar 1-15'!AF18,'Mar 16-31'!AF18,'Apr 1-15'!AF18,'Apr 16-30'!AF18,'May 1-15'!AF18,'May 16-31'!AF18,'Jun 1-15'!AF18,'Jun 16-30'!AF18) -> 0 | AG18: =SUM('Jan 1-15'!AG18,'Jan 16-31'!AG18,'Feb 1-15'!AG18,'Feb 16-29'!AG18,'Mar 1-15'!AG18,'Mar 16-31'!AG18,'Apr 1-15'!AG18,'Apr 16-30'!AG18,'May 1-15'!AG18,'May 16-31'!AG18,'Jun 1-15'!AG18,'Jun 16-30'!AG18) -> 35.5 | AH18: =AI18/AG18 -> 3.1076056 | AI18: =SUM('Jan 1-15'!AI18,'Jan 16-31'!AI18,'Feb 1-15'!AI18,'Feb 16-29'!AI18,'Mar 1-15'!AI18,'Mar 16-31'!AI18,'Apr 1-15'!AI18,'Apr 16-30'!AI18,'May 1-15'!AI18,'May 16-31'!AI18,'Jun 1-15'!AI18,'Jun 16-30'!AI18) -> 110.32 | AJ18: =SUM('Jan 1-15'!AJ18,'Jan 16-31'!AJ18,'Feb 1-15'!AJ18,'Feb 16-29'!AJ18,'Mar 1-15'!AJ18,'Mar 16-31'!AJ18,'Apr 1-15'!AJ18,'Apr 16-30'!AJ18,'May 1-15'!AJ18,'May 16-31'!AJ18,'Jun 1-15'!AJ18,'Jun 16-30'!AJ18) -> 0 | AK18: =AL18/AJ18 -> #DIV/0! | AL18: =SUM('Jan 1-15'!AL18,'Jan 16-31'!AL18,'Feb 1-15'!AL18,'Feb 16-29'!AL18,'Mar 1-15'!AL18,'Mar 16-31'!AL18,'Apr 1-15'!AL18,'Apr 16-30'!AL18,'May 1-15'!AL18,'May 16-31'!AL18,'Jun 1-15'!AL18,'Jun 16-30'!AL18) -> 0 | AM18: =SUM('Jan 1-15'!AM18,'Jan 16-31'!AM18,'Feb 1-15'!AM18,'Feb 16-29'!AM18,'Mar 1-15'!AM18,'Mar 16-31'!AM18,'Apr 1-15'!AM18,'Apr 16-30'!AM18,'May 1-15'!AM18,'May 16-31'!AM18,'Jun 1-15'!AM18,'Jun 16-30'!AM18) -> 0 | AN18: =AO18/AM18 -> #DIV/0! | AO18: =SUM('Jan 1-15'!AO18,'Jan 16-31'!AO18,'Feb 1-15'!AO18,'Feb 16-29'!AO18,'Mar 1-15'!AO18,'Mar 16-31'!AO18,'Apr 1-15'!AO18,'Apr 16-30'!AO18,'May 1-15'!AO18,'May 16-31'!AO18,'Jun 1-15'!AO18,'Jun 16-30'!AO18) -> 0 | AP18: =SUM('Jan 1-15'!AP18,'Jan 16-31'!AP18,'Feb 1-15'!AP18,'Feb 16-29'!AP18,'Mar 1-15'!AP18,'Mar 16-31'!AP18,'Apr 1-15'!AP18,'Apr 16-30'!AP18,'May 1-15'!AP18,'May 16-31'!AP18,'Jun 1-15'!AP18,'Jun 16-30'!AP18) -> 0 | AQ18: =AR18/AP18 -> #DIV/0! | AR18: =SUM('Jan 1-15'!AR18,'Jan 16-31'!AR18,'Feb 1-15'!AR18,'Feb 16-29'!AR18,'Mar 1-15'!AR18,'Mar 16-31'!AR18,'Apr 1-15'!AR18,'Apr 16-30'!AR18,'May 1-15'!AR18,'May 16-31'!AR18,'Jun 1-15'!AR18,'Jun 16-30'!AR18) -> 0 | AS18: =U18+X18+AA18+AD18+AG18+AJ18+AM18+AP18 -> 98 | AT18: =AU18/AS18 -> 3.6868367 | AU18: =W18+Z18+AC18+AF18+AI18+AL18+AO18+AR18 -> 361.31 | AV18: =C18+U18 -> 26.3 | AW18: =AX18/AV18 -> 4.8707224 | AX18: =E18+W18 -> 128.1 | AY18: =F18+X18 -> 0 | AZ18: =BA18/AY18 -> #DIV/0! | BA18: =H18+Z18 -> 0 | BB18: =AJ18+AA18+I18 -> 181.7 | BC18: =BD18/BB18 -> 3.9173363 | BD18: =AL18+AC18+K18 -> 711.78 | BE18: =AM18+AD18+L18 -> 0 | BF18: =BG18/BE18 -> #DIV/0! | BG18: =AO18+AF18+N18 -> 0 | BH18: =AP18+AG18+O18 -> 74 | BI18: =BJ18/BH18 -> 3.0886486 | BJ18: =AR18+AI18+Q18 -> 228.56 | BK18: =AV18+AY18+BB18+BE18+BH18 -> 282 | BL18: =BM18/BK18 -> 3.7887943 | BM18: =AX18+BA18+BD18+BG18+BJ18 -> 1068.44
A19: Latud | B19: =SUM('Jan 1-15'!B19,'Jan 16-31'!B19,'Feb 1-15'!B19,'Feb 16-29'!B19,'Mar 1-15'!B19,'Mar 16-31'!B19,'Apr 1-15'!B19,'Apr 16-30'!B19,'May 1-15'!B19,'May 16-31'!B19,'Jun 1-15'!B19,'Jun 16-30'!B19) -> 27 | C19: =SUM('Jan 1-15'!C19,'Jan 16-31'!C19,'Feb 1-15'!C19,'Feb 16-29'!C19,'Mar 1-15'!C19,'Mar 16-31'!C19,'Apr 1-15'!C19,'Apr 16-30'!C19,'May 1-15'!C19,'May 16-31'!C19,'Jun 1-15'!C19,'Jun 16-30'!C19) -> 0 | D19: =E19/C19 -> #DIV/0! | E19: =SUM('Jan 1-15'!E19,'Jan 16-31'!E19,'Feb 1-15'!E19,'Feb 16-29'!E19,'Mar 1-15'!E19,'Mar 16-31'!E19,'Apr 1-15'!E19,'Apr 16-30'!E19,'May 1-15'!E19,'May 16-31'!E19,'Jun 1-15'!E19,'Jun 16-30'!E19) -> 0 | F19: =SUM('Jan 1-15'!F19,'Jan 16-31'!F19,'Feb 1-15'!F19,'Feb 16-29'!F19,'Mar 1-15'!F19,'Mar 16-31'!F19,'Apr 1-15'!F19,'Apr 16-30'!F19,'May 1-15'!F19,'May 16-31'!F19,'Jun 1-15'!F19,'Jun 16-30'!F19) -> 0 | G19: =H19/F19 -> #DIV/0! | H19: =SUM('Jan 1-15'!H19,'Jan 16-31'!H19,'Feb 1-15'!H19,'Feb 16-29'!H19,'Mar 1-15'!H19,'Mar 16-31'!H19,'Apr 1-15'!H19,'Apr 16-30'!H19,'May 1-15'!H19,'May 16-31'!H19,'Jun 1-15'!H19,'Jun 16-30'!H19) -> 0 | I19: =SUM('Jan 1-15'!I19,'Jan 16-31'!I19,'Feb 1-15'!I19,'Feb 16-29'!I19,'Mar 1-15'!I19,'Mar 16-31'!I19,'Apr 1-15'!I19,'Apr 16-30'!I19,'May 1-15'!I19,'May 16-31'!I19,'Jun 1-15'!I19,'Jun 16-30'!I19) -> 0 | J19: =K19/I19 -> #DIV/0! | K19: =SUM('Jan 1-15'!K19,'Jan 16-31'!K19,'Feb 1-15'!K19,'Feb 16-29'!K19,'Mar 1-15'!K19,'Mar 16-31'!K19,'Apr 1-15'!K19,'Apr 16-30'!K19,'May 1-15'!K19,'May 16-31'!K19,'Jun 1-15'!K19,'Jun 16-30'!K19) -> 0 | L19: =SUM('Jan 1-15'!L19,'Jan 16-31'!L19,'Feb 1-15'!L19,'Feb 16-29'!L19,'Mar 1-15'!L19,'Mar 16-31'!L19,'Apr 1-15'!L19,'Apr 16-30'!L19,'May 1-15'!L19,'May 16-31'!L19,'Jun 1-15'!L19,'Jun 16-30'!L19) -> 0 | M19: =N19/L19 -> #DIV/0! | N19: =SUM('Jan 1-15'!N19,'Jan 16-31'!N19,'Feb 1-15'!N19,'Feb 16-29'!N19,'Mar 1-15'!N19,'Mar 16-31'!N19,'Apr 1-15'!N19,'Apr 16-30'!N19,'May 1-15'!N19,'May 16-31'!N19,'Jun 1-15'!N19,'Jun 16-30'!N19) -> 0 | O19: =SUM('Jan 1-15'!O19,'Jan 16-31'!O19,'Feb 1-15'!O19,'Feb 16-29'!O19,'Mar 1-15'!O19,'Mar 16-31'!O19,'Apr 1-15'!O19,'Apr 16-30'!O19,'May 1-15'!O19,'May 16-31'!O19,'Jun 1-15'!O19,'Jun 16-30'!O19) -> 0 | P19: =Q19/O19 -> #DIV/0! | Q19: =SUM('Jan 1-15'!Q19,'Jan 16-31'!Q19,'Feb 1-15'!Q19,'Feb 16-29'!Q19,'Mar 1-15'!Q19,'Mar 16-31'!Q19,'Apr 1-15'!Q19,'Apr 16-30'!Q19,'May 1-15'!Q19,'May 16-31'!Q19,'Jun 1-15'!Q19,'Jun 16-30'!Q19) -> 0 | R19: =SUM('Jan 1-15'!R19,'Jan 16-31'!R19,'Feb 1-15'!R19,'Feb 16-29'!R19,'Mar 1-15'!R19,'Mar 16-31'!R19,'Apr 1-15'!R19,'Apr 16-30'!R19,'May 1-15'!R19,'May 16-31'!R19,'Jun 1-15'!R19,'Jun 16-30'!R19) -> 0 | S19: =T19/R19 -> #DIV/0! | T19: =SUM('Jan 1-15'!T19,'Jan 16-31'!T19,'Feb 1-15'!T19,'Feb 16-29'!T19,'Mar 1-15'!T19,'Mar 16-31'!T19,'Apr 1-15'!T19,'Apr 16-30'!T19,'May 1-15'!T19,'May 16-31'!T19,'Jun 1-15'!T19,'Jun 16-30'!T19) -> 0 | U19: =SUM('Jan 1-15'!U19,'Jan 16-31'!U19,'Feb 1-15'!U19,'Feb 16-29'!U19,'Mar 1-15'!U19,'Mar 16-31'!U19,'Apr 1-15'!U19,'Apr 16-30'!U19,'May 1-15'!U19,'May 16-31'!U19,'Jun 1-15'!U19,'Jun 16-30'!U19) -> 40.3 | V19: =W19/U19 -> 4.5 | W19: =SUM('Jan 1-15'!W19,'Jan 16-31'!W19,'Feb 1-15'!W19,'Feb 16-29'!W19,'Mar 1-15'!W19,'Mar 16-31'!W19,'Apr 1-15'!W19,'Apr 16-30'!W19,'May 1-15'!W19,'May 16-31'!W19,'Jun 1-15'!W19,'Jun 16-30'!W19) -> 181.35 | X19: =SUM('Jan 1-15'!X19,'Jan 16-31'!X19,'Feb 1-15'!X19,'Feb 16-29'!X19,'Mar 1-15'!X19,'Mar 16-31'!X19,'Apr 1-15'!X19,'Apr 16-30'!X19,'May 1-15'!X19,'May 16-31'!X19,'Jun 1-15'!X19,'Jun 16-30'!X19) -> 0 | Y19: =Z19/X19 -> #DIV/0! | Z19: =SUM('Jan 1-15'!Z19,'Jan 16-31'!Z19,'Feb 1-15'!Z19,'Feb 16-29'!Z19,'Mar 1-15'!Z19,'Mar 16-31'!Z19,'Apr 1-15'!Z19,'Apr 16-30'!Z19,'May 1-15'!Z19,'May 16-31'!Z19,'Jun 1-15'!Z19,'Jun 16-30'!Z19) -> 0 | AA19: =SUM('Jan 1-15'!AA19,'Jan 16-31'!AA19,'Feb 1-15'!AA19,'Feb 16-29'!AA19,'Mar 1-15'!AA19,'Mar 16-31'!AA19,'Apr 1-15'!AA19,'Apr 16-30'!AA19,'May 1-15'!AA19,'May 16-31'!AA19,'Jun 1-15'!AA19,'Jun 16-30'!AA19) -> 0 | AB19: =AC19/AA19 -> #DIV/0! | AC19: =SUM('Jan 1-15'!AC19,'Jan 16-31'!AC19,'Feb 1-15'!AC19,'Feb 16-29'!AC19,'Mar 1-15'!AC19,'Mar 16-31'!AC19,'Apr 1-15'!AC19,'Apr 16-30'!AC19,'May 1-15'!AC19,'May 16-31'!AC19,'Jun 1-15'!AC19,'Jun 16-30'!AC19) -> 0 | AD19: =SUM('Jan 1-15'!AD19,'Jan 16-31'!AD19,'Feb 1-15'!AD19,'Feb 16-29'!AD19,'Mar 1-15'!AD19,'Mar 16-31'!AD19,'Apr 1-15'!AD19,'Apr 16-30'!AD19,'May 1-15'!AD19,'May 16-31'!AD19,'Jun 1-15'!AD19,'Jun 16-30'!AD19) -> 0 | AE19: =AF19/AD19 -> #DIV/0! | AF19: =SUM('Jan 1-15'!AF19,'Jan 16-31'!AF19,'Feb 1-15'!AF19,'Feb 16-29'!AF19,'Mar 1-15'!AF19,'Mar 16-31'!AF19,'Apr 1-15'!AF19,'Apr 16-30'!AF19,'May 1-15'!AF19,'May 16-31'!AF19,'Jun 1-15'!AF19,'Jun 16-30'!AF19) -> 0 | AG19: =SUM('Jan 1-15'!AG19,'Jan 16-31'!AG19,'Feb 1-15'!AG19,'Feb 16-29'!AG19,'Mar 1-15'!AG19,'Mar 16-31'!AG19,'Apr 1-15'!AG19,'Apr 16-30'!AG19,'May 1-15'!AG19,'May 16-31'!AG19,'Jun 1-15'!AG19,'Jun 16-30'!AG19) -> 0 | AH19: =AI19/AG19 -> #DIV/0! | AI19: =SUM('Jan 1-15'!AI19,'Jan 16-31'!AI19,'Feb 1-15'!AI19,'Feb 16-29'!AI19,'Mar 1-15'!AI19,'Mar 16-31'!AI19,'Apr 1-15'!AI19,'Apr 16-30'!AI19,'May 1-15'!AI19,'May 16-31'!AI19,'Jun 1-15'!AI19,'Jun 16-30'!AI19) -> 0 | AJ19: =SUM('Jan 1-15'!AJ19,'Jan 16-31'!AJ19,'Feb 1-15'!AJ19,'Feb 16-29'!AJ19,'Mar 1-15'!AJ19,'Mar 16-31'!AJ19,'Apr 1-15'!AJ19,'Apr 16-30'!AJ19,'May 1-15'!AJ19,'May 16-31'!AJ19,'Jun 1-15'!AJ19,'Jun 16-30'!AJ19) -> 0 | AK19: =AL19/AJ19 -> #DIV/0! | AL19: =SUM('Jan 1-15'!AL19,'Jan 16-31'!AL19,'Feb 1-15'!AL19,'Feb 16-29'!AL19,'Mar 1-15'!AL19,'Mar 16-31'!AL19,'Apr 1-15'!AL19,'Apr 16-30'!AL19,'May 1-15'!AL19,'May 16-31'!AL19,'Jun 1-15'!AL19,'Jun 16-30'!AL19) -> 0 | AM19: =SUM('Jan 1-15'!AM19,'Jan 16-31'!AM19,'Feb 1-15'!AM19,'Feb 16-29'!AM19,'Mar 1-15'!AM19,'Mar 16-31'!AM19,'Apr 1-15'!AM19,'Apr 16-30'!AM19,'May 1-15'!AM19,'May 16-31'!AM19,'Jun 1-15'!AM19,'Jun 16-30'!AM19) -> 0 | AN19: =AO19/AM19 -> #DIV/0! | AO19: =SUM('Jan 1-15'!AO19,'Jan 16-31'!AO19,'Feb 1-15'!AO19,'Feb 16-29'!AO19,'Mar 1-15'!AO19,'Mar 16-31'!AO19,'Apr 1-15'!AO19,'Apr 16-30'!AO19,'May 1-15'!AO19,'May 16-31'!AO19,'Jun 1-15'!AO19,'Jun 16-30'!AO19) -> 0 | AP19: =SUM('Jan 1-15'!AP19,'Jan 16-31'!AP19,'Feb 1-15'!AP19,'Feb 16-29'!AP19,'Mar 1-15'!AP19,'Mar 16-31'!AP19,'Apr 1-15'!AP19,'Apr 16-30'!AP19,'May 1-15'!AP19,'May 16-31'!AP19,'Jun 1-15'!AP19,'Jun 16-30'!AP19) -> 0 | AQ19: =AR19/AP19 -> #DIV/0! | AR19: =SUM('Jan 1-15'!AR19,'Jan 16-31'!AR19,'Feb 1-15'!AR19,'Feb 16-29'!AR19,'Mar 1-15'!AR19,'Mar 16-31'!AR19,'Apr 1-15'!AR19,'Apr 16-30'!AR19,'May 1-15'!AR19,'May 16-31'!AR19,'Jun 1-15'!AR19,'Jun 16-30'!AR19) -> 0 | AS19: =U19+X19+AA19+AD19+AG19+AJ19+AM19+AP19 -> 40.3 | AT19: =AU19/AS19 -> 4.5 | AU19: =W19+Z19+AC19+AF19+AI19+AL19+AO19+AR19 -> 181.35 | AV19: =C19+U19 -> 40.3 | AW19: =AX19/AV19 -> 4.5 | AX19: =E19+W19 -> 181.35 | AY19: =F19+X19 -> 0 | AZ19: =BA19/AY19 -> #DIV/0! | BA19: =H19+Z19 -> 0 | BB19: =AJ19+AA19+I19 -> 0 | BC19: =BD19/BB19 -> #DIV/0! | BD19: =AL19+AC19+K19 -> 0 | BE19: =AM19+AD19+L19 -> 0 | BF19: =BG19/BE19 -> #DIV/0! | BG19: =AO19+AF19+N19 -> 0 | BH19: =AP19+AG19+O19 -> 0 | BI19: =BJ19/BH19 -> #DIV/0! | BJ19: =AR19+AI19+Q19 -> 0 | BK19: =AV19+AY19+BB19+BE19+BH19 -> 40.3 | BL19: =BM19/BK19 -> 4.5 | BM19: =AX19+BA19+BD19+BG19+BJ19 -> 181.35
