Workbook

Sheet DS 2026 Cumulative
A1: Department of Agriculture
A2: REGIONAL FIELD OFFICE MIMAROPA
A3: Rice Program
A5: DRY SEASON 2026 Planting Report
A7: MUNICIPALITY / BARANGAY | B7: NO. OF FARMER PLANTED | C7: IRRIGATED | I7: RAINFED | R7: =A5 -> DRY SEASON 2026 Planting Report | X7: REMARKS
C9: HYBRID SEEDS | D9: REGISTERED SEEDS | E9: CERTIFIED SEEDS | F9: GOOD QUALITY SEEDS | G9: FARMERS HOME SAVED SEEDS / GS | H9: TOTAL | I9: LOWLAND | N9: UPLAND | Q9: TOTAL | R9: HYBRID SEEDS | S9: REGISTERED SEEDS | T9: CERTIFIED SEEDS | U9: GOOD QUALITY SEEDS | V9: FARMERS HOME SAVED SEEDS / GS | W9: TOTAL
I10: HYBRID SEEDS | J10: REGISTERED SEEDS | K10: CERTIFIED SEEDS | L10: GOOD QUALITY SEEDS | M10: FARMERS HOME SAVED SEEDS | N10: CERTIFIED SEEDS | O10: GOOD QUALITY SEEDS | P10: FARMERS HOME SAVED SEEDS / GS
A11: Rizal | B11: =SUM(B12:B23) -> 2264 | C11: =SUM(C12:C23) -> 1420.8533 | D11: =SUM(D12:D23) -> 0 | E11: =SUM(E12:E23) -> 1282.65 | F11: =SUM(F12:F23) -> 0 | G11: =SUM(G12:G23) -> 146.74 | H11: =SUM(H12:H23) -> 2850.2433 | I11: =SUM(I12:I23) -> 394.49 | ... W11: =SUM(W12:W23) -> 4195.9333
A12: Bunog | B12: =SUM('Sept 16-30'!B12,'Oct 1-15'!B12,'Oct 16-31'!B12,'Nov 1-15'!B12,'Nov 16-30'!B12,'Dec 1-15'!B12,'Dec 16-31'!B12,'Jan 1-15'!B12,'Jan 16-31'!B12,'Feb 1-15'!B12,'Feb 16-28'!B12,'Mar 1-15'!B12) -> 146 | C12: =SUM('Sept 16-30'!C12,'Oct 1-15'!C12,'Oct 16-31'!C12,'Nov 1-15'!C12,'Nov 16-30'!C12,'Dec 1-15'!C12,'Dec 16-31'!C12,'Jan 1-15'!C12,'Jan 16-31'!C12,'Feb 1-15'!C12,'Feb 16-28'!C12,'Mar 1-15'!C12) -> 10.4 | D12: =SUM('Sept 16-30'!D12,'Oct 1-15'!D12,'Oct 16-31'!D12,'Nov 1-15'!D12,'Nov 16-30'!D12,'Dec 1-15'!D12,'Dec 16-31'!D12,'Jan 1-15'!D12,'Jan 16-31'!D12,'Feb 1-15'!D12,'Feb 16-28'!D12,'Mar 1-15'!D12) -> 0 | E12: =SUM('Sept 16-30'!E12,'Oct 1-15'!E12,'Oct 16-31'!E12,'Nov 1-15'!E12,'Nov 16-30'!E12,'Dec 1-15'!E12,'Dec 16-31'!E12,'Jan 1-15'!E12,'Jan 16-31'!E12,'Feb 1-15'!E12,'Feb 16-28'!E12,'Mar 1-15'!E12) -> 11.5 | F12: =SUM('Sept 16-30'!F12,'Oct 1-15'!F12,'Oct 16-31'!F12,'Nov 1-15'!F12,'Nov 16-30'!F12,'Dec 1-15'!F12,'Dec 16-31'!F12,'Jan 1-15'!F12,'Jan 16-31'!F12,'Feb 1-15'!F12,'Feb 16-28'!F12,'Mar 1-15'!F12) -> 0 | G12: =SUM('Sept 16-30'!G12,'Oct 1-15'!G12,'Oct 16-31'!G12,'Nov 1-15'!G12,'Nov 16-30'!G12,'Dec 1-15'!G12,'Dec 16-31'!G12,'Jan 1-15'!G12,'Jan 16-31'!G12,'Feb 1-15'!G12,'Feb 16-28'!G12,'Mar 1-15'!G12) -> 15.1 | H12: =SUM(C12:G12) -> 37 | I12: =SUM('Sept 16-30'!I12,'Oct 1-15'!I12,'Oct 16-31'!I12,'Nov 1-15'!I12,'Nov 16-30'!I12,'Dec 1-15'!I12,'Dec 16-31'!I12,'Jan 1-15'!I12,'Jan 16-31'!I12,'Feb 1-15'!I12,'Feb 16-28'!I12,'Mar 1-15'!I12) -> 44.4 | J12: =SUM('Sept 16-30'!J12,'Oct 1-15'!J12,'Oct 16-31'!J12,'Nov 1-15'!J12,'Nov 16-30'!J12,'Dec 1-15'!J12,'Dec 16-31'!J12,'Jan 1-15'!J12,'Jan 16-31'!J12,'Feb 1-15'!J12,'Feb 16-28'!J12,'Mar 1-15'!J12) -> 0 | K12: =SUM('Sept 16-30'!K12,'Oct 1-15'!K12,'Oct 16-31'!K12,'Nov 1-15'!K12,'Nov 16-30'!K12,'Dec 1-15'!K12,'Dec 16-31'!K12,'Jan 1-15'!K12,'Jan 16-31'!K12,'Feb 1-15'!K12,'Feb 16-28'!K12,'Mar 1-15'!K12) -> 41.9 | L12: =SUM('Sept 16-30'!L12,'Oct 1-15'!L12,'Oct 16-31'!L12,'Nov 1-15'!L12,'Nov 16-30'!L12,'Dec 1-15'!L12,'Dec 16-31'!L12,'Jan 1-15'!L12,'Jan 16-31'!L12,'Feb 1-15'!L12,'Feb 16-28'!L12,'Mar 1-15'!L12) -> 0 | M12: =SUM('Sept 16-30'!M12,'Oct 1-15'!M12,'Oct 16-31'!M12,'Nov 1-15'!M12,'Nov 16-30'!M12,'Dec 1-15'!M12,'Dec 16-31'!M12,'Jan 1-15'!M12,'Jan 16-31'!M12,'Feb 1-15'!M12,'Feb 16-28'!M12,'Mar 1-15'!M12) -> 47.4 | N12: =SUM('Sept 16-30'!N12,'Oct 1-15'!N12,'Oct 16-31'!N12,'Nov 1-15'!N12,'Nov 16-30'!N12,'Dec 1-15'!N12,'Dec 16-31'!N12,'Jan 1-15'!N12,'Jan 16-31'!N12,'Feb 1-15'!N12,'Feb 16-28'!N12,'Mar 1-15'!N12) -> 0 | O12: =SUM('Sept 16-30'!O12,'Oct 1-15'!O12,'Oct 16-31'!O12,'Nov 1-15'!O12,'Nov 16-30'!O12,'Dec 1-15'!O12,'Dec 16-31'!O12,'Jan 1-15'!O12,'Jan 16-31'!O12,'Feb 1-15'!O12,'Feb 16-28'!O12,'Mar 1-15'!O12) -> 0 | P12: =SUM('Sept 16-30'!P12,'Oct 1-15'!P12,'Oct 16-31'!P12,'Nov 1-15'!P12,'Nov 16-30'!P12,'Dec 1-15'!P12,'Dec 16-31'!P12,'Jan 1-15'!P12,'Jan 16-31'!P12,'Feb 1-15'!P12,'Feb 16-28'!P12,'Mar 1-15'!P12) -> 0 | Q12: =SUM(I12:P12) -> 133.7 | R12: =SUM('Sept 16-30'!R12,'Oct 1-15'!R12,'Oct 16-31'!R12,'Nov 1-15'!R12,'Nov 16-30'!R12,'Dec 1-15'!R12,'Dec 16-31'!R12,'Jan 1-15'!R12,'Jan 16-31'!R12,'Feb 1-15'!R12,'Feb 16-28'!R12,'Mar 1-15'!R12) -> 54.8 | S12: =SUM('Sept 16-30'!S12,'Oct 1-15'!S12,'Oct 16-31'!S12,'Nov 1-15'!S12,'Nov 16-30'!S12,'Dec 1-15'!S12,'Dec 16-31'!S12,'Jan 1-15'!S12,'Jan 16-31'!S12,'Feb 1-15'!S12,'Feb 16-28'!S12,'Mar 1-15'!S12) -> 0 | T12: =SUM('Sept 16-30'!T12,'Oct 1-15'!T12,'Oct 16-31'!T12,'Nov 1-15'!T12,'Nov 16-30'!T12,'Dec 1-15'!T12,'Dec 16-31'!T12,'Jan 1-15'!T12,'Jan 16-31'!T12,'Feb 1-15'!T12,'Feb 16-28'!T12,'Mar 1-15'!T12) -> 53.4 | U12: =SUM('Sept 16-30'!U12,'Oct 1-15'!U12,'Oct 16-31'!U12,'Nov 1-15'!U12,'Nov 16-30'!U12,'Dec 1-15'!U12,'Dec 16-31'!U12,'Jan 1-15'!U12,'Jan 16-31'!U12,'Feb 1-15'!U12,'Feb 16-28'!U12,'Mar 1-15'!U12) -> 0 | V12: =SUM('Sept 16-30'!V12,'Oct 1-15'!V12,'Oct 16-31'!V12,'Nov 1-15'!V12,'Nov 16-30'!V12,'Dec 1-15'!V12,'Dec 16-31'!V12,'Jan 1-15'!V12,'Jan 16-31'!V12,'Feb 1-15'!V12,'Feb 16-28'!V12,'Mar 1-15'!V12) -> 62.5 | W12: =SUM(R12:V12) -> 170.7
A13: Campong Ulay | B13: =SUM('Sept 16-30'!B13,'Oct 1-15'!B13,'Oct 16-31'!B13,'Nov 1-15'!B13,'Nov 16-30'!B13,'Dec 1-15'!B13,'Dec 16-31'!B13,'Jan 1-15'!B13,'Jan 16-31'!B13,'Feb 1-15'!B13,'Feb 16-28'!B13,'Mar 1-15'!B13) -> 136 | C13: =SUM('Sept 16-30'!C13,'Oct 1-15'!C13,'Oct 16-31'!C13,'Nov 1-15'!C13,'Nov 16-30'!C13,'Dec 1-15'!C13,'Dec 16-31'!C13,'Jan 1-15'!C13,'Jan 16-31'!C13,'Feb 1-15'!C13,'Feb 16-28'!C13,'Mar 1-15'!C13) -> 78.3 | D13: =SUM('Sept 16-30'!D13,'Oct 1-15'!D13,'Oct 16-31'!D13,'Nov 1-15'!D13,'Nov 16-30'!D13,'Dec 1-15'!D13,'Dec 16-31'!D13,'Jan 1-15'!D13,'Jan 16-31'!D13,'Feb 1-15'!D13,'Feb 16-28'!D13,'Mar 1-15'!D13) -> 0 | E13: =SUM('Sept 16-30'!E13,'Oct 1-15'!E13,'Oct 16-31'!E13,'Nov 1-15'!E13,'Nov 16-30'!E13,'Dec 1-15'!E13,'Dec 16-31'!E13,'Jan 1-15'!E13,'Jan 16-31'!E13,'Feb 1-15'!E13,'Feb 16-28'!E13,'Mar 1-15'!E13) -> 81 | F13: =SUM('Sept 16-30'!F13,'Oct 1-15'!F13,'Oct 16-31'!F13,'Nov 1-15'!F13,'Nov 16-30'!F13,'Dec 1-15'!F13,'Dec 16-31'!F13,'Jan 1-15'!F13,'Jan 16-31'!F13,'Feb 1-15'!F13,'Feb 16-28'!F13,'Mar 1-15'!F13) -> 0 | G13: =SUM('Sept 16-30'!G13,'Oct 1-15'!G13,'Oct 16-31'!G13,'Nov 1-15'!G13,'Nov 16-30'!G13,'Dec 1-15'!G13,'Dec 16-31'!G13,'Jan 1-15'!G13,'Jan 16-31'!G13,'Feb 1-15'!G13,'Feb 16-28'!G13,'Mar 1-15'!G13) -> 27.5 | H13: =SUM(C13:G13) -> 186.8 | I13: =SUM('Sept 16-30'!I13,'Oct 1-15'!I13,'Oct 16-31'!I13,'Nov 1-15'!I13,'Nov 16-30'!I13,'Dec 1-15'!I13,'Dec 16-31'!I13,'Jan 1-15'!I13,'Jan 16-31'!I13,'Feb 1-15'!I13,'Feb 16-28'!I13,'Mar 1-15'!I13) -> 2.5 | J13: =SUM('Sept 16-30'!J13,'Oct 1-15'!J13,'Oct 16-31'!J13,'Nov 1-15'!J13,'Nov 16-30'!J13,'Dec 1-15'!J13,'Dec 16-31'!J13,'Jan 1-15'!J13,'Jan 16-31'!J13,'Feb 1-15'!J13,'Feb 16-28'!J13,'Mar 1-15'!J13) -> 0 | K13: =SUM('Sept 16-30'!K13,'Oct 1-15'!K13,'Oct 16-31'!K13,'Nov 1-15'!K13,'Nov 16-30'!K13,'Dec 1-15'!K13,'Dec 16-31'!K13,'Jan 1-15'!K13,'Jan 16-31'!K13,'Feb 1-15'!K13,'Feb 16-28'!K13,'Mar 1-15'!K13) -> 12 | L13: =SUM('Sept 16-30'!L13,'Oct 1-15'!L13,'Oct 16-31'!L13,'Nov 1-15'!L13,'Nov 16-30'!L13,'Dec 1-15'!L13,'Dec 16-31'!L13,'Jan 1-15'!L13,'Jan 16-31'!L13,'Feb 1-15'!L13,'Feb 16-28'!L13,'Mar 1-15'!L13) -> 0 | M13: =SUM('Sept 16-30'!M13,'Oct 1-15'!M13,'Oct 16-31'!M13,'Nov 1-15'!M13,'Nov 16-30'!M13,'Dec 1-15'!M13,'Dec 16-31'!M13,'Jan 1-15'!M13,'Jan 16-31'!M13,'Feb 1-15'!M13,'Feb 16-28'!M13,'Mar 1-15'!M13) -> 0 | N13: =SUM('Sept 16-30'!N13,'Oct 1-15'!N13,'Oct 16-31'!N13,'Nov 1-15'!N13,'Nov 16-30'!N13,'Dec 1-15'!N13,'Dec 16-31'!N13,'Jan 1-15'!N13,'Jan 16-31'!N13,'Feb 1-15'!N13,'Feb 16-28'!N13,'Mar 1-15'!N13) -> 0 | O13: =SUM('Sept 16-30'!O13,'Oct 1-15'!O13,'Oct 16-31'!O13,'Nov 1-15'!O13,'Nov 16-30'!O13,'Dec 1-15'!O13,'Dec 16-31'!O13,'Jan 1-15'!O13,'Jan 16-31'!O13,'Feb 1-15'!O13,'Feb 16-28'!O13,'Mar 1-15'!O13) -> 0 | P13: =SUM('Sept 16-30'!P13,'Oct 1-15'!P13,'Oct 16-31'!P13,'Nov 1-15'!P13,'Nov 16-30'!P13,'Dec 1-15'!P13,'Dec 16-31'!P13,'Jan 1-15'!P13,'Jan 16-31'!P13,'Feb 1-15'!P13,'Feb 16-28'!P13,'Mar 1-15'!P13) -> 0 | Q13: =SUM(I13:P13) -> 14.5 | R13: =SUM('Sept 16-30'!R13,'Oct 1-15'!R13,'Oct 16-31'!R13,'Nov 1-15'!R13,'Nov 16-30'!R13,'Dec 1-15'!R13,'Dec 16-31'!R13,'Jan 1-15'!R13,'Jan 16-31'!R13,'Feb 1-15'!R13,'Feb 16-28'!R13,'Mar 1-15'!R13) -> 80.8 | S13: =SUM('Sept 16-30'!S13,'Oct 1-15'!S13,'Oct 16-31'!S13,'Nov 1-15'!S13,'Nov 16-30'!S13,'Dec 1-15'!S13,'Dec 16-31'!S13,'Jan 1-15'!S13,'Jan 16-31'!S13,'Feb 1-15'!S13,'Feb 16-28'!S13,'Mar 1-15'!S13) -> 0 | T13: =SUM('Sept 16-30'!T13,'Oct 1-15'!T13,'Oct 16-31'!T13,'Nov 1-15'!T13,'Nov 16-30'!T13,'Dec 1-15'!T13,'Dec 16-31'!T13,'Jan 1-15'!T13,'Jan 16-31'!T13,'Feb 1-15'!T13,'Feb 16-28'!T13,'Mar 1-15'!T13) -> 93 | U13: =SUM('Sept 16-30'!U13,'Oct 1-15'!U13,'Oct 16-31'!U13,'Nov 1-15'!U13,'Nov 16-30'!U13,'Dec 1-15'!U13,'Dec 16-31'!U13,'Jan 1-15'!U13,'Jan 16-31'!U13,'Feb 1-15'!U13,'Feb 16-28'!U13,'Mar 1-15'!U13) -> 0 | V13: =SUM('Sept 16-30'!V13,'Oct 1-15'!V13,'Oct 16-31'!V13,'Nov 1-15'!V13,'Nov 16-30'!V13,'Dec 1-15'!V13,'Dec 16-31'!V13,'Jan 1-15'!V13,'Jan 16-31'!V13,'Feb 1-15'!V13,'Feb 16-28'!V13,'Mar 1-15'!V13) -> 27.5 | W13: =SUM(R13:V13) -> 201.3
A14: Candawaga | B14: =SUM('Sept 16-30'!B14,'Oct 1-15'!B14,'Oct 16-31'!B14,'Nov 1-15'!B14,'Nov 16-30'!B14,'Dec 1-15'!B14,'Dec 16-31'!B14,'Jan 1-15'!B14,'Jan 16-31'!B14,'Feb 1-15'!B14,'Feb 16-28'!B14,'Mar 1-15'!B14) -> 389 | C14: =SUM('Sept 16-30'!C14,'Oct 1-15'!C14,'Oct 16-31'!C14,'Nov 1-15'!C14,'Nov 16-30'!C14,'Dec 1-15'!C14,'Dec 16-31'!C14,'Jan 1-15'!C14,'Jan 16-31'!C14,'Feb 1-15'!C14,'Feb 16-28'!C14,'Mar 1-15'!C14) -> 668.7 | D14: =SUM('Sept 16-30'!D14,'Oct 1-15'!D14,'Oct 16-31'!D14,'Nov 1-15'!D14,'Nov 16-30'!D14,'Dec 1-15'!D14,'Dec 16-31'!D14,'Jan 1-15'!D14,'Jan 16-31'!D14,'Feb 1-15'!D14,'Feb 16-28'!D14,'Mar 1-15'!D14) -> 0 | E14: =SUM('Sept 16-30'!E14,'Oct 1-15'!E14,'Oct 16-31'!E14,'Nov 1-15'!E14,'Nov 16-30'!E14,'Dec 1-15'!E14,'Dec 16-31'!E14,'Jan 1-15'!E14,'Jan 16-31'!E14,'Feb 1-15'!E14,'Feb 16-28'!E14,'Mar 1-15'!E14) -> 158 | F14: =SUM('Sept 16-30'!F14,'Oct 1-15'!F14,'Oct 16-31'!F14,'Nov 1-15'!F14,'Nov 16-30'!F14,'Dec 1-15'!F14,'Dec 16-31'!F14,'Jan 1-15'!F14,'Jan 16-31'!F14,'Feb 1-15'!F14,'Feb 16-28'!F14,'Mar 1-15'!F14) -> 0 | G14: =SUM('Sept 16-30'!G14,'Oct 1-15'!G14,'Oct 16-31'!G14,'Nov 1-15'!G14,'Nov 16-30'!G14,'Dec 1-15'!G14,'Dec 16-31'!G14,'Jan 1-15'!G14,'Jan 16-31'!G14,'Feb 1-15'!G14,'Feb 16-28'!G14,'Mar 1-15'!G14) -> 2 | H14: =SUM(C14:G14) -> 828.7 | I14: =SUM('Sept 16-30'!I14,'Oct 1-15'!I14,'Oct 16-31'!I14,'Nov 1-15'!I14,'Nov 16-30'!I14,'Dec 1-15'!I14,'Dec 16-31'!I14,'Jan 1-15'!I14,'Jan 16-31'!I14,'Feb 1-15'!I14,'Feb 16-28'!I14,'Mar 1-15'!I14) -> 51.79 | J14: =SUM('Sept 16-30'!J14,'Oct 1-15'!J14,'Oct 16-31'!J14,'Nov 1-15'!J14,'Nov 16-30'!J14,'Dec 1-15'!J14,'Dec 16-31'!J14,'Jan 1-15'!J14,'Jan 16-31'!J14,'Feb 1-15'!J14,'Feb 16-28'!J14,'Mar 1-15'!J14) -> 0 | K14: =SUM('Sept 16-30'!K14,'Oct 1-15'!K14,'Oct 16-31'!K14,'Nov 1-15'!K14,'Nov 16-30'!K14,'Dec 1-15'!K14,'Dec 16-31'!K14,'Jan 1-15'!K14,'Jan 16-31'!K14,'Feb 1-15'!K14,'Feb 16-28'!K14,'Mar 1-15'!K14) -> 28.9 | L14: =SUM('Sept 16-30'!L14,'Oct 1-15'!L14,'Oct 16-31'!L14,'Nov 1-15'!L14,'Nov 16-30'!L14,'Dec 1-15'!L14,'Dec 16-31'!L14,'Jan 1-15'!L14,'Jan 16-31'!L14,'Feb 1-15'!L14,'Feb 16-28'!L14,'Mar 1-15'!L14) -> 0 | M14: =SUM('Sept 16-30'!M14,'Oct 1-15'!M14,'Oct 16-31'!M14,'Nov 1-15'!M14,'Nov 16-30'!M14,'Dec 1-15'!M14,'Dec 16-31'!M14,'Jan 1-15'!M14,'Jan 16-31'!M14,'Feb 1-15'!M14,'Feb 16-28'!M14,'Mar 1-15'!M14) -> 28.6 | N14: =SUM('Sept 16-30'!N14,'Oct 1-15'!N14,'Oct 16-31'!N14,'Nov 1-15'!N14,'Nov 16-30'!N14,'Dec 1-15'!N14,'Dec 16-31'!N14,'Jan 1-15'!N14,'Jan 16-31'!N14,'Feb 1-15'!N14,'Feb 16-28'!N14,'Mar 1-15'!N14) -> 0 | O14: =SUM('Sept 16-30'!O14,'Oct 1-15'!O14,'Oct 16-31'!O14,'Nov 1-15'!O14,'Nov 16-30'!O14,'Dec 1-15'!O14,'Dec 16-31'!O14,'Jan 1-15'!O14,'Jan 16-31'!O14,'Feb 1-15'!O14,'Feb 16-28'!O14,'Mar 1-15'!O14) -> 0 | P14: =SUM('Sept 16-30'!P14,'Oct 1-15'!P14,'Oct 16-31'!P14,'Nov 1-15'!P14,'Nov 16-30'!P14,'Dec 1-15'!P14,'Dec 16-31'!P14,'Jan 1-15'!P14,'Jan 16-31'!P14,'Feb 1-15'!P14,'Feb 16-28'!P14,'Mar 1-15'!P14) -> 0 | Q14: =SUM(I14:P14) -> 109.29 | R14: =SUM('Sept 16-30'!R14,'Oct 1-15'!R14,'Oct 16-31'!R14,'Nov 1-15'!R14,'Nov 16-30'!R14,'Dec 1-15'!R14,'Dec 16-31'!R14,'Jan 1-15'!R14,'Jan 16-31'!R14,'Feb 1-15'!R14,'Feb 16-28'!R14,'Mar 1-15'!R14) -> 720.49 | S14: =SUM('Sept 16-30'!S14,'Oct 1-15'!S14,'Oct 16-31'!S14,'Nov 1-15'!S14,'Nov 16-30'!S14,'Dec 1-15'!S14,'Dec 16-31'!S14,'Jan 1-15'!S14,'Jan 16-31'!S14,'Feb 1-15'!S14,'Feb 16-28'!S14,'Mar 1-15'!S14) -> 0 | T14: =SUM('Sept 16-30'!T14,'Oct 1-15'!T14,'Oct 16-31'!T14,'Nov 1-15'!T14,'Nov 16-30'!T14,'Dec 1-15'!T14,'Dec 16-31'!T14,'Jan 1-15'!T14,'Jan 16-31'!T14,'Feb 1-15'!T14,'Feb 16-28'!T14,'Mar 1-15'!T14) -> 186.9 | U14: =SUM('Sept 16-30'!U14,'Oct 1-15'!U14,'Oct 16-31'!U14,'Nov 1-15'!U14,'Nov 16-30'!U14,'Dec 1-15'!U14,'Dec 16-31'!U14,'Jan 1-15'!U14,'Jan 16-31'!U14,'Feb 1-15'!U14,'Feb 16-28'!U14,'Mar 1-15'!U14) -> 0 | V14: =SUM('Sept 16-30'!V14,'Oct 1-15'!V14,'Oct 16-31'!V14,'Nov 1-15'!V14,'Nov 16-30'!V14,'Dec 1-15'!V14,'Dec 16-31'!V14,'Jan 1-15'!V14,'Jan 16-31'!V14,'Feb 1-15'!V14,'Feb 16-28'!V14,'Mar 1-15'!V14) -> 30.6 | W14: =SUM(R14:V14) -> 937.99
A15: Canipaan | B15: =SUM('Sept 16-30'!B15,'Oct 1-15'!B15,'Oct 16-31'!B15,'Nov 1-15'!B15,'Nov 16-30'!B15,'Dec 1-15'!B15,'Dec 16-31'!B15,'Jan 1-15'!B15,'Jan 16-31'!B15,'Feb 1-15'!B15,'Feb 16-28'!B15,'Mar 1-15'!B15) -> 114 | C15: =SUM('Sept 16-30'!C15,'Oct 1-15'!C15,'Oct 16-31'!C15,'Nov 1-15'!C15,'Nov 16-30'!C15,'Dec 1-15'!C15,'Dec 16-31'!C15,'Jan 1-15'!C15,'Jan 16-31'!C15,'Feb 1-15'!C15,'Feb 16-28'!C15,'Mar 1-15'!C15) -> 20.5 | D15: =SUM('Sept 16-30'!D15,'Oct 1-15'!D15,'Oct 16-31'!D15,'Nov 1-15'!D15,'Nov 16-30'!D15,'Dec 1-15'!D15,'Dec 16-31'!D15,'Jan 1-15'!D15,'Jan 16-31'!D15,'Feb 1-15'!D15,'Feb 16-28'!D15,'Mar 1-15'!D15) -> 0 | E15: =SUM('Sept 16-30'!E15,'Oct 1-15'!E15,'Oct 16-31'!E15,'Nov 1-15'!E15,'Nov 16-30'!E15,'Dec 1-15'!E15,'Dec 16-31'!E15,'Jan 1-15'!E15,'Jan 16-31'!E15,'Feb 1-15'!E15,'Feb 16-28'!E15,'Mar 1-15'!E15) -> 33 | F15: =SUM('Sept 16-30'!F15,'Oct 1-15'!F15,'Oct 16-31'!F15,'Nov 1-15'!F15,'Nov 16-30'!F15,'Dec 1-15'!F15,'Dec 16-31'!F15,'Jan 1-15'!F15,'Jan 16-31'!F15,'Feb 1-15'!F15,'Feb 16-28'!F15,'Mar 1-15'!F15) -> 0 | G15: =SUM('Sept 16-30'!G15,'Oct 1-15'!G15,'Oct 16-31'!G15,'Nov 1-15'!G15,'Nov 16-30'!G15,'Dec 1-15'!G15,'Dec 16-31'!G15,'Jan 1-15'!G15,'Jan 16-31'!G15,'Feb 1-15'!G15,'Feb 16-28'!G15,'Mar 1-15'!G15) -> 2.8 | H15: =SUM(C15:G15) -> 56.3 | I15: =SUM('Sept 16-30'!I15,'Oct 1-15'!I15,'Oct 16-31'!I15,'Nov 1-15'!I15,'Nov 16-30'!I15,'Dec 1-15'!I15,'Dec 16-31'!I15,'Jan 1-15'!I15,'Jan 16-31'!I15,'Feb 1-15'!I15,'Feb 16-28'!I15,'Mar 1-15'!I15) -> 71.5 | J15: =SUM('Sept 16-30'!J15,'Oct 1-15'!J15,'Oct 16-31'!J15,'Nov 1-15'!J15,'Nov 16-30'!J15,'Dec 1-15'!J15,'Dec 16-31'!J15,'Jan 1-15'!J15,'Jan 16-31'!J15,'Feb 1-15'!J15,'Feb 16-28'!J15,'Mar 1-15'!J15) -> 0 | K15: =SUM('Sept 16-30'!K15,'Oct 1-15'!K15,'Oct 16-31'!K15,'Nov 1-15'!K15,'Nov 16-30'!K15,'Dec 1-15'!K15,'Dec 16-31'!K15,'Jan 1-15'!K15,'Jan 16-31'!K15,'Feb 1-15'!K15,'Feb 16-28'!K15,'Mar 1-15'!K15) -> 143.7 | L15: =SUM('Sept 16-30'!L15,'Oct 1-15'!L15,'Oct 16-31'!L15,'Nov 1-15'!L15,'Nov 16-30'!L15,'Dec 1-15'!L15,'Dec 16-31'!L15,'Jan 1-15'!L15,'Jan 16-31'!L15,'Feb 1-15'!L15,'Feb 16-28'!L15,'Mar 1-15'!L15) -> 0 | M15: =SUM('Sept 16-30'!M15,'Oct 1-15'!M15,'Oct 16-31'!M15,'Nov 1-15'!M15,'Nov 16-30'!M15,'Dec 1-15'!M15,'Dec 16-31'!M15,'Jan 1-15'!M15,'Jan 16-31'!M15,'Feb 1-15'!M15,'Feb 16-28'!M15,'Mar 1-15'!M15) -> 20.5 | N15: =SUM('Sept 16-30'!N15,'Oct 1-15'!N15,'Oct 16-31'!N15,'Nov 1-15'!N15,'Nov 16-30'!N15,'Dec 1-15'!N15,'Dec 16-31'!N15,'Jan 1-15'!N15,'Jan 16-31'!N15,'Feb 1-15'!N15,'Feb 16-28'!N15,'Mar 1-15'!N15) -> 0 | O15: =SUM('Sept 16-30'!O15,'Oct 1-15'!O15,'Oct 16-31'!O15,'Nov 1-15'!O15,'Nov 16-30'!O15,'Dec 1-15'!O15,'Dec 16-31'!O15,'Jan 1-15'!O15,'Jan 16-31'!O15,'Feb 1-15'!O15,'Feb 16-28'!O15,'Mar 1-15'!O15) -> 0 | P15: =SUM('Sept 16-30'!P15,'Oct 1-15'!P15,'Oct 16-31'!P15,'Nov 1-15'!P15,'Nov 16-30'!P15,'Dec 1-15'!P15,'Dec 16-31'!P15,'Jan 1-15'!P15,'Jan 16-31'!P15,'Feb 1-15'!P15,'Feb 16-28'!P15,'Mar 1-15'!P15) -> 0 | Q15: =SUM(I15:P15) -> 235.7 | R15: =SUM('Sept 16-30'!R15,'Oct 1-15'!R15,'Oct 16-31'!R15,'Nov 1-15'!R15,'Nov 16-30'!R15,'Dec 1-15'!R15,'Dec 16-31'!R15,'Jan 1-15'!R15,'Jan 16-31'!R15,'Feb 1-15'!R15,'Feb 16-28'!R15,'Mar 1-15'!R15) -> 92 | S15: =SUM('Sept 16-30'!S15,'Oct 1-15'!S15,'Oct 16-31'!S15,'Nov 1-15'!S15,'Nov 16-30'!S15,'Dec 1-15'!S15,'Dec 16-31'!S15,'Jan 1-15'!S15,'Jan 16-31'!S15,'Feb 1-15'!S15,'Feb 16-28'!S15,'Mar 1-15'!S15) -> 0 | T15: =SUM('Sept 16-30'!T15,'Oct 1-15'!T15,'Oct 16-31'!T15,'Nov 1-15'!T15,'Nov 16-30'!T15,'Dec 1-15'!T15,'Dec 16-31'!T15,'Jan 1-15'!T15,'Jan 16-31'!T15,'Feb 1-15'!T15,'Feb 16-28'!T15,'Mar 1-15'!T15) -> 176.7 | U15: =SUM('Sept 16-30'!U15,'Oct 1-15'!U15,'Oct 16-31'!U15,'Nov 1-15'!U15,'Nov 16-30'!U15,'Dec 1-15'!U15,'Dec 16-31'!U15,'Jan 1-15'!U15,'Jan 16-31'!U15,'Feb 1-15'!U15,'Feb 16-28'!U15,'Mar 1-15'!U15) -> 0 | V15: =SUM('Sept 16-30'!V15,'Oct 1-15'!V15,'Oct 16-31'!V15,'Nov 1-15'!V15,'Nov 16-30'!V15,'Dec 1-15'!V15,'Dec 16-31'!V15,'Jan 1-15'!V15,'Jan 16-31'!V15,'Feb 1-15'!V15,'Feb 16-28'!V15,'Mar 1-15'!V15) -> 23.3 | W15: =SUM(R15:V15) -> 292
A16: Culasian | B16: =SUM('Sept 16-30'!B16,'Oct 1-15'!B16,'Oct 16-31'!B16,'Nov 1-15'!B16,'Nov 16-30'!B16,'Dec 1-15'!B16,'Dec 16-31'!B16,'Jan 1-15'!B16,'Jan 16-31'!B16,'Feb 1-15'!B16,'Feb 16-28'!B16,'Mar 1-15'!B16) -> 141 | C16: =SUM('Sept 16-30'!C16,'Oct 1-15'!C16,'Oct 16-31'!C16,'Nov 1-15'!C16,'Nov 16-30'!C16,'Dec 1-15'!C16,'Dec 16-31'!C16,'Jan 1-15'!C16,'Jan 16-31'!C16,'Feb 1-15'!C16,'Feb 16-28'!C16,'Mar 1-15'!C16) -> 81.5 | D16: =SUM('Sept 16-30'!D16,'Oct 1-15'!D16,'Oct 16-31'!D16,'Nov 1-15'!D16,'Nov 16-30'!D16,'Dec 1-15'!D16,'Dec 16-31'!D16,'Jan 1-15'!D16,'Jan 16-31'!D16,'Feb 1-15'!D16,'Feb 16-28'!D16,'Mar 1-15'!D16) -> 0 | E16: =SUM('Sept 16-30'!E16,'Oct 1-15'!E16,'Oct 16-31'!E16,'Nov 1-15'!E16,'Nov 16-30'!E16,'Dec 1-15'!E16,'Dec 16-31'!E16,'Jan 1-15'!E16,'Jan 16-31'!E16,'Feb 1-15'!E16,'Feb 16-28'!E16,'Mar 1-15'!E16) -> 82.9 | F16: =SUM('Sept 16-30'!F16,'Oct 1-15'!F16,'Oct 16-31'!F16,'Nov 1-15'!F16,'Nov 16-30'!F16,'Dec 1-15'!F16,'Dec 16-31'!F16,'Jan 1-15'!F16,'Jan 16-31'!F16,'Feb 1-15'!F16,'Feb 16-28'!F16,'Mar 1-15'!F16) -> 0 | G16: =SUM('Sept 16-30'!G16,'Oct 1-15'!G16,'Oct 16-31'!G16,'Nov 1-15'!G16,'Nov 16-30'!G16,'Dec 1-15'!G16,'Dec 16-31'!G16,'Jan 1-15'!G16,'Jan 16-31'!G16,'Feb 1-15'!G16,'Feb 16-28'!G16,'Mar 1-15'!G16) -> 11 | H16: =SUM(C16:G16) -> 175.4 | I16: =SUM('Sept 16-30'!I16,'Oct 1-15'!I16,'Oct 16-31'!I16,'Nov 1-15'!I16,'Nov 16-30'!I16,'Dec 1-15'!I16,'Dec 16-31'!I16,'Jan 1-15'!I16,'Jan 16-31'!I16,'Feb 1-15'!I16,'Feb 16-28'!I16,'Mar 1-15'!I16) -> 0 | J16: =SUM('Sept 16-30'!J16,'Oct 1-15'!J16,'Oct 16-31'!J16,'Nov 1-15'!J16,'Nov 16-30'!J16,'Dec 1-15'!J16,'Dec 16-31'!J16,'Jan 1-15'!J16,'Jan 16-31'!J16,'Feb 1-15'!J16,'Feb 16-28'!J16,'Mar 1-15'!J16) -> 0 | K16: =SUM('Sept 16-30'!K16,'Oct 1-15'!K16,'Oct 16-31'!K16,'Nov 1-15'!K16,'Nov 16-30'!K16,'Dec 1-15'!K16,'Dec 16-31'!K16,'Jan 1-15'!K16,'Jan 16-31'!K16,'Feb 1-15'!K16,'Feb 16-28'!K16,'Mar 1-15'!K16) -> 73.7 | L16: =SUM('Sept 16-30'!L16,'Oct 1-15'!L16,'Oct 16-31'!L16,'Nov 1-15'!L16,'Nov 16-30'!L16,'Dec 1-15'!L16,'Dec 16-31'!L16,'Jan 1-15'!L16,'Jan 16-31'!L16,'Feb 1-15'!L16,'Feb 16-28'!L16,'Mar 1-15'!L16) -> 0 | M16: =SUM('Sept 16-30'!M16,'Oct 1-15'!M16,'Oct 16-31'!M16,'Nov 1-15'!M16,'Nov 16-30'!M16,'Dec 1-15'!M16,'Dec 16-31'!M16,'Jan 1-15'!M16,'Jan 16-31'!M16,'Feb 1-15'!M16,'Feb 16-28'!M16,'Mar 1-15'!M16) -> 2.9 | N16: =SUM('Sept 16-30'!N16,'Oct 1-15'!N16,'Oct 16-31'!N16,'Nov 1-15'!N16,'Nov 16-30'!N16,'Dec 1-15'!N16,'Dec 16-31'!N16,'Jan 1-15'!N16,'Jan 16-31'!N16,'Feb 1-15'!N16,'Feb 16-28'!N16,'Mar 1-15'!N16) -> 0 | O16: =SUM('Sept 16-30'!O16,'Oct 1-15'!O16,'Oct 16-31'!O16,'Nov 1-15'!O16,'Nov 16-30'!O16,'Dec 1-15'!O16,'Dec 16-31'!O16,'Jan 1-15'!O16,'Jan 16-31'!O16,'Feb 1-15'!O16,'Feb 16-28'!O16,'Mar 1-15'!O16) -> 0 | P16: =SUM('Sept 16-30'!P16,'Oct 1-15'!P16,'Oct 16-31'!P16,'Nov 1-15'!P16,'Nov 16-30'!P16,'Dec 1-15'!P16,'Dec 16-31'!P16,'Jan 1-15'!P16,'Jan 16-31'!P16,'Feb 1-15'!P16,'Feb 16-28'!P16,'Mar 1-15'!P16) -> 0 | Q16: =SUM(I16:P16) -> 76.6 | R16: =SUM('Sept 16-30'!R16,'Oct 1-15'!R16,'Oct 16-31'!R16,'Nov 1-15'!R16,'Nov 16-30'!R16,'Dec 1-15'!R16,'Dec 16-31'!R16,'Jan 1-15'!R16,'Jan 16-31'!R16,'Feb 1-15'!R16,'Feb 16-28'!R16,'Mar 1-15'!R16) -> 81.5 | S16: =SUM('Sept 16-30'!S16,'Oct 1-15'!S16,'Oct 16-31'!S16,'Nov 1-15'!S16,'Nov 16-30'!S16,'Dec 1-15'!S16,'Dec 16-31'!S16,'Jan 1-15'!S16,'Jan 16-31'!S16,'Feb 1-15'!S16,'Feb 16-28'!S16,'Mar 1-15'!S16) -> 0 | T16: =SUM('Sept 16-30'!T16,'Oct 1-15'!T16,'Oct 16-31'!T16,'Nov 1-15'!T16,'Nov 16-30'!T16,'Dec 1-15'!T16,'Dec 16-31'!T16,'Jan 1-15'!T16,'Jan 16-31'!T16,'Feb 1-15'!T16,'Feb 16-28'!T16,'Mar 1-15'!T16) -> 156.6 | U16: =SUM('Sept 16-30'!U16,'Oct 1-15'!U16,'Oct 16-31'!U16,'Nov 1-15'!U16,'Nov 16-30'!U16,'Dec 1-15'!U16,'Dec 16-31'!U16,'Jan 1-15'!U16,'Jan 16-31'!U16,'Feb 1-15'!U16,'Feb 16-28'!U16,'Mar 1-15'!U16) -> 0 | V16: =SUM('Sept 16-30'!V16,'Oct 1-15'!V16,'Oct 16-31'!V16,'Nov 1-15'!V16,'Nov 16-30'!V16,'Dec 1-15'!V16,'Dec 16-31'!V16,'Jan 1-15'!V16,'Jan 16-31'!V16,'Feb 1-15'!V16,'Feb 16-28'!V16,'Mar 1-15'!V16) -> 13.9 | W16: =SUM(R16:V16) -> 252
A17: Iraan | B17: =SUM('Sept 16-30'!B17,'Oct 1-15'!B17,'Oct 16-31'!B17,'Nov 1-15'!B17,'Nov 16-30'!B17,'Dec 1-15'!B17,'Dec 16-31'!B17,'Jan 1-15'!B17,'Jan 16-31'!B17,'Feb 1-15'!B17,'Feb 16-28'!B17,'Mar 1-15'!B17) -> 341 | C17: =SUM('Sept 16-30'!C17,'Oct 1-15'!C17,'Oct 16-31'!C17,'Nov 1-15'!C17,'Nov 16-30'!C17,'Dec 1-15'!C17,'Dec 16-31'!C17,'Jan 1-15'!C17,'Jan 16-31'!C17,'Feb 1-15'!C17,'Feb 16-28'!C17,'Mar 1-15'!C17) -> 11.3 | D17: =SUM('Sept 16-30'!D17,'Oct 1-15'!D17,'Oct 16-31'!D17,'Nov 1-15'!D17,'Nov 16-30'!D17,'Dec 1-15'!D17,'Dec 16-31'!D17,'Jan 1-15'!D17,'Jan 16-31'!D17,'Feb 1-15'!D17,'Feb 16-28'!D17,'Mar 1-15'!D17) -> 0 | E17: =SUM('Sept 16-30'!E17,'Oct 1-15'!E17,'Oct 16-31'!E17,'Nov 1-15'!E17,'Nov 16-30'!E17,'Dec 1-15'!E17,'Dec 16-31'!E17,'Jan 1-15'!E17,'Jan 16-31'!E17,'Feb 1-15'!E17,'Feb 16-28'!E17,'Mar 1-15'!E17) -> 295.7 | F17: =SUM('Sept 16-30'!F17,'Oct 1-15'!F17,'Oct 16-31'!F17,'Nov 1-15'!F17,'Nov 16-30'!F17,'Dec 1-15'!F17,'Dec 16-31'!F17,'Jan 1-15'!F17,'Jan 16-31'!F17,'Feb 1-15'!F17,'Feb 16-28'!F17,'Mar 1-15'!F17) -> 0 | G17: =SUM('Sept 16-30'!G17,'Oct 1-15'!G17,'Oct 16-31'!G17,'Nov 1-15'!G17,'Nov 16-30'!G17,'Dec 1-15'!G17,'Dec 16-31'!G17,'Jan 1-15'!G17,'Jan 16-31'!G17,'Feb 1-15'!G17,'Feb 16-28'!G17,'Mar 1-15'!G17) -> 47.19 | H17: =SUM(C17:G17) -> 354.19 | I17: =SUM('Sept 16-30'!I17,'Oct 1-15'!I17,'Oct 16-31'!I17,'Nov 1-15'!I17,'Nov 16-30'!I17,'Dec 1-15'!I17,'Dec 16-31'!I17,'Jan 1-15'!I17,'Jan 16-31'!I17,'Feb 1-15'!I17,'Feb 16-28'!I17,'Mar 1-15'!I17) -> 15 | J17: =SUM('Sept 16-30'!J17,'Oct 1-15'!J17,'Oct 16-31'!J17,'Nov 1-15'!J17,'Nov 16-30'!J17,'Dec 1-15'!J17,'Dec 16-31'!J17,'Jan 1-15'!J17,'Jan 16-31'!J17,'Feb 1-15'!J17,'Feb 16-28'!J17,'Mar 1-15'!J17) -> 0 | K17: =SUM('Sept 16-30'!K17,'Oct 1-15'!K17,'Oct 16-31'!K17,'Nov 1-15'!K17,'Nov 16-30'!K17,'Dec 1-15'!K17,'Dec 16-31'!K17,'Jan 1-15'!K17,'Jan 16-31'!K17,'Feb 1-15'!K17,'Feb 16-28'!K17,'Mar 1-15'!K17) -> 181 | L17: =SUM('Sept 16-30'!L17,'Oct 1-15'!L17,'Oct 16-31'!L17,'Nov 1-15'!L17,'Nov 16-30'!L17,'Dec 1-15'!L17,'Dec 16-31'!L17,'Jan 1-15'!L17,'Jan 16-31'!L17,'Feb 1-15'!L17,'Feb 16-28'!L17,'Mar 1-15'!L17) -> 0 | M17: =SUM('Sept 16-30'!M17,'Oct 1-15'!M17,'Oct 16-31'!M17,'Nov 1-15'!M17,'Nov 16-30'!M17,'Dec 1-15'!M17,'Dec 16-31'!M17,'Jan 1-15'!M17,'Jan 16-31'!M17,'Feb 1-15'!M17,'Feb 16-28'!M17,'Mar 1-15'!M17) -> 43 | N17: =SUM('Sept 16-30'!N17,'Oct 1-15'!N17,'Oct 16-31'!N17,'Nov 1-15'!N17,'Nov 16-30'!N17,'Dec 1-15'!N17,'Dec 16-31'!N17,'Jan 1-15'!N17,'Jan 16-31'!N17,'Feb 1-15'!N17,'Feb 16-28'!N17,'Mar 1-15'!N17) -> 0 | O17: =SUM('Sept 16-30'!O17,'Oct 1-15'!O17,'Oct 16-31'!O17,'Nov 1-15'!O17,'Nov 16-30'!O17,'Dec 1-15'!O17,'Dec 16-31'!O17,'Jan 1-15'!O17,'Jan 16-31'!O17,'Feb 1-15'!O17,'Feb 16-28'!O17,'Mar 1-15'!O17) -> 0 | P17: =SUM('Sept 16-30'!P17,'Oct 1-15'!P17,'Oct 16-31'!P17,'Nov 1-15'!P17,'Nov 16-30'!P17,'Dec 1-15'!P17,'Dec 16-31'!P17,'Jan 1-15'!P17,'Jan 16-31'!P17,'Feb 1-15'!P17,'Feb 16-28'!P17,'Mar 1-15'!P17) -> 0 | Q17: =SUM(I17:P17) -> 239 | R17: =SUM('Sept 16-30'!R17,'Oct 1-15'!R17,'Oct 16-31'!R17,'Nov 1-15'!R17,'Nov 16-30'!R17,'Dec 1-15'!R17,'Dec 16-31'!R17,'Jan 1-15'!R17,'Jan 16-31'!R17,'Feb 1-15'!R17,'Feb 16-28'!R17,'Mar 1-15'!R17) -> 26.3 | S17: =SUM('Sept 16-30'!S17,'Oct 1-15'!S17,'Oct 16-31'!S17,'Nov 1-15'!S17,'Nov 16-30'!S17,'Dec 1-15'!S17,'Dec 16-31'!S17,'Jan 1-15'!S17,'Jan 16-31'!S17,'Feb 1-15'!S17,'Feb 16-28'!S17,'Mar 1-15'!S17) -> 0 | T17: =SUM('Sept 16-30'!T17,'Oct 1-15'!T17,'Oct 16-31'!T17,'Nov 1-15'!T17,'Nov 16-30'!T17,'Dec 1-15'!T17,'Dec 16-31'!T17,'Jan 1-15'!T17,'Jan 16-31'!T17,'Feb 1-15'!T17,'Feb 16-28'!T17,'Mar 1-15'!T17) -> 476.7 | U17: =SUM('Sept 16-30'!U17,'Oct 1-15'!U17,'Oct 16-31'!U17,'Nov 1-15'!U17,'Nov 16-30'!U17,'Dec 1-15'!U17,'Dec 16-31'!U17,'Jan 1-15'!U17,'Jan 16-31'!U17,'Feb 1-15'!U17,'Feb 16-28'!U17,'Mar 1-15'!U17) -> 0 | V17: =SUM('Sept 16-30'!V17,'Oct 1-15'!V17,'Oct 16-31'!V17,'Nov 1-15'!V17,'Nov 16-30'!V17,'Dec 1-15'!V17,'Dec 16-31'!V17,'Jan 1-15'!V17,'Jan 16-31'!V17,'Feb 1-15'!V17,'Feb 16-28'!V17,'Mar 1-15'!V17) -> 90.19 | W17: =SUM(R17:V17) -> 593.19
A18: Latud | B18: =SUM('Sept 16-30'!B18,'Oct 1-15'!B18,'Oct 16-31'!B18,'Nov 1-15'!B18,'Nov 16-30'!B18,'Dec 1-15'!B18,'Dec 16-31'!B18,'Jan 1-15'!B18,'Jan 16-31'!B18,'Feb 1-15'!B18,'Feb 16-28'!B18,'Mar 1-15'!B18) -> 54 | C18: =SUM('Sept 16-30'!C18,'Oct 1-15'!C18,'Oct 16-31'!C18,'Nov 1-15'!C18,'Nov 16-30'!C18,'Dec 1-15'!C18,'Dec 16-31'!C18,'Jan 1-15'!C18,'Jan 16-31'!C18,'Feb 1-15'!C18,'Feb 16-28'!C18,'Mar 1-15'!C18) -> 0 | D18: =SUM('Sept 16-30'!D18,'Oct 1-15'!D18,'Oct 16-31'!D18,'Nov 1-15'!D18,'Nov 16-30'!D18,'Dec 1-15'!D18,'Dec 16-31'!D18,'Jan 1-15'!D18,'Jan 16-31'!D18,'Feb 1-15'!D18,'Feb 16-28'!D18,'Mar 1-15'!D18) -> 0 | E18: =SUM('Sept 16-30'!E18,'Oct 1-15'!E18,'Oct 16-31'!E18,'Nov 1-15'!E18,'Nov 16-30'!E18,'Dec 1-15'!E18,'Dec 16-31'!E18,'Jan 1-15'!E18,'Jan 16-31'!E18,'Feb 1-15'!E18,'Feb 16-28'!E18,'Mar 1-15'!E18) -> 18.5 | F18: =SUM('Sept 16-30'!F18,'Oct 1-15'!F18,'Oct 16-31'!F18,'Nov 1-15'!F18,'Nov 16-30'!F18,'Dec 1-15'!F18,'Dec 16-31'!F18,'Jan 1-15'!F18,'Jan 16-31'!F18,'Feb 1-15'!F18,'Feb 16-28'!F18,'Mar 1-15'!F18) -> 0 | G18: =SUM('Sept 16-30'!G18,'Oct 1-15'!G18,'Oct 16-31'!G18,'Nov 1-15'!G18,'Nov 16-30'!G18,'Dec 1-15'!G18,'Dec 16-31'!G18,'Jan 1-15'!G18,'Jan 16-31'!G18,'Feb 1-15'!G18,'Feb 16-28'!G18,'Mar 1-15'!G18) -> 0 | H18: =SUM(C18:G18) -> 18.5 | I18: =SUM('Sept 16-30'!I18,'Oct 1-15'!I18,'Oct 16-31'!I18,'Nov 1-15'!I18,'Nov 16-30'!I18,'Dec 1-15'!I18,'Dec 16-31'!I18,'Jan 1-15'!I18,'Jan 16-31'!I18,'Feb 1-15'!I18,'Feb 16-28'!I18,'Mar 1-15'!I18) -> 40.3 | J18: =SUM('Sept 16-30'!J18,'Oct 1-15'!J18,'Oct 16-31'!J18,'Nov 1-15'!J18,'Nov 16-30'!J18,'Dec 1-15'!J18,'Dec 16-31'!J18,'Jan 1-15'!J18,'Jan 16-31'!J18,'Feb 1-15'!J18,'Feb 16-28'!J18,'Mar 1-15'!J18) -> 0 | K18: =SUM('Sept 16-30'!K18,'Oct 1-15'!K18,'Oct 16-31'!K18,'Nov 1-15'!K18,'Nov 16-30'!K18,'Dec 1-15'!K18,'Dec 16-31'!K18,'Jan 1-15'!K18,'Jan 16-31'!K18,'Feb 1-15'!K18,'Feb 16-28'!K18,'Mar 1-15'!K18) -> 52 | L18: =SUM('Sept 16-30'!L18,'Oct 1-15'!L18,'Oct 16-31'!L18,'Nov 1-15'!L18,'Nov 16-30'!L18,'Dec 1-15'!L18,'Dec 16-31'!L18,'Jan 1-15'!L18,'Jan 16-31'!L18,'Feb 1-15'!L18,'Feb 16-28'!L18,'Mar 1-15'!L18) -> 0 | M18: =SUM('Sept 16-30'!M18,'Oct 1-15'!M18,'Oct 16-31'!M18,'Nov 1-15'!M18,'Nov 16-30'!M18,'Dec 1-15'!M18,'Dec 16-31'!M18,'Jan 1-15'!M18,'Jan 16-31'!M18,'Feb 1-15'!M18,'Feb 16-28'!M18,'Mar 1-15'!M18) -> 0 | N18: =SUM('Sept 16-30'!N18,'Oct 1-15'!N18,'Oct 16-31'!N18,'Nov 1-15'!N18,'Nov 16-30'!N18,'Dec 1-15'!N18,'Dec 16-31'!N18,'Jan 1-15'!N18,'Jan 16-31'!N18,'Feb 1-15'!N18,'Feb 16-28'!N18,'Mar 1-15'!N18) -> 0 | O18: =SUM('Sept 16-30'!O18,'Oct 1-15'!O18,'Oct 16-31'!O18,'Nov 1-15'!O18,'Nov 16-30'!O18,'Dec 1-15'!O18,'Dec 16-31'!O18,'Jan 1-15'!O18,'Jan 16-31'!O18,'Feb 1-15'!O18,'Feb 16-28'!O18,'Mar 1-15'!O18) -> 0 | P18: =SUM('Sept 16-30'!P18,'Oct 1-15'!P18,'Oct 16-31'!P18,'Nov 1-15'!P18,'Nov 16-30'!P18,'Dec 1-15'!P18,'Dec 16-31'!P18,'Jan 1-15'!P18,'Jan 16-31'!P18,'Feb 1-15'!P18,'Feb 16-28'!P18,'Mar 1-15'!P18) -> 0 | Q18: =SUM(I18:P18) -> 92.3 | R18: =SUM('Sept 16-30'!R18,'Oct 1-15'!R18,'Oct 16-31'!R18,'Nov 1-15'!R18,'Nov 16-30'!R18,'Dec 1-15'!R18,'Dec 16-31'!R18,'Jan 1-15'!R18,'Jan 16-31'!R18,'Feb 1-15'!R18,'Feb 16-28'!R18,'Mar 1-15'!R18) -> 40.3 | S18: =SUM('Sept 16-30'!S18,'Oct 1-15'!S18,'Oct 16-31'!S18,'Nov 1-15'!S18,'Nov 16-30'!S18,'Dec 1-15'!S18,'Dec 16-31'!S18,'Jan 1-15'!S18,'Jan 16-31'!S18,'Feb 1-15'!S18,'Feb 16-28'!S18,'Mar 1-15'!S18) -> 0 | T18: =SUM('Sept 16-30'!T18,'Oct 1-15'!T18,'Oct 16-31'!T18,'Nov 1-15'!T18,'Nov 16-30'!T18,'Dec 1-15'!T18,'Dec 16-31'!T18,'Jan 1-15'!T18,'Jan 16-31'!T18,'Feb 1-15'!T18,'Feb 16-28'!T18,'Mar 1-15'!T18) -> 70.5 | U18: =SUM('Sept 16-30'!U18,'Oct 1-15'!U18,'Oct 16-31'!U18,'Nov 1-15'!U18,'Nov 16-30'!U18,'Dec 1-15'!U18,'Dec 16-31'!U18,'Jan 1-15'!U18,'Jan 16-31'!U18,'Feb 1-15'!U18,'Feb 16-28'!U18,'Mar 1-15'!U18) -> 0 | V18: =SUM('Sept 16-30'!V18,'Oct 1-15'!V18,'Oct 16-31'!V18,'Nov 1-15'!V18,'Nov 16-30'!V18,'Dec 1-15'!V18,'Dec 16-31'!V18,'Jan 1-15'!V18,'Jan 16-31'!V18,'Feb 1-15'!V18,'Feb 16-28'!V18,'Mar 1-15'!V18) -> 0 | W18: =SUM(R18:V18) -> 110.8
A19: Panalingaan | B19: =SUM('Sept 16-30'!B19,'Oct 1-15'!B19,'Oct 16-31'!B19,'Nov 1-15'!B19,'Nov 16-30'!B19,'Dec 1-15'!B19,'Dec 16-31'!B19,'Jan 1-15'!B19,'Jan 16-31'!B19,'Feb 1-15'!B19,'Feb 16-28'!B19,'Mar 1-15'!B19) -> 239 | C19: =SUM('Sept 16-30'!C19,'Oct 1-15'!C19,'Oct 16-31'!C19,'Nov 1-15'!C19,'Nov 16-30'!C19,'Dec 1-15'!C19,'Dec 16-31'!C19,'Jan 1-15'!C19,'Jan 16-31'!C19,'Feb 1-15'!C19,'Feb 16-28'!C19,'Mar 1-15'!C19) -> 144.51 | D19: =SUM('Sept 16-30'!D19,'Oct 1-15'!D19,'Oct 16-31'!D19,'Nov 1-15'!D19,'Nov 16-30'!D19,'Dec 1-15'!D19,'Dec 16-31'!D19,'Jan 1-15'!D19,'Jan 16-31'!D19,'Feb 1-15'!D19,'Feb 16-28'!D19,'Mar 1-15'!D19) -> 0 | E19: =SUM('Sept 16-30'!E19,'Oct 1-15'!E19,'Oct 16-31'!E19,'Nov 1-15'!E19,'Nov 16-30'!E19,'Dec 1-15'!E19,'Dec 16-31'!E19,'Jan 1-15'!E19,'Jan 16-31'!E19,'Feb 1-15'!E19,'Feb 16-28'!E19,'Mar 1-15'!E19) -> 126.65 | F19: =SUM('Sept 16-30'!F19,'Oct 1-15'!F19,'Oct 16-31'!F19,'Nov 1-15'!F19,'Nov 16-30'!F19,'Dec 1-15'!F19,'Dec 16-31'!F19,'Jan 1-15'!F19,'Jan 16-31'!F19,'Feb 1-15'!F19,'Feb 16-28'!F19,'Mar 1-15'!F19) -> 0 | G19: =SUM('Sept 16-30'!G19,'Oct 1-15'!G19,'Oct 16-31'!G19,'Nov 1-15'!G19,'Nov 16-30'!G19,'Dec 1-15'!G19,'Dec 16-31'!G19,'Jan 1-15'!G19,'Jan 16-31'!G19,'Feb 1-15'!G19,'Feb 16-28'!G19,'Mar 1-15'!G19) -> 17.7 | H19: =SUM(C19:G19) -> 288.86 | I19: =SUM('Sept 16-30'!I19,'Oct 1-15'!I19,'Oct 16-31'!I19,'Nov 1-15'!I19,'Nov 16-30'!I19,'Dec 1-15'!I19,'Dec 16-31'!I19,'Jan 1-15'!I19,'Jan 16-31'!I19,'Feb 1-15'!I19,'Feb 16-28'!I19,'Mar 1-15'!I19) -> 40 | J19: =SUM('Sept 16-30'!J19,'Oct 1-15'!J19,'Oct 16-31'!J19,'Nov 1-15'!J19,'Nov 16-30'!J19,'Dec 1-15'!J19,'Dec 16-31'!J19,'Jan 1-15'!J19,'Jan 16-31'!J19,'Feb 1-15'!J19,'Feb 16-28'!J19,'Mar 1-15'!J19) -> 0 | K19: =SUM('Sept 16-30'!K19,'Oct 1-15'!K19,'Oct 16-31'!K19,'Nov 1-15'!K19,'Nov 16-30'!K19,'Dec 1-15'!K19,'Dec 16-31'!K19,'Jan 1-15'!K19,'Jan 16-31'!K19,'Feb 1-15'!K19,'Feb 16-28'!K19,'Mar 1-15'!K19) -> 47.5 | L19: =SUM('Sept 16-30'!L19,'Oct 1-15'!L19,'Oct 16-31'!L19,'Nov 1-15'!L19,'Nov 16-30'!L19,'Dec 1-15'!L19,'Dec 16-31'!L19,'Jan 1-15'!L19,'Jan 16-31'!L19,'Feb 1-15'!L19,'Feb 16-28'!L19,'Mar 1-15'!L19) -> 0 | M19: =SUM('Sept 16-30'!M19,'Oct 1-15'!M19,'Oct 16-31'!M19,'Nov 1-15'!M19,'Nov 16-30'!M19,'Dec 1-15'!M19,'Dec 16-31'!M19,'Jan 1-15'!M19,'Jan 16-31'!M19,'Feb 1-15'!M19,'Feb 16-28'!M19,'Mar 1-15'!M19) -> 8.5 | N19: =SUM('Sept 16-30'!N19,'Oct 1-15'!N19,'Oct 16-31'!N19,'Nov 1-15'!N19,'Nov 16-30'!N19,'Dec 1-15'!N19,'Dec 16-31'!N19,'Jan 1-15'!N19,'Jan 16-31'!N19,'Feb 1-15'!N19,'Feb 16-28'!N19,'Mar 1-15'!N19) -> 0 | O19: =SUM('Sept 16-30'!O19,'Oct 1-15'!O19,'Oct 16-31'!O19,'Nov 1-15'!O19,'Nov 16-30'!O19,'Dec 1-15'!O19,'Dec 16-31'!O19,'Jan 1-15'!O19,'Jan 16-31'!O19,'Feb 1-15'!O19,'Feb 16-28'!O19,'Mar 1-15'!O19) -> 0 | P19: =SUM('Sept 16-30'!P19,'Oct 1-15'!P19,'Oct 16-31'!P19,'Nov 1-15'!P19,'Nov 16-30'!P19,'Dec 1-15'!P19,'Dec 16-31'!P19,'Jan 1-15'!P19,'Jan 16-31'!P19,'Feb 1-15'!P19,'Feb 16-28'!P19,'Mar 1-15'!P19) -> 0 | Q19: =SUM(I19:P19) -> 96 | R19: =SUM('Sept 16-30'!R19,'Oct 1-15'!R19,'Oct 16-31'!R19,'Nov 1-15'!R19,'Nov 16-30'!R19,'Dec 1-15'!R19,'Dec 16-31'!R19,'Jan 1-15'!R19,'Jan 16-31'!R19,'Feb 1-15'!R19,'Feb 16-28'!R19,'Mar 1-15'!R19) -> 184.51 | S19: =SUM('Sept 16-30'!S19,'Oct 1-15'!S19,'Oct 16-31'!S19,'Nov 1-15'!S19,'Nov 16-30'!S19,'Dec 1-15'!S19,'Dec 16-31'!S19,'Jan 1-15'!S19,'Jan 16-31'!S19,'Feb 1-15'!S19,'Feb 16-28'!S19,'Mar 1-15'!S19) -> 0 | T19: =SUM('Sept 16-30'!T19,'Oct 1-15'!T19,'Oct 16-31'!T19,'Nov 1-15'!T19,'Nov 16-30'!T19,'Dec 1-15'!T19,'Dec 16-31'!T19,'Jan 1-15'!T19,'Jan 16-31'!T19,'Feb 1-15'!T19,'Feb 16-28'!T19,'Mar 1-15'!T19) -> 174.15 | U19: =SUM('Sept 16-30'!U19,'Oct 1-15'!U19,'Oct 16-31'!U19,'Nov 1-15'!U19,'Nov 16-30'!U19,'Dec 1-15'!U19,'Dec 16-31'!U19,'Jan 1-15'!U19,'Jan 16-31'!U19,'Feb 1-15'!U19,'Feb 16-28'!U19,'Mar 1-15'!U19) -> 0 | V19: =SUM('Sept 16-30'!V19,'Oct 1-15'!V19,'Oct 16-31'!V19,'Nov 1-15'!V19,'Nov 16-30'!V19,'Dec 1-15'!V19,'Dec 16-31'!V19,'Jan 1-15'!V19,'Jan 16-31'!V19,'Feb 1-15'!V19,'Feb 16-28'!V19,'Mar 1-15'!V19) -> 26.2 | W19: =SUM(R19:V19) -> 384.86
A20: Punta Baja | B20: =SUM('Sept 16-30'!B20,'Oct 1-15'!B20,'Oct 16-31'!B20,'Nov 1-15'!B20,'Nov 16-30'!B20,'Dec 1-15'!B20,'Dec 16-31'!B20,'Jan 1-15'!B20,'Jan 16-31'!B20,'Feb 1-15'!B20,'Feb 16-28'!B20,'Mar 1-15'!B20) -> 365 | C20: =SUM('Sept 16-30'!C20,'Oct 1-15'!C20,'Oct 16-31'!C20,'Nov 1-15'!C20,'Nov 16-30'!C20,'Dec 1-15'!C20,'Dec 16-31'!C20,'Jan 1-15'!C20,'Jan 16-31'!C20,'Feb 1-15'!C20,'Feb 16-28'!C20,'Mar 1-15'!C20) -> 305.05 | D20: =SUM('Sept 16-30'!D20,'Oct 1-15'!D20,'Oct 16-31'!D20,'Nov 1-15'!D20,'Nov 16-30'!D20,'Dec 1-15'!D20,'Dec 16-31'!D20,'Jan 1-15'!D20,'Jan 16-31'!D20,'Feb 1-15'!D20,'Feb 16-28'!D20,'Mar 1-15'!D20) -> 0 | E20: =SUM('Sept 16-30'!E20,'Oct 1-15'!E20,'Oct 16-31'!E20,'Nov 1-15'!E20,'Nov 16-30'!E20,'Dec 1-15'!E20,'Dec 16-31'!E20,'Jan 1-15'!E20,'Jan 16-31'!E20,'Feb 1-15'!E20,'Feb 16-28'!E20,'Mar 1-15'!E20) -> 364.6 | F20: =SUM('Sept 16-30'!F20,'Oct 1-15'!F20,'Oct 16-31'!F20,'Nov 1-15'!F20,'Nov 16-30'!F20,'Dec 1-15'!F20,'Dec 16-31'!F20,'Jan 1-15'!F20,'Jan 16-31'!F20,'Feb 1-15'!F20,'Feb 16-28'!F20,'Mar 1-15'!F20) -> 0 | G20: =SUM('Sept 16-30'!G20,'Oct 1-15'!G20,'Oct 16-31'!G20,'Nov 1-15'!G20,'Nov 16-30'!G20,'Dec 1-15'!G20,'Dec 16-31'!G20,'Jan 1-15'!G20,'Jan 16-31'!G20,'Feb 1-15'!G20,'Feb 16-28'!G20,'Mar 1-15'!G20) -> 12.3 | H20: =SUM(C20:G20) -> 681.95 | I20: =SUM('Sept 16-30'!I20,'Oct 1-15'!I20,'Oct 16-31'!I20,'Nov 1-15'!I20,'Nov 16-30'!I20,'Dec 1-15'!I20,'Dec 16-31'!I20,'Jan 1-15'!I20,'Jan 16-31'!I20,'Feb 1-15'!I20,'Feb 16-28'!I20,'Mar 1-15'!I20) -> 10.5 | J20: =SUM('Sept 16-30'!J20,'Oct 1-15'!J20,'Oct 16-31'!J20,'Nov 1-15'!J20,'Nov 16-30'!J20,'Dec 1-15'!J20,'Dec 16-31'!J20,'Jan 1-15'!J20,'Jan 16-31'!J20,'Feb 1-15'!J20,'Feb 16-28'!J20,'Mar 1-15'!J20) -> 0 | K20: =SUM('Sept 16-30'!K20,'Oct 1-15'!K20,'Oct 16-31'!K20,'Nov 1-15'!K20,'Nov 16-30'!K20,'Dec 1-15'!K20,'Dec 16-31'!K20,'Jan 1-15'!K20,'Jan 16-31'!K20,'Feb 1-15'!K20,'Feb 16-28'!K20,'Mar 1-15'!K20) -> 29.5 | L20: =SUM('Sept 16-30'!L20,'Oct 1-15'!L20,'Oct 16-31'!L20,'Nov 1-15'!L20,'Nov 16-30'!L20,'Dec 1-15'!L20,'Dec 16-31'!L20,'Jan 1-15'!L20,'Jan 16-31'!L20,'Feb 1-15'!L20,'Feb 16-28'!L20,'Mar 1-15'!L20) -> 0 | M20: =SUM('Sept 16-30'!M20,'Oct 1-15'!M20,'Oct 16-31'!M20,'Nov 1-15'!M20,'Nov 16-30'!M20,'Dec 1-15'!M20,'Dec 16-31'!M20,'Jan 1-15'!M20,'Jan 16-31'!M20,'Feb 1-15'!M20,'Feb 16-28'!M20,'Mar 1-15'!M20) -> 4 | N20: =SUM('Sept 16-30'!N20,'Oct 1-15'!N20,'Oct 16-31'!N20,'Nov 1-15'!N20,'Nov 16-30'!N20,'Dec 1-15'!N20,'Dec 16-31'!N20,'Jan 1-15'!N20,'Jan 16-31'!N20,'Feb 1-15'!N20,'Feb 16-28'!N20,'Mar 1-15'!N20) -> 0 | O20: =SUM('Sept 16-30'!O20,'Oct 1-15'!O20,'Oct 16-31'!O20,'Nov 1-15'!O20,'Nov 16-30'!O20,'Dec 1-15'!O20,'Dec 16-31'!O20,'Jan 1-15'!O20,'Jan 16-31'!O20,'Feb 1-15'!O20,'Feb 16-28'!O20,'Mar 1-15'!O20) -> 0 | P20: =SUM('Sept 16-30'!P20,'Oct 1-15'!P20,'Oct 16-31'!P20,'Nov 1-15'!P20,'Nov 16-30'!P20,'Dec 1-15'!P20,'Dec 16-31'!P20,'Jan 1-15'!P20,'Jan 16-31'!P20,'Feb 1-15'!P20,'Feb 16-28'!P20,'Mar 1-15'!P20) -> 0 | Q20: =SUM(I20:P20) -> 44 | R20: =SUM('Sept 16-30'!R20,'Oct 1-15'!R20,'Oct 16-31'!R20,'Nov 1-15'!R20,'Nov 16-30'!R20,'Dec 1-15'!R20,'Dec 16-31'!R20,'Jan 1-15'!R20,'Jan 16-31'!R20,'Feb 1-15'!R20,'Feb 16-28'!R20,'Mar 1-15'!R20) -> 315.55 | S20: =SUM('Sept 16-30'!S20,'Oct 1-15'!S20,'Oct 16-31'!S20,'Nov 1-15'!S20,'Nov 16-30'!S20,'Dec 1-15'!S20,'Dec 16-31'!S20,'Jan 1-15'!S20,'Jan 16-31'!S20,'Feb 1-15'!S20,'Feb 16-28'!S20,'Mar 1-15'!S20) -> 0 | T20: =SUM('Sept 16-30'!T20,'Oct 1-15'!T20,'Oct 16-31'!T20,'Nov 1-15'!T20,'Nov 16-30'!T20,'Dec 1-15'!T20,'Dec 16-31'!T20,'Jan 1-15'!T20,'Jan 16-31'!T20,'Feb 1-15'!T20,'Feb 16-28'!T20,'Mar 1-15'!T20) -> 394.1 | U20: =SUM('Sept 16-30'!U20,'Oct 1-15'!U20,'Oct 16-31'!U20,'Nov 1-15'!U20,'Nov 16-30'!U20,'Dec 1-15'!U20,'Dec 16-31'!U20,'Jan 1-15'!U20,'Jan 16-31'!U20,'Feb 1-15'!U20,'Feb 16-28'!U20,'Mar 1-15'!U20) -> 0 | V20: =SUM('Sept 16-30'!V20,'Oct 1-15'!V20,'Oct 16-31'!V20,'Nov 1-15'!V20,'Nov 16-30'!V20,'Dec 1-15'!V20,'Dec 16-31'!V20,'Jan 1-15'!V20,'Jan 16-31'!V20,'Feb 1-15'!V20,'Feb 16-28'!V20,'Mar 1-15'!V20) -> 11.3 | W20: =SUM(R20:V20) -> 720.95
A21: Ransang | B21: =SUM('Sept 16-30'!B21,'Oct 1-15'!B21,'Oct 16-31'!B21,'Nov 1-15'!B21,'Nov 16-30'!B21,'Dec 1-15'!B21,'Dec 16-31'!B21,'Jan 1-15'!B21,'Jan 16-31'!B21,'Feb 1-15'!B21,'Feb 16-28'!B21,'Mar 1-15'!B21) -> 79 | C21: =SUM('Sept 16-30'!C21,'Oct 1-15'!C21,'Oct 16-31'!C21,'Nov 1-15'!C21,'Nov 16-30'!C21,'Dec 1-15'!C21,'Dec 16-31'!C21,'Jan 1-15'!C21,'Jan 16-31'!C21,'Feb 1-15'!C21,'Feb 16-28'!C21,'Mar 1-15'!C21) -> 87.5933 | D21: =SUM('Sept 16-30'!D21,'Oct 1-15'!D21,'Oct 16-31'!D21,'Nov 1-15'!D21,'Nov 16-30'!D21,'Dec 1-15'!D21,'Dec 16-31'!D21,'Jan 1-15'!D21,'Jan 16-31'!D21,'Feb 1-15'!D21,'Feb 16-28'!D21,'Mar 1-15'!D21) -> 0 | E21: =SUM('Sept 16-30'!E21,'Oct 1-15'!E21,'Oct 16-31'!E21,'Nov 1-15'!E21,'Nov 16-30'!E21,'Dec 1-15'!E21,'Dec 16-31'!E21,'Jan 1-15'!E21,'Jan 16-31'!E21,'Feb 1-15'!E21,'Feb 16-28'!E21,'Mar 1-15'!E21) -> 13.4 | F21: =SUM('Sept 16-30'!F21,'Oct 1-15'!F21,'Oct 16-31'!F21,'Nov 1-15'!F21,'Nov 16-30'!F21,'Dec 1-15'!F21,'Dec 16-31'!F21,'Jan 1-15'!F21,'Jan 16-31'!F21,'Feb 1-15'!F21,'Feb 16-28'!F21,'Mar 1-15'!F21) -> 0 | G21: =SUM('Sept 16-30'!G21,'Oct 1-15'!G21,'Oct 16-31'!G21,'Nov 1-15'!G21,'Nov 16-30'!G21,'Dec 1-15'!G21,'Dec 16-31'!G21,'Jan 1-15'!G21,'Jan 16-31'!G21,'Feb 1-15'!G21,'Feb 16-28'!G21,'Mar 1-15'!G21) -> 5.4 | H21: =SUM(C21:G21) -> 106.3933 | I21: =SUM('Sept 16-30'!I21,'Oct 1-15'!I21,'Oct 16-31'!I21,'Nov 1-15'!I21,'Nov 16-30'!I21,'Dec 1-15'!I21,'Dec 16-31'!I21,'Jan 1-15'!I21,'Jan 16-31'!I21,'Feb 1-15'!I21,'Feb 16-28'!I21,'Mar 1-15'!I21) -> 12 | J21: =SUM('Sept 16-30'!J21,'Oct 1-15'!J21,'Oct 16-31'!J21,'Nov 1-15'!J21,'Nov 16-30'!J21,'Dec 1-15'!J21,'Dec 16-31'!J21,'Jan 1-15'!J21,'Jan 16-31'!J21,'Feb 1-15'!J21,'Feb 16-28'!J21,'Mar 1-15'!J21) -> 0 | K21: =SUM('Sept 16-30'!K21,'Oct 1-15'!K21,'Oct 16-31'!K21,'Nov 1-15'!K21,'Nov 16-30'!K21,'Dec 1-15'!K21,'Dec 16-31'!K21,'Jan 1-15'!K21,'Jan 16-31'!K21,'Feb 1-15'!K21,'Feb 16-28'!K21,'Mar 1-15'!K21) -> 40.6 | L21: =SUM('Sept 16-30'!L21,'Oct 1-15'!L21,'Oct 16-31'!L21,'Nov 1-15'!L21,'Nov 16-30'!L21,'Dec 1-15'!L21,'Dec 16-31'!L21,'Jan 1-15'!L21,'Jan 16-31'!L21,'Feb 1-15'!L21,'Feb 16-28'!L21,'Mar 1-15'!L21) -> 0 | M21: =SUM('Sept 16-30'!M21,'Oct 1-15'!M21,'Oct 16-31'!M21,'Nov 1-15'!M21,'Nov 16-30'!M21,'Dec 1-15'!M21,'Dec 16-31'!M21,'Jan 1-15'!M21,'Jan 16-31'!M21,'Feb 1-15'!M21,'Feb 16-28'!M21,'Mar 1-15'!M21) -> 0 | N21: =SUM('Sept 16-30'!N21,'Oct 1-15'!N21,'Oct 16-31'!N21,'Nov 1-15'!N21,'Nov 16-30'!N21,'Dec 1-15'!N21,'Dec 16-31'!N21,'Jan 1-15'!N21,'Jan 16-31'!N21,'Feb 1-15'!N21,'Feb 16-28'!N21,'Mar 1-15'!N21) -> 0 | O21: =SUM('Sept 16-30'!O21,'Oct 1-15'!O21,'Oct 16-31'!O21,'Nov 1-15'!O21,'Nov 16-30'!O21,'Dec 1-15'!O21,'Dec 16-31'!O21,'Jan 1-15'!O21,'Jan 16-31'!O21,'Feb 1-15'!O21,'Feb 16-28'!O21,'Mar 1-15'!O21) -> 0 | P21: =SUM('Sept 16-30'!P21,'Oct 1-15'!P21,'Oct 16-31'!P21,'Nov 1-15'!P21,'Nov 16-30'!P21,'Dec 1-15'!P21,'Dec 16-31'!P21,'Jan 1-15'!P21,'Jan 16-31'!P21,'Feb 1-15'!P21,'Feb 16-28'!P21,'Mar 1-15'!P21) -> 0 | Q21: =SUM(I21:P21) -> 52.6 | R21: =SUM('Sept 16-30'!R21,'Oct 1-15'!R21,'Oct 16-31'!R21,'Nov 1-15'!R21,'Nov 16-30'!R21,'Dec 1-15'!R21,'Dec 16-31'!R21,'Jan 1-15'!R21,'Jan 16-31'!R21,'Feb 1-15'!R21,'Feb 16-28'!R21,'Mar 1-15'!R21) -> 99.5933 | S21: =SUM('Sept 16-30'!S21,'Oct 1-15'!S21,'Oct 16-31'!S21,'Nov 1-15'!S21,'Nov 16-30'!S21,'Dec 1-15'!S21,'Dec 16-31'!S21,'Jan 1-15'!S21,'Jan 16-31'!S21,'Feb 1-15'!S21,'Feb 16-28'!S21,'Mar 1-15'!S21) -> 0 | T21: =SUM('Sept 16-30'!T21,'Oct 1-15'!T21,'Oct 16-31'!T21,'Nov 1-15'!T21,'Nov 16-30'!T21,'Dec 1-15'!T21,'Dec 16-31'!T21,'Jan 1-15'!T21,'Jan 16-31'!T21,'Feb 1-15'!T21,'Feb 16-28'!T21,'Mar 1-15'!T21) -> 54 | U21: =SUM('Sept 16-30'!U21,'Oct 1-15'!U21,'Oct 16-31'!U21,'Nov 1-15'!U21,'Nov 16-30'!U21,'Dec 1-15'!U21,'Dec 16-31'!U21,'Jan 1-15'!U21,'Jan 16-31'!U21,'Feb 1-15'!U21,'Feb 16-28'!U21,'Mar 1-15'!U21) -> 0 | V21: =SUM('Sept 16-30'!V21,'Oct 1-15'!V21,'Oct 16-31'!V21,'Nov 1-15'!V21,'Nov 16-30'!V21,'Dec 1-15'!V21,'Dec 16-31'!V21,'Jan 1-15'!V21,'Jan 16-31'!V21,'Feb 1-15'!V21,'Feb 16-28'!V21,'Mar 1-15'!V21) -> 5.4 | W21: =SUM(R21:V21) -> 158.9933
A22: Taburi | B22: =SUM('Sept 16-30'!B22,'Oct 1-15'!B22,'Oct 16-31'!B22,'Nov 1-15'!B22,'Nov 16-30'!B22,'Dec 1-15'!B22,'Dec 16-31'!B22,'Jan 1-15'!B22,'Jan 16-31'!B22,'Feb 1-15'!B22,'Feb 16-28'!B22,'Mar 1-15'!B22) -> 260 | C22: =SUM('Sept 16-30'!C22,'Oct 1-15'!C22,'Oct 16-31'!C22,'Nov 1-15'!C22,'Nov 16-30'!C22,'Dec 1-15'!C22,'Dec 16-31'!C22,'Jan 1-15'!C22,'Jan 16-31'!C22,'Feb 1-15'!C22,'Feb 16-28'!C22,'Mar 1-15'!C22) -> 13 | D22: =SUM('Sept 16-30'!D22,'Oct 1-15'!D22,'Oct 16-31'!D22,'Nov 1-15'!D22,'Nov 16-30'!D22,'Dec 1-15'!D22,'Dec 16-31'!D22,'Jan 1-15'!D22,'Jan 16-31'!D22,'Feb 1-15'!D22,'Feb 16-28'!D22,'Mar 1-15'!D22) -> 0 | E22: =SUM('Sept 16-30'!E22,'Oct 1-15'!E22,'Oct 16-31'!E22,'Nov 1-15'!E22,'Nov 16-30'!E22,'Dec 1-15'!E22,'Dec 16-31'!E22,'Jan 1-15'!E22,'Jan 16-31'!E22,'Feb 1-15'!E22,'Feb 16-28'!E22,'Mar 1-15'!E22) -> 97.4 | F22: =SUM('Sept 16-30'!F22,'Oct 1-15'!F22,'Oct 16-31'!F22,'Nov 1-15'!F22,'Nov 16-30'!F22,'Dec 1-15'!F22,'Dec 16-31'!F22,'Jan 1-15'!F22,'Jan 16-31'!F22,'Feb 1-15'!F22,'Feb 16-28'!F22,'Mar 1-15'!F22) -> 0 | G22: =SUM('Sept 16-30'!G22,'Oct 1-15'!G22,'Oct 16-31'!G22,'Nov 1-15'!G22,'Nov 16-30'!G22,'Dec 1-15'!G22,'Dec 16-31'!G22,'Jan 1-15'!G22,'Jan 16-31'!G22,'Feb 1-15'!G22,'Feb 16-28'!G22,'Mar 1-15'!G22) -> 5.75 | H22: =SUM(C22:G22) -> 116.15 | I22: =SUM('Sept 16-30'!I22,'Oct 1-15'!I22,'Oct 16-31'!I22,'Nov 1-15'!I22,'Nov 16-30'!I22,'Dec 1-15'!I22,'Dec 16-31'!I22,'Jan 1-15'!I22,'Jan 16-31'!I22,'Feb 1-15'!I22,'Feb 16-28'!I22,'Mar 1-15'!I22) -> 106.5 | J22: =SUM('Sept 16-30'!J22,'Oct 1-15'!J22,'Oct 16-31'!J22,'Nov 1-15'!J22,'Nov 16-30'!J22,'Dec 1-15'!J22,'Dec 16-31'!J22,'Jan 1-15'!J22,'Jan 16-31'!J22,'Feb 1-15'!J22,'Feb 16-28'!J22,'Mar 1-15'!J22) -> 0 | K22: =SUM('Sept 16-30'!K22,'Oct 1-15'!K22,'Oct 16-31'!K22,'Nov 1-15'!K22,'Nov 16-30'!K22,'Dec 1-15'!K22,'Dec 16-31'!K22,'Jan 1-15'!K22,'Jan 16-31'!K22,'Feb 1-15'!K22,'Feb 16-28'!K22,'Mar 1-15'!K22) -> 150.5 | L22: =SUM('Sept 16-30'!L22,'Oct 1-15'!L22,'Oct 16-31'!L22,'Nov 1-15'!L22,'Nov 16-30'!L22,'Dec 1-15'!L22,'Dec 16-31'!L22,'Jan 1-15'!L22,'Jan 16-31'!L22,'Feb 1-15'!L22,'Feb 16-28'!L22,'Mar 1-15'!L22) -> 0 | M22: =SUM('Sept 16-30'!M22,'Oct 1-15'!M22,'Oct 16-31'!M22,'Nov 1-15'!M22,'Nov 16-30'!M22,'Dec 1-15'!M22,'Dec 16-31'!M22,'Jan 1-15'!M22,'Jan 16-31'!M22,'Feb 1-15'!M22,'Feb 16-28'!M22,'Mar 1-15'!M22) -> 0 | N22: =SUM('Sept 16-30'!N22,'Oct 1-15'!N22,'Oct 16-31'!N22,'Nov 1-15'!N22,'Nov 16-30'!N22,'Dec 1-15'!N22,'Dec 16-31'!N22,'Jan 1-15'!N22,'Jan 16-31'!N22,'Feb 1-15'!N22,'Feb 16-28'!N22,'Mar 1-15'!N22) -> 0 | O22: =SUM('Sept 16-30'!O22,'Oct 1-15'!O22,'Oct 16-31'!O22,'Nov 1-15'!O22,'Nov 16-30'!O22,'Dec 1-15'!O22,'Dec 16-31'!O22,'Jan 1-15'!O22,'Jan 16-31'!O22,'Feb 1-15'!O22,'Feb 16-28'!O22,'Mar 1-15'!O22) -> 0 | P22: =SUM('Sept 16-30'!P22,'Oct 1-15'!P22,'Oct 16-31'!P22,'Nov 1-15'!P22,'Nov 16-30'!P22,'Dec 1-15'!P22,'Dec 16-31'!P22,'Jan 1-15'!P22,'Jan 16-31'!P22,'Feb 1-15'!P22,'Feb 16-28'!P22,'Mar 1-15'!P22) -> 0 | Q22: =SUM(I22:P22) -> 257 | R22: =SUM('Sept 16-30'!R22,'Oct 1-15'!R22,'Oct 16-31'!R22,'Nov 1-15'!R22,'Nov 16-30'!R22,'Dec 1-15'!R22,'Dec 16-31'!R22,'Jan 1-15'!R22,'Jan 16-31'!R22,'Feb 1-15'!R22,'Feb 16-28'!R22,'Mar 1-15'!R22) -> 119.5 | S22: =SUM('Sept 16-30'!S22,'Oct 1-15'!S22,'Oct 16-31'!S22,'Nov 1-15'!S22,'Nov 16-30'!S22,'Dec 1-15'!S22,'Dec 16-31'!S22,'Jan 1-15'!S22,'Jan 16-31'!S22,'Feb 1-15'!S22,'Feb 16-28'!S22,'Mar 1-15'!S22) -> 0 | T22: =SUM('Sept 16-30'!T22,'Oct 1-15'!T22,'Oct 16-31'!T22,'Nov 1-15'!T22,'Nov 16-30'!T22,'Dec 1-15'!T22,'Dec 16-31'!T22,'Jan 1-15'!T22,'Jan 16-31'!T22,'Feb 1-15'!T22,'Feb 16-28'!T22,'Mar 1-15'!T22) -> 247.9 | U22: =SUM('Sept 16-30'!U22,'Oct 1-15'!U22,'Oct 16-31'!U22,'Nov 1-15'!U22,'Nov 16-30'!U22,'Dec 1-15'!U22,'Dec 16-31'!U22,'Jan 1-15'!U22,'Jan 16-31'!U22,'Feb 1-15'!U22,'Feb 16-28'!U22,'Mar 1-15'!U22) -> 0 | V22: =SUM('Sept 16-30'!V22,'Oct 1-15'!V22,'Oct 16-31'!V22,'Nov 1-15'!V22,'Nov 16-30'!V22,'Dec 1-15'!V22,'Dec 16-31'!V22,'Jan 1-15'!V22,'Jan 16-31'!V22,'Feb 1-15'!V22,'Feb 16-28'!V22,'Mar 1-15'!V22) -> 5.75 | W22: =SUM(R22:V22) -> 373.15
A24: - to be submitted every 15th and 30th day of the month
A25: - March 15 submission for terminal planting under DS cropping
A26: =-A29 -> 0

Sheet Sept 16-30
A1: Department of Agriculture
A2: REGIONAL FIELD OFFICE MIMAROPA
A3: Rice Program
A5: DRY SEASON 2026 Planting Report
A6: as of September 30, 2025
A7: MUNICIPALITY / BARANGAY | B7: NO. OF FARMER PLANTED | C7: IRRIGATED | I7: RAINFED | R7: =A5 -> DRY SEASON 2026 Planting Report | X7: REMARKS
C9: HYBRID SEEDS | D9: REGISTERED SEEDS | E9: CERTIFIED SEEDS | F9: GOOD QUALITY SEEDS | G9: FARMERS HOME SAVED SEEDS / GS | H9: TOTAL | I9: LOWLAND | N9: UPLAND | Q9: TOTAL | R9: HYBRID SEEDS | S9: REGISTERED SEEDS | T9: CERTIFIED SEEDS | U9: GOOD QUALITY SEEDS | V9: FARMERS HOME SAVED SEEDS / GS | W9: TOTAL
I10: HYBRID SEEDS | J10: REGISTERED SEEDS | K10: CERTIFIED SEEDS | L10: GOOD QUALITY SEEDS | M10: FARMERS HOME SAVED SEEDS | N10: CERTIFIED SEEDS | O10: GOOD QUALITY SEEDS | P10: FARMERS HOME SAVED SEEDS / GS
A11: Rizal | B11: =SUM(B12:B23) -> 45 | C11: =SUM(C12:C23) -> 2.6 | D11: =SUM(D12:D23) -> 0 | E11: =SUM(E12:E23) -> 30.2 | F11: =SUM(F12:F23) -> 0 | G11: =SUM(G12:G23) -> 10.1 | H11: =SUM(H12:H23) -> 42.9 | I11: =SUM(I12:I23) -> 1 | ... W11: =SUM(W12:W23) -> 73
A12: Bunog | B12: - | H12: =SUM(C12:G12) -> 0 | Q12: =SUM(I12:P12) -> 0 | R12: =C12+I12 -> 0 | S12: =D12+J12 -> 0 | T12: =E12+K12+N12 -> 0 | U12: =F12+L12+O12 -> 0 | V12: =G12+M12+P12 -> 0 | W12: =SUM(R12:V12) -> 0
A13: Campong Ulay | B13: 7 | E13: 8 | H13: =SUM(C13:G13) -> 8 | K13: 1.5 | Q13: =SUM(I13:P13) -> 1.5 | R13: =C13+I13 -> 0 | S13: =D13+J13 -> 0 | T13: =E13+K13+N13 -> 9.5 | U13: =F13+L13+O13 -> 0 | V13: =G13+M13+P13 -> 0 | W13: =SUM(R13:V13) -> 9.5
A14: Candawaga | B14: - | H14: =SUM(C14:G14) -> 0 | Q14: =SUM(I14:P14) -> 0 | R14: =C14+I14 -> 0 | S14: =D14+J14 -> 0 | T14: =E14+K14+N14 -> 0 | U14: =F14+L14+O14 -> 0 | V14: =G14+M14+P14 -> 0 | W14: =SUM(R14:V14) -> 0
A15: Canipaan | B15: 20 | E15: 5.5 | H15: =SUM(C15:G15) -> 5.5 | K15: 20.3 | M15: 3.5 | Q15: =SUM(I15:P15) -> 23.8 | R15: =C15+I15 -> 0 | S15: =D15+J15 -> 0 | T15: =E15+K15+N15 -> 25.8 | U15: =F15+L15+O15 -> 0 | V15: =G15+M15+P15 -> 3.5 | W15: =SUM(R15:V15) -> 29.3
A16: Culasian | B16: - | H16: =SUM(C16:G16) -> 0 | Q16: =SUM(I16:P16) -> 0 | R16: =C16+I16 -> 0 | S16: =D16+J16 -> 0 | T16: =E16+K16+N16 -> 0 | U16: =F16+L16+O16 -> 0 | V16: =G16+M16+P16 -> 0 | W16: =SUM(R16:V16) -> 0
A17: Iraan | B17: 6 | G17: 3.6 | H17: =SUM(C17:G17) -> 3.6 | I17: 1 | M17: 2.5 | Q17: =SUM(I17:P17) -> 3.5 | R17: =C17+I17 -> 1 | S17: =D17+J17 -> 0 | T17: =E17+K17+N17 -> 0 | U17: =F17+L17+O17 -> 0 | V17: =G17+M17+P17 -> 6.1 | W17: =SUM(R17:V17) -> 7.1
A18: Latud | B18: - | H18: =SUM(C18:G18) -> 0 | Q18: =SUM(I18:P18) -> 0 | R18: =C18+I18 -> 0 | S18: =D18+J18 -> 0 | T18: =E18+K18+N18 -> 0 | U18: =F18+L18+O18 -> 0 | V18: =G18+M18+P18 -> 0 | W18: =SUM(R18:V18) -> 0
A19: Panalingaan | B19: - | H19: =SUM(C19:G19) -> 0 | Q19: =SUM(I19:P19) -> 0 | R19: =C19+I19 -> 0 | S19: =D19+J19 -> 0 | T19: =E19+K19+N19 -> 0 | U19: =F19+L19+O19 -> 0 | V19: =G19+M19+P19 -> 0 | W19: =SUM(R19:V19) -> 0
A20: Punta Baja | B20: 8 | E20: 15.7 | G20: 2 | H20: =SUM(C20:G20) -> 17.7 | Q20: =SUM(I20:P20) -> 0 | R20: =C20+I20 -> 0 | S20: =D20+J20 -> 0 | T20: =E20+K20+N20 -> 15.7 | U20: =F20+L20+O20 -> 0 | V20: =G20+M20+P20 -> 2 | W20: =SUM(R20:V20) -> 17.7
A21: Ransang | B21: 4 | C21: 2.6 | E21: 1 | G21: 4.5 | H21: =SUM(C21:G21) -> 8.1 | K21: 1.3 | Q21: =SUM(I21:P21) -> 1.3 | R21: =C21+I21 -> 2.6 | S21: =D21+J21 -> 0 | T21: =E21+K21+N21 -> 2.3 | U21: =F21+L21+O21 -> 0 | V21: =G21+M21+P21 -> 4.5 | W21: =SUM(R21:V21) -> 9.4
A22: Taburi | B22: - | H22: =SUM(C22:G22) -> 0 | Q22: =SUM(I22:P22) -> 0 | R22: =C22+I22 -> 0 | S22: =D22+J22 -> 0 | T22: =E22+K22+N22 -> 0 | U22: =F22+L22+O22 -> 0 | V22: =G22+M22+P22 -> 0 | W22: =SUM(R22:V22) -> 0
A24: - to be submitted every 15th and 30th day of the month
A25: - March 15 submission for terminal planting under DS cropping
A26: =-A29 -> 0

Sheet Sept 16-30 Materlist (2)
A1: Department of Agriculture
A2: REGIONAL FIELD OFFICE MIMAROPA
A3: Rice Program
A5: DRY SEASON 2026 Planting Report
A6: as of Sept 30
A7: Farm Location (Barangay) | B7: Name of farmer | F7: Area Planted (Hectares) | G7: Date of Crop Establishent | H7: Location | I7: Type of Seeds and Variety | N7: Seeding Rate (Kg/Ha.) | O7: Field source of water
B8: first_name | C8: middle_name | D8: last_name | E8: ext_name | G8: (Transplanting or Broadcasting) | I8: HYBRID SEEDS | J8: REGISTERED SEEDS | K8: CERTIFIED SEEDS | L8: GOOD QUALITY SEEDS | M8: FARMERS HOME SAVED SEEDS / GS | O8: (Irrigated/ Rainfed Lowland/ Rainfed Upland)
B9: MARIANITA | C9: LEIDO | D9: EDEP | F9: 2 | H9: Campong Ulay | K9: RC 402 | O9: Irrigated
B10: ELGEN | C10: AMIRELA | D10: NOYNOYAN | F10: 2 | H10: Campong Ulay | K10: RC402 | O10: Irrigated
A11: Rizal | B11: SAIDEL | C11: ERONG | D11: PONGO | F11: 1 | H11: Campong Ulay | K11: RC402 | O11: Irrigated
A12: Bunog | B12: ROMMEL | C12: MARING | D12: PONGO | F12: 1 | H12: Campong Ulay | K12: RC402 | O12: Irrigated
A13: Campong Ulay | B13: EDWIN | C13: TUMACA | D13: SOLABO | F13: 1 | H13: Campong Ulay | K13: rc222 | O13: Irrigated
A14: Candawaga | B14: MOISES | C14: GAPILANGO | D14: TABI | F14: 1 | H14: Campong Ulay | K14: RC402 | O14: Irrigated
A15: Canipaan | B15: JOJO | D15: NOMAN | F15: 1.5 | H15: Campong Ulay | K15: RC222 | O15: Rainfed
A16: Culasian | B16: GEDION | C16: PERALTA | D16: BALDOS | F16: 1 | H16: Canipaan | K16: RC402 | O16: Rainfed
A17: Iraan | B17: GIRLIE | C17: PERALTA | D17: BALDOS | F17: 1 | H17: Canipaan | K17: RC222 | O17: Rainfed
A18: Latud | B18: ENDRITA | C18: MAMUCO | D18: BONBON | F18: 2 | H18: Canipaan | M18: BLONDE | O18: Rainfed
A19: Panalingaan | B19: ARENIO | C19: FAVILA | D19: BUNDAL | E19: JR | F19: 2 | H19: Canipaan | K19: RC402 | O19: Rainfed
A20: Punta Baja | B20: SANTONY | C20: TRINIDAD | D20: CAYAO | F20: 1 | H20: Canipaan | K20: RC402 | O20: Rainfed
A21: Ransang | B21: REX | C21: NICOR | D21: CLAVERIA | F21: 2 | H21: Canipaan | K21: rc222 | O21: Irrigated
A22: Taburi | B22: JULIO | C22: CARDIJON | D22: MAGBANUA | F22: 1 | H22: Canipaan | K22: RC402 | O22: Rainfed
B23: ANNABELLE | C23: CABATANA | D23: MANILINGAN | F23: 3 | H23: Canipaan | K23: RC222 | O23: Rainfed
B24: GUILLERMA | C24: BAYADOS | D24: MANILINGAN | F24: 1 | H24: Canipaan | K24: rc222 | O24: Rainfed
B25: BRAHIM | C25: MAGBANUA | D25: PASE | F25: 1 | H25: Canipaan | K25: rc222 | O25: Irrigated
A26: =-A29 -> 0 | B26: VICTOR | C26: MAGBANUA | D26: PASE | F26: 1 | H26: Canipaan | K26: rc402 | O26: Irrigated
B27: DOMINADOR | C27: SILAO | D27: SAGUCIO | F27: 1 | H27: Canipaan | K27: RC222 | O27: Rainfed
B28: ALBERTA | C28: CAYAO | D28: TRINIDAD | F28: 1.5 | H28: Canipaan | K28: rc222 | O28: Irrigated
B29: EDDIE | C29: BONBON | D29: TRINIDAD | F29: 1 | H29: Canipaan | K29: RC402 | O29: Rainfed
B30: ERWIN | C30: CLAVERIA | D30: TRINIDAD | F30: 2 | H30: Canipaan | K30: rc222 | O30: Rainfed
B31: QUIRICO | C31: CAYAO | D31: TRINIDAD | F31: 1 | H31: Canipaan | K31: rc22 | O31: Rainfed
B32: YOKO | C32: APOSTOL | D32: TRINIDAD | F32: 2 | H32: Canipaan | K32: RC222 | O32: Rainfed
B33: RICARDO | C33: LIGARDE | D33: VILLANUEVA | F33: 2 | H33: Canipaan | K33: rc218 | O33: Rainfed
B34: angella | C34: cayao | D34: trinidad | F34: 1.3 | H34: Canipaan | K34: rc222 | O34: Rainfed
B35: LILIA | C35: BONBON | D35: TRINIDAD | F35: 1.5 | H35: Canipaan | M35: BLONDE | O35: Rainfed
B36: LILIA | C36: ASPERA | D36: AZUELO | F36: 1 | H36: Iraan | I36: TH 82 | O36: Rainfed
B37: ENECITA | C37: MIRANDA | D37: BALAURO | F37: 0.5 | H37: Iraan | M37: BLANDI | O37: Rainfed
B38: RENANTE | C38: LUSOC | D38: DUHAYLUNGSOD | F38: 1.8 | H38: Iraan | M38: BLANDE | O38: Irrigated
B39: JOLANE | C39: CAPUNONG | D39: GAITERA | F39: 1.8 | H39: Iraan | M39: SR | O39: Irrigated
B40: JOEMAR | C40: TABLANZA | D40: MONGCAL | F40: 1 | H40: Iraan | M40: BLANDE | O40: Rainfed
B41: ALICIA | C41: CARTACIANO | D41: MONTARGO | F41: 1 | H41: Iraan | M41: THAILAND | O41: Rainfed
...

Sheet Oct 1-15
A1: Department of Agriculture
A2: REGIONAL FIELD OFFICE MIMAROPA
A3: Rice Program
A5: DRY SEASON 2026 Planting Report
A6: as of October 15, 2025
A7: MUNICIPALITY / BARANGAY | B7: NO. OF FARMER PLANTED | C7: IRRIGATED | I7: RAINFED | R7: =A5 -> DRY SEASON 2026 Planting Report | X7: REMARKS
C9: HYBRID SEEDS | D9: REGISTERED SEEDS | E9: CERTIFIED SEEDS | F9: GOOD QUALITY SEEDS | G9: FARMERS HOME SAVED SEEDS / GS | H9: TOTAL | I9: LOWLAND | N9: UPLAND | Q9: TOTAL | R9: HYBRID SEEDS | S9: REGISTERED SEEDS | T9: CERTIFIED SEEDS | U9: GOOD QUALITY SEEDS | V9: FARMERS HOME SAVED SEEDS / GS | W9: TOTAL
I10: HYBRID SEEDS | J10: REGISTERED SEEDS | K10: CERTIFIED SEEDS | L10: GOOD QUALITY SEEDS | M10: FARMERS HOME SAVED SEEDS | N10: CERTIFIED SEEDS | O10: GOOD QUALITY SEEDS | P10: FARMERS HOME SAVED SEEDS / GS
A11: Rizal | B11: =SUM(B12:B23) -> 80 | C11: =SUM(C12:C23) -> 24.7 | D11: =SUM(D12:D23) -> 0 | E11: =SUM(E12:E23) -> 35.5 | F11: =SUM(F12:F23) -> 0 | G11: =SUM(G12:G23) -> 5 | H11: =SUM(H12:H23) -> 0 | I11: =SUM(I12:I23) -> 8.9 | ... W11: =SUM(W12:W23) -> 123.6
A12: Bunog | B12: 6 | I12: 2.8 | K12: 0.5 | M12: 2.9 | Q12: =SUM(I12:P12) -> 6.2 | R12: =C12+I12 -> 2.8 | S12: =D12+J12 -> 0 | T12: =E12+K12+N12 -> 0.5 | U12: =F12+L12+O12 -> 0 | V12: =G12+M12+P12 -> 2.9 | W12: =SUM(R12:V12) -> 6.2
A13: Campong Ulay | B13: 4 | C13: 4 | K13: 3.5 | Q13: =SUM(I13:P13) -> 3.5 | R13: =C13+I13 -> 4 | S13: =D13+J13 -> 0 | T13: =E13+K13+N13 -> 3.5 | U13: =F13+L13+O13 -> 0 | V13: =G13+M13+P13 -> 0 | W13: =SUM(R13:V13) -> 7.5
A14: Candawaga | B14: 5 | C14: 7 | E14: 3.5 | K14: 2.5 | Q14: =SUM(I14:P14) -> 2.5 | R14: =C14+I14 -> 7 | S14: =D14+J14 -> 0 | T14: =E14+K14+N14 -> 6 | U14: =F14+L14+O14 -> 0 | V14: =G14+M14+P14 -> 0 | W14: =SUM(R14:V14) -> 13
A15: Canipaan | B15: 13 | C15: 2.8 | E15: 3 | I15: 3.6 | K15: 10.8 | M15: 1 | Q15: =SUM(I15:P15) -> 15.4 | R15: =C15+I15 -> 6.4 | S15: =D15+J15 -> 0 | T15: =E15+K15+N15 -> 13.8 | U15: =F15+L15+O15 -> 0 | V15: =G15+M15+P15 -> 1 | W15: =SUM(R15:V15) -> 21.2
A16: Culasian | B16: 4 | E16: 2 | K16: 3.8 | Q16: =SUM(I16:P16) -> 3.8 | R16: =C16+I16 -> 0 | S16: =D16+J16 -> 0 | T16: =E16+K16+N16 -> 5.8 | U16: =F16+L16+O16 -> 0 | V16: =G16+M16+P16 -> 0 | W16: =SUM(R16:V16) -> 5.8
A17: Iraan | B17: 19 | C17: 1 | E17: 8.5 | G17: 2.8 | K17: 13.5 | M17: 3.5 | Q17: =SUM(I17:P17) -> 17 | R17: =C17+I17 -> 1 | S17: =D17+J17 -> 0 | T17: =E17+K17+N17 -> 22 | U17: =F17+L17+O17 -> 0 | V17: =G17+M17+P17 -> 6.3 | W17: =SUM(R17:V17) -> 29.3
A18: Latud | B18: 0 | Q18: =SUM(I18:P18) -> 0 | R18: =C18+I18 -> 0 | S18: =D18+J18 -> 0 | T18: =E18+K18+N18 -> 0 | U18: =F18+L18+O18 -> 0 | V18: =G18+M18+P18 -> 0 | W18: =SUM(R18:V18) -> 0
A19: Panalingaan | B19: 0 | Q19: =SUM(I19:P19) -> 0 | R19: =C19+I19 -> 0 | S19: =D19+J19 -> 0 | T19: =E19+K19+N19 -> 0 | U19: =F19+L19+O19 -> 0 | V19: =G19+M19+P19 -> 0 | W19: =SUM(R19:V19) -> 0
A20: Punta Baja | B20: 18 | C20: 7.7 | E20: 12.5 | G20: 2.2 | I20: 2.5 | K20: 1 | Q20: =SUM(I20:P20) -> 3.5 | R20: =C20+I20 -> 10.2 | S20: =D20+J20 -> 0 | T20: =E20+K20+N20 -> 13.5 | U20: =F20+L20+O20 -> 0 | V20: =G20+M20+P20 -> 2.2 | W20: =SUM(R20:V20) -> 25.9
A21: Ransang | B21: 7 | C21: 2.2 | E21: 6 | K21: 1.5 | Q21: =SUM(I21:P21) -> 1.5 | R21: =C21+I21 -> 2.2 | S21: =D21+J21 -> 0 | T21: =E21+K21+N21 -> 7.5 | U21: =F21+L21+O21 -> 0 | V21: =G21+M21+P21 -> 0 | W21: =SUM(R21:V21) -> 9.7
A22: Taburi | B22: 4 | K22: 5 | Q22: =SUM(I22:P22) -> 5 | R22: =C22+I22 -> 0 | S22: =D22+J22 -> 0 | T22: =E22+K22+N22 -> 5 | U22: =F22+L22+O22 -> 0 | V22: =G22+M22+P22 -> 0 | W22: =SUM(R22:V22) -> 5
A24: - to be submitted every 15th and 30th day of the month
A25: - March 15 submission for terminal planting under DS cropping
A26: =-A29 -> 0

Sheet Oct 1-15 Materlist
A1: Department of Agriculture
A2: REGIONAL FIELD OFFICE MIMAROPA
A3: Rice Program
A5: DRY SEASON 2026 Planting Report | I5: H | K5: CS | M5: FS
A6: as of Oct 15, 2025
A7: Location | B7: Name of Farmer | F7: Area Planted (Hectares) | G7: Date of Crop Establishent | H7: Location | I7: Type of Seeds and Variety | N7: Seeding Rate (Kg/Ha.) | O7: Field source of water
B8: first_name | C8: middle_name | D8: last_name | E8: ext_name | G8: (Transplanting or Broadcasting) | I8: HYBRID SEEDS | J8: REGISTERED SEEDS | K8: CERTIFIED SEEDS | L8: GOOD QUALITY SEEDS | M8: FARMERS HOME SAVED SEEDS / GS | O8: (Irrigated/ Rainfed Lowland/ Rainfed Upland)
B9: YASHIR | C9: AMILASAN | D9: ALAM | F9: 1.6 | H9: Bunog | I9: JACKPOT | O9: Rainfed
B10: HADSMAR | C10: OMIS | D10: AMILASAN | F10: 0.7 | H10: Bunog | I10: JACKPOT | O10: Rainfed
A11: Rizal | B11: ERWIN | C11: ESO | D11: JABEL | F11: 1.9 | H11: Bunog | M11: b-4 | O11: Rainfed
A12: Bunog | B12: ARCHIE | C12: ESO | D12: JABEL | F12: 1 | H12: Bunog | M12: speed | O12: Rainfed
A13: Campong Ulay | B13: ALFREDO | C13: TAUBAN | D13: JURILLA SR. | F13: 0.5 | H13: Bunog | I13: HABILIS | O13: Rainfed
A14: Candawaga | B14: RAIDE | C14: JAIBE | D14: SAYROL | F14: 0.5 | H14: Bunog | K14: rc 402 | O14: Rainfed
A15: Canipaan | B15: ZENAIDA | C15: BADENAS | D15: DIESTA | F15: 3 | H15: Campong Ulay | I15: HABILIS | O15: Irrigated
A16: Culasian | B16: GEORGE | C16: TIPO | D16: LIANG | F16: 1 | H16: Campong Ulay | I16: HABILIS | O16: Irrigated
A17: Iraan | B17: MANOLING | C17: ANGELES | D17: MARTINEZ | F17: 1.5 | H17: Campong Ulay | K17: RC402 | O17: Rainfed
A18: Latud | B18: HAKIMIN | C18: ABDULAH | D18: SAYLILA | F18: 2 | H18: Campong Ulay | K18: RC402 | O18: Rainfed
A19: Panalingaan | B19: JEFFREY | C19: CAYAO | D19: BONBON | F19: 1 | H19: Canipaan | K19: RC 222 | O19: Rainfed
A20: Punta Baja | B20: ARLENE | C20: MAGBANUA | D20: BUNDAL | F20: 2 | H20: Canipaan | I20: HABILIS | O20: Rainfed
A21: Ransang | B21: LORNA | C21: DELGADO | D21: CAYAO | F21: 1.5 | H21: Canipaan | K21: RC 402 | O21: Rainfed
A22: Taburi | B22: ABIAS | C22: MONTIEL | D22: CLAVERIA | F22: 2 | H22: Canipaan | K22: RC 222 | O22: Rainfed
B23: LIZA | C23: BALBERDE | D23: FAVILA | F23: 1 | H23: Canipaan | K23: RC 222 | O23: Rainfed
B24: ANDRES | C24: CAYAO | D24: LIBANAN | F24: 1 | H24: Canipaan | K24: RC 402 | O24: Rainfed
B25: ANTONIO | C25: FAVILA | D25: MAGBANUA | E25: SR | F25: 1.6 | H25: Canipaan | I25: HABILIS | O25: Rainfed
A26: =-A29 -> 0 | B26: STEPANIA | C26: CAYAO | D26: MAGBANUA | F26: 1 | H26: Canipaan | M26: BLANDI | O26: Rainfed
B27: DANA | C27: FAVILA | D27: OMBI-ON | F27: 2 | H27: Canipaan | K27: RC 222 | O27: Irrigated
B28: JL | C28: FAVILA | D28: OMBI-ON | F28: 2.8 | H28: Canipaan | I28: HABILIS | O28: Irrigated
B29: JOLITO | C29: RONGCO | D29: OMBI-ON | F29: 3 | H29: Canipaan | K29: RC 402 | O29: Rainfed
